File: Klausurvorbereitung/Übungen/UE5_Specimen_RawData_4.csv
Texteingaben : Proben-beschriftung;"dpp-PUL6-4"
Allgemein : Startdatum;16.08.2018 16:31:34
Abmessung : Querschnitt;3,45000;mm^2

Zeit;Traversenweg;Last;Dehnung 1;Zugspannung
(sec);(mm);(kN);(%);(MPa)
0,00000;-0,0023;0,083;-0,00110;24,19
0,20000;-0,0011;0,084;-0,00107;24,25
0,40000;0,0034;0,103;0,00055;29,74
0,60000;0,0075;0,130;0,00297;37,71
0,80000;0,0111;0,152;0,00496;44,03
1,00000;0,0143;0,168;0,00662;48,79
1,20000;0,0176;0,181;0,00845;52,38
1,40000;0,0212;0,191;0,01032;55,34
1,60000;0,0244;0,195;0,01210;56,67
1,80000;0,0276;0,201;0,01372;58,14
2,00000;0,0311;0,206;0,01560;59,57
2,20000;0,0344;0,208;0,01745;60,40
2,40000;0,0376;0,211;0,01906;61,05
2,60000;0,0412;0,213;0,02089;61,73
2,80000;0,0445;0,217;0,02267;62,98
3,00000;0,0476;0,219;0,02423;63,53
3,20000;0,0510;0,222;0,02587;64,39
3,40000;0,0545;0,226;0,02765;65,62
3,60000;0,0576;0,230;0,02922;66,53
3,80000;0,0610;0,238;0,03081;68,86
4,00000;0,0646;0,247;0,03280;71,55
4,20000;0,0677;0,263;0,03428;76,14
4,40000;0,0709;0,277;0,03588;80,30
4,60000;0,0745;0,292;0,03776;84,75
4,80000;0,0778;0,308;0,03937;89,25
5,00000;0,0809;0,319;0,04104;92,41
5,20000;0,0845;0,329;0,04279;95,45
5,40000;0,0877;0,338;0,04459;97,97
5,60000;0,0910;0,347;0,04626;100,48
5,80000;0,0945;0,357;0,04797;103,35
6,00000;0,0978;0,366;0,04978;106,06
6,20000;0,1010;0,376;0,05133;108,88
6,40000;0,1043;0,387;0,05294;112,20
6,60000;0,1078;0,400;0,05478;115,85
6,80000;0,1111;0,412;0,05641;119,53
7,00000;0,1143;0,427;0,05805;123,87
7,20000;0,1179;0,441;0,05985;127,82
7,40000;0,1211;0,452;0,06142;130,88
7,60000;0,1242;0,461;0,06307;133,56
7,80000;0,1278;0,467;0,06475;135,24
8,00000;0,1311;0,472;0,06638;136,96
8,20000;0,1343;0,476;0,06796;138,10
8,40000;0,1378;0,479;0,06953;138,98
8,60000;0,1412;0,484;0,07116;140,27
8,80000;0,1444;0,487;0,07266;141,08
9,00000;0,1477;0,490;0,07409;141,95
9,20000;0,1512;0,495;0,07573;143,52
9,40000;0,1544;0,502;0,07713;145,37
9,60000;0,1576;0,509;0,07856;147,57
9,80000;0,1612;0,518;0,08011;150,19
10,00000;0,1644;0,530;0,08139;153,59
10,20000;0,1676;0,542;0,08288;157,14
10,40000;0,1711;0,557;0,08440;161,59
10,60000;0,1744;0,570;0,08584;165,14
10,80000;0,1776;0,588;0,08714;170,53
11,00000;0,1812;0,604;0,08871;175,14
11,20000;0,1844;0,621;0,09012;179,94
11,40000;0,1877;0,633;0,09156;183,41
11,60000;0,1910;0,641;0,09298;185,78
11,80000;0,1944;0,650;0,09445;188,41
12,00000;0,1977;0,659;0,09587;190,94
12,20000;0,2010;0,665;0,09727;192,72
12,40000;0,2045;0,673;0,09888;195,04
12,60000;0,2078;0,681;0,10039;197,35
12,80000;0,2109;0,689;0,10191;199,60
13,00000;0,2146;0,701;0,10388;203,09
13,20000;0,2177;0,708;0,10550;205,18
13,40000;0,2208;0,724;0,10700;209,85
13,60000;0,2245;0,737;0,10878;213,60
13,80000;0,2277;0,755;0,11051;218,98
14,00000;0,2309;0,770;0,11213;223,22
14,20000;0,2344;0,782;0,11377;226,71
14,40000;0,2377;0,788;0,11544;228,29
14,60000;0,2410;0,791;0,11714;229,21
14,80000;0,2444;0,793;0,11872;229,93
15,00000;0,2478;0,796;0,12039;230,65
15,20000;0,2510;0,799;0,12196;231,62
15,40000;0,2543;0,802;0,12363;232,32
15,60000;0,2578;0,806;0,12561;233,75
15,80000;0,2611;0,812;0,12722;235,40
16,00000;0,2642;0,818;0,12867;236,98
16,20000;0,2679;0,823;0,13058;238,62
16,40000;0,2711;0,828;0,13225;239,93
16,60000;0,2742;0,832;0,13386;241,08
16,80000;0,2778;0,837;0,13573;242,72
17,00000;0,2811;0,843;0,13739;244,42
17,20000;0,2843;0,853;0,13903;247,26
17,40000;0,2878;0,865;0,14082;250,77
17,60000;0,2911;0,881;0,14259;255,32
17,80000;0,2944;0,894;0,14413;259,14
18,00000;0,2977;0,905;0,14591;262,37
18,20000;0,3012;0,916;0,14774;265,46
18,40000;0,3044;0,925;0,14941;268,13
18,60000;0,3076;0,937;0,15099;271,70
18,80000;0,3113;0,952;0,15283;275,93
19,00000;0,3144;0,965;0,15444;279,64
19,20000;0,3176;0,977;0,15612;283,20
19,40000;0,3211;0,994;0,15793;288,21
19,60000;0,3244;1,006;0,15969;291,66
19,80000;0,3276;1,022;0,16134;296,21
20,00000;0,3312;1,039;0,16322;301,25
20,20000;0,3344;1,053;0,16488;305,34
20,40000;0,3377;1,072;0,16658;310,61
20,60000;0,3410;1,085;0,16818;314,54
20,80000;0,3445;1,098;0,17007;318,15
21,00000;0,3477;1,106;0,17168;320,71
21,20000;0,3510;1,113;0,17330;322,62
21,40000;0,3546;1,117;0,17518;323,91
21,60000;0,3578;1,121;0,17678;324,90
21,80000;0,3609;1,124;0,17839;325,71
22,00000;0,3645;1,127;0,18034;326,65
22,20000;0,3678;1,130;0,18195;327,49
22,40000;0,3709;1,132;0,18354;328,22
22,60000;0,3745;1,136;0,18545;329,24
22,80000;0,3778;1,143;0,18713;331,21
23,00000;0,3810;1,148;0,18884;332,71
23,20000;0,3844;1,154;0,19058;334,58
23,40000;0,3877;1,161;0,19231;336,56
23,60000;0,3909;1,167;0,19401;338,23
23,80000;0,3943;1,177;0,19564;341,09
24,00000;0,3978;1,188;0,19752;344,41
24,20000;0,4010;1,200;0,19904;347,71
24,40000;0,4043;1,214;0,20078;351,81
24,60000;0,4078;1,226;0,20258;355,31
24,80000;0,4111;1,234;0,20418;357,72
25,00000;0,4142;1,245;0,20584;360,91
25,20000;0,4179;1,253;0,20774;363,33
25,40000;0,4211;1,266;0,20937;367,04
25,60000;0,4243;1,273;0,21099;369,08
25,80000;0,4278;1,284;0,21275;372,12
26,00000;0,4312;1,291;0,21441;374,28
26,20000;0,4343;1,299;0,21607;376,64
26,40000;0,4377;1,311;0,21771;379,90
26,60000;0,4411;1,321;0,21952;382,80
26,80000;0,4444;1,334;0,22124;386,75
27,00000;0,4476;1,347;0,22290;390,47
27,20000;0,4512;1,359;0,22469;393,99
27,40000;0,4544;1,372;0,22636;397,81
27,60000;0,4575;1,381;0,22796;400,25
27,80000;0,4611;1,389;0,22983;402,62
28,00000;0,4644;1,397;0,23142;404,95
28,20000;0,4676;1,402;0,23298;406,28
28,40000;0,4712;1,410;0,23488;408,62
28,60000;0,4744;1,419;0,23646;411,27
28,80000;0,4776;1,429;0,23814;414,26
29,00000;0,4811;1,439;0,23980;417,06
29,20000;0,4844;1,444;0,24146;418,54
29,40000;0,4877;1,456;0,24314;422,01
29,60000;0,4909;1,464;0,24475;424,30
29,80000;0,4945;1,471;0,24662;426,25
30,00000;0,4977;1,478;0,24827;428,31
30,20000;0,5010;1,484;0,24981;430,25
30,40000;0,5045;1,493;0,25174;432,62
30,60000;0,5077;1,505;0,25350;436,15
30,80000;0,5109;1,515;0,25519;439,19
31,00000;0,5146;1,530;0,25703;443,41
31,20000;0,5178;1,544;0,25870;447,42
31,40000;0,5209;1,552;0,26035;449,95
31,60000;0,5246;1,563;0,26224;452,99
31,80000;0,5277;1,572;0,26389;455,57
32,00000;0,5310;1,583;0,26552;458,77
32,20000;0,5344;1,594;0,26729;462,10
32,40000;0,5378;1,607;0,26913;465,85
32,60000;0,5410;1,620;0,27077;469,50
32,80000;0,5443;1,627;0,27239;471,53
33,00000;0,5478;1,633;0,27418;473,34
33,20000;0,5511;1,641;0,27593;475,55
33,40000;0,5542;1,652;0,27754;478,70
33,60000;0,5578;1,660;0,27940;481,17
33,80000;0,5611;1,672;0,28098;484,63
34,00000;0,5642;1,683;0,28257;487,89
34,20000;0,5679;1,696;0,28443;491,45
34,40000;0,5711;1,701;0,28610;493,06
34,60000;0,5743;1,708;0,28767;494,93
34,80000;0,5778;1,712;0,28939;496,23
35,00000;0,5811;1,718;0,29097;497,95
35,20000;0,5844;1,722;0,29274;499,25
35,40000;0,5877;1,727;0,29429;500,69
35,60000;0,5912;1,731;0,29599;501,76
35,80000;0,5944;1,735;0,29756;502,81
36,00000;0,5976;1,737;0,29915;503,42
36,20000;0,6012;1,739;0,30094;504,17
36,40000;0,6044;1,743;0,30254;505,27
36,60000;0,6075;1,748;0,30402;506,59
36,80000;0,6112;1,754;0,30588;508,39
37,00000;0,6145;1,764;0,30747;511,16
37,20000;0,6176;1,773;0,30903;513,97
37,40000;0,6212;1,789;0,31083;518,57
37,60000;0,6244;1,809;0,31237;524,46
37,80000;0,6276;1,825;0,31395;528,91
38,00000;0,6311;1,842;0,31573;533,88
38,20000;0,6344;1,857;0,31742;538,18
38,40000;0,6377;1,869;0,31897;541,87
38,60000;0,6410;1,882;0,32057;545,65
38,80000;0,6445;1,895;0,32229;549,27
39,00000;0,6477;1,904;0,32378;551,79
39,20000;0,6509;1,916;0,32534;555,39
39,40000;0,6545;1,927;0,32709;558,56
39,60000;0,6578;1,939;0,32869;562,02
39,80000;0,6609;1,952;0,33026;565,67
40,00000;0,6646;1,969;0,33203;570,69
40,20000;0,6678;1,984;0,33363;575,08
40,40000;0,6709;1,995;0,33518;578,16
40,60000;0,6745;2,007;0,33693;581,84
40,80000;0,6778;2,019;0,33844;585,26
41,00000;0,6809;2,023;0,34000;586,38
41,20000;0,6844;2,030;0,34162;588,48
41,40000;0,6878;2,036;0,34329;590,19
41,60000;0,6910;2,040;0,34489;591,39
41,80000;0,6943;2,045;0,34642;592,76
42,00000;0,6978;2,050;0,34814;594,24
42,20000;0,7010;2,055;0,34962;595,79
42,40000;0,7042;2,058;0,35117;596,57
42,60000;0,7078;2,060;0,35289;597,12
42,80000;0,7111;2,063;0,35450;598,00
43,00000;0,7143;2,064;0,35592;598,14
43,20000;0,7178;2,065;0,35754;598,43
43,40000;0,7211;2,067;0,35920;599,16
43,60000;0,7243;2,071;0,36070;600,15
43,80000;0,7278;2,077;0,36236;601,97
44,00000;0,7312;2,085;0,36396;604,42
44,20000;0,7344;2,098;0,36550;607,97
44,40000;0,7377;2,114;0,36717;612,82
44,60000;0,7412;2,126;0,36884;616,16
44,80000;0,7444;2,138;0,37030;619,71
45,00000;0,7476;2,148;0,37185;622,58
45,20000;0,7512;2,160;0,37371;625,97
45,40000;0,7544;2,168;0,37527;628,42
45,60000;0,7575;2,178;0,37661;631,39
45,80000;0,7613;2,192;0,37838;635,27
46,00000;0,7644;2,200;0,37992;637,72
46,20000;0,7676;2,210;0,38146;640,66
46,40000;0,7711;2,218;0,38296;642,99
46,60000;0,7744;2,227;0,38444;645,64
46,80000;0,7777;2,237;0,38601;648,42
47,00000;0,7810;2,251;0,38761;652,45
47,20000;0,7844;2,265;0,38925;656,62
47,40000;0,7878;2,285;0,39073;662,29
47,60000;0,7909;2,303;0,39221;667,44
47,80000;0,7945;2,316;0,39406;671,33
48,00000;0,7977;2,328;0,39550;674,89
48,20000;0,8009;2,338;0,39705;677,54
48,40000;0,8045;2,345;0,39877;679,85
48,60000;0,8078;2,354;0,40028;682,40
48,80000;0,8109;2,363;0,40187;684,83
49,00000;0,8145;2,370;0,40352;687,00
49,20000;0,8177;2,376;0,40503;688,79
49,40000;0,8210;2,381;0,40656;690,18
49,60000;0,8244;2,385;0,40823;691,29
49,80000;0,8278;2,389;0,40983;692,42
50,00000;0,8311;2,393;0,41146;693,77
50,20000;0,8344;2,399;0,41286;695,39
50,40000;0,8378;2,405;0,41451;697,23
50,60000;0,8411;2,413;0,41608;699,46
50,80000;0,8442;2,423;0,41749;702,39
51,00000;0,8479;2,436;0,41923;706,03
51,20000;0,8511;2,451;0,42078;710,51
51,40000;0,8542;2,467;0,42226;714,94
51,60000;0,8579;2,479;0,42395;718,57
51,80000;0,8611;2,495;0,42545;723,07
52,00000;0,8643;2,504;0,42690;725,87
52,20000;0,8678;2,512;0,42854;727,98
52,40000;0,8711;2,519;0,43015;730,06
52,60000;0,8744;2,523;0,43161;731,19
52,80000;0,8777;2,525;0,43303;731,82
53,00000;0,8811;2,529;0,43480;733,10
53,20000;0,8844;2,534;0,43627;734,58
53,40000;0,8876;2,542;0,43777;736,82
53,60000;0,8912;2,550;0,43944;739,22
53,80000;0,8944;2,563;0,44096;742,99
54,00000;0,8976;2,573;0,44243;745,80
54,20000;0,9012;2,591;0,44416;750,96
54,40000;0,9045;2,605;0,44562;755,12
54,60000;0,9076;2,615;0,44706;758,10
54,80000;0,9111;2,624;0,44866;760,69
55,00000;0,9144;2,631;0,45024;762,66
55,20000;0,9176;2,636;0,45181;764,00
55,40000;0,9211;2,640;0,45326;765,27
55,60000;0,9245;2,643;0,45494;766,17
55,80000;0,9277;2,646;0,45641;767,10
56,00000;0,9310;2,651;0,45786;768,42
56,20000;0,9345;2,656;0,45944;769,77
56,40000;0,9376;2,664;0,46094;772,11
56,60000;0,9409;2,672;0,46238;774,37
56,80000;0,9445;2,679;0,46405;776,46
57,00000;0,9478;2,687;0,46550;778,85
57,20000;0,9510;2,697;0,46690;781,67
57,40000;0,9545;2,704;0,46853;783,78
57,60000;0,9578;2,713;0,47002;786,28
57,80000;0,9609;2,721;0,47145;788,74
58,00000;0,9644;2,737;0,47305;793,31
58,20000;0,9678;2,751;0,47460;797,27
58,40000;0,9711;2,765;0,47602;801,46
58,60000;0,9743;2,779;0,47744;805,43
58,80000;0,9779;2,793;0,47908;809,64
59,00000;0,9810;2,804;0,48046;812,66
59,20000;0,9843;2,820;0,48186;817,26
59,40000;0,9878;2,829;0,48354;820,04
59,60000;0,9910;2,843;0,48499;824,06
59,80000;0,9942;2,853;0,48637;827,03
60,00000;0,9979;2,866;0,48814;830,71
60,20000;1,0011;2,873;0,48942;832,84
60,40000;1,0043;2,880;0,49104;834,89
60,60000;1,0078;2,889;0,49257;837,27
60,80000;1,0111;2,898;0,49405;840,03
61,00000;1,0143;2,911;0,49552;843,65
61,20000;1,0178;2,925;0,49702;847,73
61,40000;1,0211;2,943;0,49861;852,97
61,60000;1,0244;2,952;0,49995;855,70
61,80000;1,0276;2,962;0,50143;858,47
62,00000;1,0311;2,968;0,50304;860,15
62,20000;1,0344;2,970;0,50444;860,85
62,32800;1,0364;2,971;0,50534;861,19
62,52800;1,0399;2,973;0,50678;861,65
62,72800;1,0433;2,973;0,50845;861,85
62,92800;1,0465;2,974;0,50987;861,96
63,12800;1,0498;2,974;0,51138;862,10
63,32800;1,0533;2,975;0,51293;862,31
63,52800;1,0565;2,976;0,51432;862,51
63,72800;1,0597;2,978;0,51569;863,08
63,92800;1,0633;2,979;0,51742;863,54
64,12800;1,0666;2,983;0,51883;864,69
64,32800;1,0697;2,987;0,52028;865,81
64,52800;1,0733;2,994;0,52191;867,90
64,72800;1,0766;3,003;0,52322;870,40
64,92800;1,0797;3,013;0,52466;873,25
65,12800;1,0832;3,028;0,52621;877,66
65,32800;1,0866;3,041;0,52773;881,48
65,52800;1,0897;3,058;0,52912;886,29
65,72800;1,0933;3,073;0,53060;890,79
65,92800;1,0966;3,087;0,53220;894,88
66,12800;1,0998;3,097;0,53362;897,80
66,32800;1,1031;3,106;0,53492;900,27
66,52800;1,1066;3,116;0,53656;903,10
66,72800;1,1099;3,124;0,53793;905,59
66,92800;1,1131;3,132;0,53928;907,86
67,12800;1,1166;3,145;0,54088;911,67
67,32800;1,1199;3,159;0,54226;915,57
67,52800;1,1231;3,174;0,54362;920,09
67,72800;1,1266;3,191;0,54511;925,04
67,92800;1,1299;3,205;0,54654;928,98
68,12800;1,1331;3,228;0,54781;935,75
68,32800;1,1366;3,240;0,54936;939,01
68,52800;1,1400;3,252;0,55084;942,62
68,72800;1,1431;3,262;0,55214;945,38
68,92800;1,1465;3,270;0,55345;947,74
69,12800;1,1499;3,278;0,55513;950,04
69,32800;1,1532;3,284;0,55645;951,91
69,52800;1,1564;3,290;0,55781;953,71
69,72800;1,1600;3,298;0,55937;955,84
69,92800;1,1633;3,303;0,56072;957,26
70,12800;1,1664;3,308;0,56207;958,93
70,32800;1,1700;3,316;0,56371;961,30
70,52800;1,1732;3,322;0,56501;962,86
70,72800;1,1764;3,326;0,56638;964,15
70,92800;1,1799;3,332;0,56790;965,67
71,12800;1,1832;3,337;0,56930;967,32
71,32800;1,1864;3,341;0,57067;968,32
71,52800;1,1899;3,345;0,57204;969,56
71,72800;1,1932;3,352;0,57354;971,63
71,92800;1,1965;3,358;0,57493;973,45
72,12800;1,1998;3,370;0,57627;976,87
72,32800;1,2033;3,379;0,57782;979,56
72,52800;1,2065;3,386;0,57916;981,48
72,72800;1,2097;3,393;0,58049;983,58
72,92800;1,2134;3,398;0,58204;984,82
73,12800;1,2165;3,401;0,58339;985,84
73,32800;1,2197;3,406;0,58467;987,31
73,52800;1,2234;3,411;0,58616;988,56
73,72800;1,2265;3,420;0,58757;991,41
73,92800;1,2297;3,429;0,58887;993,91
74,12800;1,2332;3,441;0,59032;997,42
74,32800;1,2366;3,449;0,59168;999,79
74,52800;1,2398;3,456;0,59306;1001,60
74,72800;1,2432;3,466;0,59440;1004,61
74,92800;1,2465;3,475;0,59594;1007,20
75,12800;1,2498;3,485;0,59720;1010,09
75,32800;1,2531;3,496;0,59845;1013,32
75,52800;1,2567;3,514;0,59997;1018,43
75,72800;1,2599;3,525;0,60131;1021,79
75,92800;1,2631;3,538;0,60249;1025,53
76,12800;1,2667;3,550;0,60407;1028,93
76,32800;1,2699;3,558;0,60539;1031,38
76,52800;1,2730;3,567;0,60669;1033,92
76,72800;1,2767;3,575;0,60824;1036,21
76,92800;1,2799;3,583;0,60957;1038,57
77,12800;1,2831;3,587;0,61090;1039,57
77,32800;1,2866;3,593;0,61241;1041,52
77,52800;1,2899;3,601;0,61379;1043,70
77,72800;1,2932;3,603;0,61515;1044,38
77,92800;1,2965;3,608;0,61649;1045,94
78,12800;1,3000;3,612;0,61793;1047,08
78,32800;1,3033;3,619;0,61938;1048,85
78,52800;1,3064;3,624;0,62060;1050,55
78,72800;1,3101;3,633;0,62219;1053,05
78,92800;1,3132;3,642;0,62340;1055,57
79,12800;1,3164;3,651;0,62466;1058,15
79,32800;1,3199;3,663;0,62610;1061,63
79,52800;1,3232;3,676;0,62747;1065,40
79,72800;1,3264;3,688;0,62873;1069,13
79,92800;1,3299;3,705;0,63018;1073,87
80,12800;1,3332;3,721;0,63159;1078,51
80,32800;1,3365;3,736;0,63287;1082,95
80,52800;1,3398;3,749;0,63423;1086,68
80,72800;1,3432;3,759;0,63567;1089,58
80,92800;1,3465;3,768;0,63697;1092,14
81,12800;1,3497;3,774;0,63826;1093,84
81,32800;1,3533;3,783;0,63976;1096,54
81,52800;1,3565;3,788;0,64103;1097,88
81,72800;1,3597;3,796;0,64246;1100,40
81,92800;1,3633;3,807;0,64385;1103,43
82,12800;1,3666;3,818;0,64523;1106,53
82,32800;1,3697;3,829;0,64647;1109,95
82,52800;1,3733;3,841;0,64786;1113,42
82,72800;1,3766;3,848;0,64925;1115,37
82,92800;1,3798;3,857;0,65050;1117,98
83,12800;1,3832;3,863;0,65179;1119,79
83,32800;1,3866;3,867;0,65314;1120,89
83,52800;1,3899;3,870;0,65448;1121,73
83,72800;1,3930;3,872;0,65570;1122,18
83,92800;1,3966;3,873;0,65715;1122,73
84,12800;1,4000;3,874;0,65844;1122,96
84,32800;1,4030;3,875;0,65961;1123,28
84,52800;1,4067;3,877;0,66105;1123,66
84,72800;1,4099;3,877;0,66233;1123,84
84,92800;1,4131;3,879;0,66350;1124,47
85,12800;1,4166;3,881;0,66487;1124,82
85,32800;1,4199;3,885;0,66624;1126,13
85,52800;1,4231;3,887;0,66754;1126,70
85,72800;1,4265;3,893;0,66892;1128,52
85,92800;1,4299;3,898;0,67023;1129,95
86,12800;1,4332;3,906;0,67143;1132,16
86,32800;1,4364;3,914;0,67272;1134,58
86,52800;1,4400;3,926;0,67419;1138,09
86,72800;1,4432;3,938;0,67547;1141,52
86,92800;1,4464;3,954;0,67670;1146,16
87,12800;1,4500;3,967;0,67817;1149,72
87,32800;1,4533;3,984;0,67946;1154,65
87,52800;1,4564;3,997;0,68064;1158,44
87,72800;1,4600;4,009;0,68205;1161,92
87,92800;1,4632;4,018;0,68334;1164,54
88,12800;1,4663;4,025;0,68453;1166,81
88,32800;1,4699;4,035;0,68585;1169,50
88,52800;1,4733;4,046;0,68716;1172,81
88,72800;1,4765;4,055;0,68833;1175,26
88,92800;1,4798;4,065;0,68953;1178,30
89,12800;1,4833;4,077;0,69094;1181,78
89,32800;1,4865;4,088;0,69207;1184,97
89,52800;1,4897;4,096;0,69321;1187,23
89,72800;1,4933;4,108;0,69472;1190,61
89,92800;1,4965;4,115;0,69595;1192,79
90,12800;1,4997;4,126;0,69705;1195,80
90,32800;1,5034;4,139;0,69845;1199,79
90,52800;1,5065;4,153;0,67019;1203,63
90,72800;1,5097;4,163;0,66919;1206,79
90,92800;1,5133;4,180;0,60628;1211,68
91,12800;1,5166;4,197;0,55098;1216,55
91,32800;1,5198;4,209;-2,02016;1220,08
91,52800;1,5232;4,218;-4,86788;1222,62
91,72800;1,5266;4,225;-5,07007;1224,61
91,92800;1,5299;4,231;-6,28646;1226,49
92,12800;1,5331;4,234;-4,85880;1227,26
92,32800;1,5366;4,238;-3,94457;1228,39
92,52800;1,5399;4,241;-4,78185;1229,21
92,72800;1,5430;4,242;-3,59660;1229,51
92,92800;1,5468;4,244;-4,75659;1230,03
93,12800;1,5499;4,245;-5,51950;1230,43
93,32800;1,5530;4,245;-4,86075;1230,50
93,52800;1,5566;4,246;-4,33686;1230,78
93,72800;1,5599;4,247;-4,76106;1231,01
93,92800;1,5630;4,248;-5,26324;1231,18
94,12800;1,5666;4,249;-4,92708;1231,57
94,32800;1,5699;4,251;-4,82267;1232,04
94,52800;1,5731;4,253;-5,00363;1232,72
94,72800;1,5765;4,255;-5,21382;1233,42
94,92800;1,5799;4,260;-4,87423;1234,77
95,12800;1,5832;4,264;-5,04743;1236,09
95,32800;1,5864;4,269;-5,14690;1237,33
95,52800;1,5900;4,279;-4,90370;1240,22
95,72800;1,5932;4,288;-5,07540;1242,81
95,92800;1,5964;4,297;-5,09964;1245,46
96,12800;1,6000;4,309;-4,93193;1248,95
96,32800;1,6032;4,318;-5,08736;1251,73
96,52800;1,6064;4,329;-5,06705;1254,77
96,72800;1,6099;4,337;-4,95713;1257,09
96,92800;1,6132;4,343;-5,08983;1258,85
97,12800;1,6165;4,350;-5,04578;1260,98
97,32800;1,6198;4,357;-4,97817;1262,99
97,52800;1,6233;4,368;-5,08671;1266,22
97,72800;1,6265;4,377;-5,03210;1268,81
97,92800;1,6297;4,387;-4,99546;1271,66
98,12800;1,6333;4,403;-5,08132;1276,14
98,32800;1,6365;4,417;-5,02319;1280,19
98,52800;1,6397;4,431;-5,01010;1284,39
98,72800;1,6433;4,444;-5,07456;1288,12
98,92800;1,6465;4,454;-5,01795;1290,99
99,12800;1,6497;4,461;-5,02210;1293,02
99,32800;1,6533;4,470;-5,06703;1295,58
99,52800;1,6565;4,480;-5,01625;1298,58
99,72800;1,6598;4,488;-5,03117;1300,86
99,92800;1,6632;4,494;-5,05995;1302,49
100,12800;1,6666;4,500;-5,01629;1304,45
100,32800;1,6698;4,507;-5,03794;1306,41
100,52800;1,6731;4,512;-5,05318;1307,72
100,72800;1,6766;4,518;-5,01816;1309,52
100,92800;1,6799;4,522;-5,04243;1310,87
101,12800;1,6830;4,528;-5,04708;1312,59
101,32800;1,6867;4,534;-5,02096;1314,26
101,52800;1,6900;4,538;-5,04502;1315,49
101,72800;1,6931;4,541;-5,04228;1316,31
101,92800;1,6967;4,548;-5,02430;1318,16
102,12800;1,6999;4,552;-5,04626;1319,29
102,32800;1,7031;4,557;-5,03848;1320,87
102,52800;1,7065;4,564;-5,02771;1322,76
102,72800;1,7099;4,571;-5,04627;1324,90
102,92800;1,7132;4,581;-5,03586;1327,93
103,12800;1,7165;4,591;-5,03093;1330,63
103,32800;1,7199;4,605;-5,04565;1334,68
103,52800;1,7232;4,620;-5,03404;1339,00
103,72800;1,7263;4,625;-5,03391;1340,68
103,92800;1,7300;4,642;-5,04432;1345,47
104,12800;1,7332;4,652;-5,03329;1348,38
104,32800;1,7364;4,659;-5,03612;1350,29
104,52800;1,7400;4,665;-5,04306;1352,07
104,72800;1,7432;4,670;-5,03325;1353,73
104,92800;1,7465;4,678;-5,03772;1355,89
105,12800;1,7500;4,685;-5,04154;1357,94
105,32801;1,7532;4,690;-5,03356;1359,33
105,52801;1,7564;4,699;-5,03910;1362,06
105,72801;1,7599;4,706;-5,04019;1364,10
105,92801;1,7633;4,713;-5,03444;1365,96
106,12801;1,7665;4,718;-5,03976;1367,53
106,32801;1,7698;4,721;-5,03925;1368,28
106,52801;1,7733;4,726;-5,03523;1369,75
106,72801;1,7766;4,729;-5,04026;1370,79
106,92801;1,7797;4,734;-5,03837;1372,31
107,12801;1,7834;4,744;-5,03611;1375,10
107,32801;1,7865;4,750;-5,04034;1376,85
107,52801;1,7896;4,760;-5,03752;1379,73
107,72801;1,7934;4,768;-5,03714;1381,89
107,92801;1,7965;4,773;-5,03998;1383,36
108,12801;1,7997;4,779;-5,03728;1385,10
108,32801;1,8033;4,784;-5,03768;1386,72
108,52801;1,8065;4,788;-5,03974;1387,91
108,72801;1,8098;4,792;-5,03724;1389,00
108,92801;1,8132;4,797;-5,03832;1390,52
109,12801;1,8166;4,802;-5,03950;1391,89
109,32801;1,8199;4,809;-5,03709;1393,95
109,52801;1,8231;4,817;-5,03895;1396,15
109,72801;1,8266;4,825;-5,03907;1398,63
109,92801;1,8299;4,837;-5,03757;1401,93
110,12801;1,8331;4,845;-5,03908;1404,40
110,32801;1,8367;4,858;-5,03899;1408,22
110,52801;1,8399;4,871;-5,03782;1411,84
110,72801;1,8430;4,876;-5,03930;1413,45
110,92801;1,8466;4,888;-5,03877;1416,75
111,12801;1,8499;4,897;-5,03809;1419,41
111,32801;1,8531;4,906;-5,03932;1421,90
111,52801;1,8565;4,918;-5,03837;1425,50
111,72801;1,8599;4,932;-5,03849;1429,48
111,92801;1,8632;4,943;-5,03927;1432,66
112,12801;1,8665;4,957;-5,03845;1436,90
112,32801;1,8699;4,972;-5,03863;1441,13
112,52801;1,8732;4,984;-5,03948;1444,59
112,72801;1,8763;4,995;-5,03861;1447,80
112,92801;1,8800;5,006;-5,03892;1451,10
113,12801;1,8832;5,021;-5,03927;1455,37
113,32801;1,8864;5,034;-5,03857;1459,07
113,52801;1,8900;5,049;-5,03920;1463,42
113,72801;1,8932;5,066;-5,03916;1468,49
113,92801;1,8964;5,080;-5,03875;1472,38
114,12801;1,8998;5,097;-5,03918;1477,48
114,32801;1,9032;5,109;-5,03921;1480,90
114,52801;1,9065;5,120;-5,03879;1484,12
114,72801;1,9098;5,126;-5,03938;1485,87
114,92801;1,9133;5,131;-5,03910;1487,30
115,12801;1,9166;5,137;-5,03898;1489,11
115,32801;1,9197;5,141;-5,03939;1490,20
115,52801;1,9234;5,145;-5,03904;1491,27
115,72801;1,9266;5,147;-5,03897;1491,83
115,92801;1,9297;5,148;-5,03960;1492,17
116,12801;1,9333;5,149;-5,03916;1492,39
116,32801;1,9365;5,149;-5,03931;1492,45
116,52801;1,9398;5,149;-5,03951;1492,50
116,72801;1,9432;5,149;-5,03926;1492,52
116,92801;1,9466;5,149;-5,03934;1492,57
117,12801;1,9499;5,150;-5,03952;1492,68
117,32801;1,9532;5,151;-5,03930;1492,91
117,52801;1,9566;5,153;-5,03903;1493,49
117,72801;1,9598;5,156;-5,03975;1494,47
117,92801;1,9631;5,160;-5,03930;1495,76
118,12801;1,9666;5,172;-5,03950;1499,02
118,32801;1,9698;5,183;-5,03961;1502,36
118,52801;1,9730;5,192;-5,03925;1504,85
118,72801;1,9767;5,209;-5,03925;1509,77
118,92801;1,9799;5,217;-5,03965;1512,09
119,12801;1,9831;5,229;-5,03949;1515,53
119,32801;1,9866;5,241;-5,03929;1519,23
119,52801;1,9899;5,252;-5,03951;1522,36
119,72801;1,9931;5,261;-5,03937;1524,98
119,92801;1,9965;5,271;-5,03938;1527,81
120,12801;2,0000;5,281;-5,03926;1530,79
120,32801;2,0032;5,297;-5,03954;1535,30
120,52801;2,0065;5,307;-5,03936;1538,39
120,72801;2,0100;5,316;-5,03937;1540,85
120,92801;2,0132;5,325;-5,03943;1543,51
121,12801;2,0163;5,333;-5,03937;1545,88
121,32801;2,0200;5,342;-5,03951;1548,39
121,52801;2,0233;5,353;-5,03967;1551,62
121,72801;2,0264;5,361;-5,03971;1553,94
121,92801;2,0300;5,377;-5,03958;1558,52
122,12801;2,0332;5,390;-5,03970;1562,32
122,32801;2,0364;5,406;-5,03939;1566,94
122,52801;2,0399;5,418;-5,03973;1570,41
122,72801;2,0432;5,430;-5,03980;1573,87
122,92801;2,0464;5,440;-5,03988;1576,74
123,12801;2,0498;5,445;-5,03992;1578,27
123,32801;2,0533;5,452;-5,03989;1580,34
123,52801;2,0565;5,456;-5,03983;1581,44
123,72801;2,0597;5,460;-5,03991;1582,52
123,92801;2,0633;5,463;-5,03985;1583,59
124,12801;2,0665;5,469;-5,03991;1585,32
124,32801;2,0697;5,475;-5,04006;1586,95
124,52801;2,0734;5,482;-5,04010;1589,02
124,72801;2,0766;5,486;-5,04021;1590,08
124,92801;2,0797;5,492;-5,04017;1591,86
125,12801;2,0832;5,501;-5,04007;1594,47
125,32801;2,0865;5,511;-5,04014;1597,35
125,52801;2,0897;5,516;-5,04013;1598,79
125,72801;2,0932;5,523;-5,04008;1600,79
125,92801;2,0966;5,530;-5,04039;1602,88
126,12801;2,0999;5,535;-5,03991;1604,22
126,32801;2,1031;5,542;-5,04016;1606,44
126,52801;2,1067;5,550;-5,04024;1608,64
126,72801;2,1099;5,561;-5,04000;1611,90
126,92801;2,1130;5,571;-5,04032;1614,67
127,12801;2,1167;5,581;-5,04026;1617,72
127,32801;2,1199;5,587;-5,04021;1619,39
127,52801;2,1231;5,592;-5,04011;1620,84
127,72801;2,1266;5,595;-5,04028;1621,82
127,92801;2,1299;5,596;-5,03978;1622,15
128,12801;2,1331;5,598;-5,04040;1622,72
128,32801;2,1365;5,603;-5,03992;1623,94
128,52801;2,1399;5,611;-5,03995;1626,29
128,72801;2,1432;5,618;-5,04024;1628,46
128,92801;2,1464;5,633;-5,04007;1632,62
129,12801;2,1500;5,646;-5,04019;1636,52
129,32801;2,1532;5,655;-5,04051;1639,15
129,52801;2,1564;5,667;-5,04055;1642,62
129,72801;2,1600;5,674;-5,04032;1644,66
129,92801;2,1632;5,681;-5,04048;1646,65
130,12801;2,1664;5,690;-5,04028;1649,18
130,32801;2,1700;5,696;-5,04061;1651,11
130,52801;2,1733;5,704;-5,04023;1653,44
130,72801;2,1764;5,712;-5,04063;1655,64
130,92801;2,1799;5,722;-5,04059;1658,63
131,12801;2,1832;5,731;-5,04050;1661,30
131,32801;2,1865;5,741;-5,04067;1664,06
131,52801;2,1898;5,754;-5,04047;1667,86
131,72801;2,1933;5,764;-5,04047;1670,75
131,92801;2,1965;5,770;-5,04043;1672,60
132,12801;2,1997;5,775;-5,04080;1673,86
132,32801;2,2033;5,781;-5,04047;1675,71
132,52801;2,2065;5,786;-5,04071;1677,06
132,72801;2,2097;5,788;-5,04069;1677,74
132,92801;2,2134;5,792;-5,04063;1678,96
133,12801;2,2165;5,801;-5,04065;1681,51
133,32801;2,2198;5,808;-5,04070;1683,38
133,52801;2,2233;5,817;-5,04075;1686,06
133,72801;2,2265;5,834;-5,04080;1691,10
133,92801;2,2298;5,847;-5,04087;1694,86
134,12801;2,2331;5,862;-5,04072;1699,13
134,32801;2,2366;5,874;-5,04094;1702,65
134,52801;2,2399;5,890;-5,04091;1707,31
134,72801;2,2431;5,900;-5,04083;1710,19
134,92801;2,2467;5,914;-5,04075;1714,11
135,12801;2,2499;5,923;-5,04079;1716,90
135,32801;2,2530;5,935;-5,04071;1720,32
135,52801;2,2567;5,947;-5,04076;1723,80
135,72801;2,2599;5,960;-5,04079;1727,40
135,92801;2,2630;5,968;-5,04091;1729,85
136,12801;2,2667;5,979;-5,04083;1733,18
136,32801;2,2699;5,985;-5,04093;1734,92
136,52801;2,2731;5,992;-5,04101;1736,85
136,72801;2,2766;5,998;-5,04081;1738,63
136,92801;2,2798;6,003;-5,04079;1740,04
137,12801;2,2831;6,008;-5,04072;1741,54
137,32801;2,2865;6,013;-5,04093;1743,00
137,52801;2,2899;6,018;-5,04100;1744,49
137,72801;2,2932;6,027;-5,04096;1746,85
137,92801;2,2964;6,033;-5,04073;1748,71
138,12801;2,3000;6,041;-5,04115;1751,07
138,32801;2,3032;6,045;-5,04078;1752,32
138,52801;2,3063;6,049;-5,04087;1753,36
138,72801;2,3100;6,053;-5,04094;1754,37
138,92801;2,3133;6,053;-5,04100;1754,54
139,12801;2,3164;6,053;-5,04088;1754,62
139,32801;2,3200;6,055;-5,04095;1755,00
139,52801;2,3232;6,056;-5,04097;1755,24
139,72801;2,3264;6,057;-5,04076;1755,70
139,92801;2,3298;6,060;-5,04110;1756,51
140,12801;2,3333;6,064;-5,04088;1757,68
140,32801;2,3365;6,066;-5,04113;1758,34
140,52801;2,3398;6,074;-5,04098;1760,69
140,72801;2,3433;6,083;-5,04102;1763,31
140,92801;2,3465;6,089;-5,04091;1764,84
141,12801;2,3497;6,098;-5,04098;1767,46
141,32801;2,3533;6,105;-5,04101;1769,45
141,52801;2,3566;6,115;-5,04090;1772,56
141,72801;2,3597;6,120;-5,04102;1773,90
141,92801;2,3633;6,130;-5,04100;1776,82
142,12801;2,3665;6,138;-5,04113;1779,08
142,32801;2,3698;6,150;-5,04090;1782,59
142,52801;2,3732;6,161;-5,04112;1785,82
142,72801;2,3766;6,177;-5,04106;1790,29
142,92801;2,3798;6,188;-5,04107;1793,64
143,12801;2,3832;6,200;-5,04104;1797,15
143,32801;2,3866;6,211;-5,04119;1800,18
143,52801;2,3899;6,217;-5,04099;1802,14
143,72801;2,3931;6,225;-5,04093;1804,28
143,92801;2,3966;6,233;-5,04131;1806,62
144,12801;2,3999;6,241;-5,04098;1808,98
144,32801;2,4030;6,253;-5,04106;1812,35
144,52801;2,4067;6,269;-5,04125;1816,97
144,72801;2,4099;6,284;-5,04109;1821,54
144,92801;2,4130;6,298;-5,04091;1825,62
145,12801;2,4166;6,315;-5,04142;1830,48
145,32801;2,4199;6,326;-5,04114;1833,57
145,52801;2,4230;6,334;-5,04103;1835,92
145,72801;2,4266;6,341;-5,04134;1838,11
145,92801;2,4299;6,348;-5,04122;1840,03
146,12801;2,4331;6,353;-5,04115;1841,53
146,32801;2,4364;6,358;-5,04131;1843,04
146,52801;2,4399;6,364;-5,04115;1844,78
146,72801;2,4432;6,371;-5,04124;1846,57
146,92801;2,4464;6,374;-5,04129;1847,59
147,12801;2,4499;6,384;-5,04128;1850,40
147,32801;2,4532;6,389;-5,04132;1852,02
147,52801;2,4565;6,397;-5,04116;1854,20
147,72801;2,4600;6,401;-5,04139;1855,46
147,92801;2,4633;6,406;-5,04136;1856,84
148,12801;2,4664;6,413;-5,04151;1858,75
148,32801;2,4699;6,416;-5,04141;1859,84
148,52801;2,4733;6,419;-5,04162;1860,56
148,72801;2,4765;6,422;-5,04136;1861,53
148,92801;2,4798;6,424;-5,04161;1862,04
149,12801;2,4833;6,430;-5,04138;1863,88
149,32801;2,4866;6,428;-5,04127;1863,06
149,52801;2,4897;6,434;-5,04169;1864,84
149,72801;2,4933;6,439;-5,04127;1866,40
149,92801;2,4966;6,445;-5,04133;1868,03
150,12801;2,4996;6,452;-5,04138;1870,23
150,32801;2,5034;6,460;-5,04145;1872,41
150,52801;2,5065;6,464;-5,04109;1873,53
150,72801;2,5097;6,468;-5,04168;1874,80
150,92801;2,5133;6,471;-5,04118;1875,78
151,12801;2,5165;6,475;-5,04139;1876,70
151,32801;2,5198;6,480;-5,04162;1878,33
151,52801;2,5231;6,484;-5,04129;1879,54
151,72801;2,5266;6,492;-5,04147;1881,61
151,92801;2,5299;6,498;-5,04146;1883,47
152,12801;2,5331;6,505;-5,04158;1885,55
152,32801;2,5367;6,516;-5,04132;1888,73
152,52801;2,5399;6,524;-5,04169;1890,93
152,72801;2,5430;6,532;-5,04144;1893,39
152,92801;2,5467;6,541;-5,04167;1895,85
153,12801;2,5499;6,546;-5,04168;1897,50
153,32801;2,5530;6,552;-5,04155;1899,19
153,52801;2,5566;6,562;-5,04166;1902,10
153,72801;2,5599;6,569;-5,04148;1904,07
153,92801;2,5631;6,577;-5,04143;1906,24
154,12801;2,5665;6,588;-5,04150;1909,44
154,32801;2,5699;6,600;-5,04155;1913,00
154,52801;2,5732;6,615;-5,04129;1917,34
154,72801;2,5765;6,630;-5,04160;1921,80
154,92801;2,5800;6,645;-5,04143;1926,08
155,12801;2,5832;6,657;-5,04150;1929,65
155,32801;2,5863;6,663;-5,04170;1931,45
155,52801;2,5900;6,675;-5,04159;1934,83
155,72801;2,5932;6,680;-5,04158;1936,37
155,92801;2,5964;6,684;-5,04167;1937,28
156,12801;2,6000;6,689;-5,04157;1938,75
156,32801;2,6032;6,691;-5,04160;1939,32
156,52801;2,6064;6,695;-5,04181;1940,51
156,72801;2,6099;6,698;-5,04163;1941,39
156,92801;2,6132;6,705;-5,04156;1943,42
157,12801;2,6165;6,711;-5,04175;1945,09
157,32801;2,6198;6,718;-5,04189;1947,37
157,52801;2,6233;6,728;-5,04160;1950,08
157,72801;2,6265;6,735;-5,04169;1952,08
157,92801;2,6298;6,745;-5,04158;1955,19
158,12801;2,6334;6,755;-5,04157;1958,09
158,32801;2,6365;6,765;-5,04174;1960,90
158,52801;2,6397;6,773;-5,04191;1963,08
158,72801;2,6433;6,782;-5,04156;1965,67
158,92801;2,6466;6,789;-5,04200;1967,91
159,12801;2,6498;6,797;-5,04190;1970,05
159,32801;2,6532;6,806;-5,04165;1972,66
159,52801;2,6566;6,818;-5,04205;1976,31
159,72801;2,6597;6,835;-5,04173;1981,12
159,92801;2,6632;6,844;-5,04173;1983,88
160,12801;2,6666;6,851;-5,04191;1985,77
160,32801;2,6698;6,859;-5,04183;1988,21
160,52801;2,6731;6,865;-5,04170;1989,81
160,72801;2,6767;6,869;-5,04218;1990,93
160,92801;2,6798;6,871;-5,04174;1991,66
161,12801;2,6831;6,873;-5,04174;1992,28
161,32801;2,6866;6,879;-5,04194;1993,87
161,52801;2,6899;6,886;-5,04161;1996,07
161,72801;2,6931;6,897;-5,04173;1999,08
161,92801;2,6967;6,908;-5,04183;2002,32
162,12801;2,6999;6,916;-5,04173;2004,76
162,32801;2,7031;6,924;-5,04163;2006,93
162,52801;2,7066;6,929;-5,04192;2008,52
162,72801;2,7099;6,934;-5,04160;2009,97
162,92801;2,7132;6,938;-5,04229;2010,98
163,12801;2,7165;6,943;-5,04189;2012,34
163,32801;2,7200;6,948;-5,04186;2013,81
163,52801;2,7232;6,951;-5,04211;2014,87
163,72801;2,7264;6,955;-5,04200;2015,81
163,92801;2,7300;6,962;-5,04184;2017,83
164,12801;2,7332;6,965;-5,04220;2018,88
164,32801;2,7363;6,970;-5,04206;2020,28
164,52801;2,7400;6,974;-5,04178;2021,33
164,72801;2,7432;6,978;-5,04229;2022,65
164,92801;2,7464;6,983;-5,04182;2024,04
165,12801;2,7499;6,988;-5,04193;2025,46
165,32801;2,7532;6,992;-5,04209;2026,64
165,52801;2,7564;6,996;-5,04191;2027,90
165,72801;2,7598;7,001;-5,04195;2029,37
165,92801;2,7633;7,006;-5,04209;2030,72
166,12801;2,7665;7,010;-5,04179;2031,97
166,32801;2,7697;7,014;-5,04180;2033,17
166,52801;2,7733;7,023;-5,04192;2035,77
166,72801;2,7766;7,032;-5,04172;2038,34
166,92801;2,7797;7,040;-5,04203;2040,57
167,12801;2,7833;7,052;-5,04195;2044,04
167,32801;2,7866;7,064;-5,04197;2047,48
167,52801;2,7897;7,073;-5,04221;2050,10
167,72801;2,7934;7,081;-5,04214;2052,34
167,92801;2,7965;7,086;-5,04194;2054,01
168,12801;2,7998;7,096;-5,04239;2056,75
168,32801;2,8032;7,102;-5,04213;2058,49
168,52801;2,8066;7,113;-5,04202;2061,61
168,72801;2,8099;7,121;-5,04255;2063,91
168,92801;2,8131;7,128;-5,04193;2066,16
169,12801;2,8166;7,141;-5,04197;2069,91
169,32801;2,8199;7,152;-5,04255;2073,06
169,52801;2,8230;7,161;-5,04251;2075,66
169,72801;2,8267;7,173;-5,04201;2079,27
169,92801;2,8298;7,181;-5,04230;2081,37
170,12801;2,8330;7,190;-5,04220;2084,06
170,32801;2,8367;7,200;-5,04233;2086,88
170,52801;2,8399;7,207;-5,04233;2089,03
170,72801;2,8431;7,212;-5,04220;2090,52
170,92801;2,8466;7,218;-5,04207;2092,25
171,12801;2,8499;7,226;-5,04233;2094,45
171,32801;2,8532;7,230;-5,04208;2095,52
171,52801;2,8564;7,237;-5,04213;2097,55
171,72801;2,8600;7,245;-5,04209;2100,10
171,92801;2,8632;7,249;-5,04194;2101,14
172,12801;2,8664;7,262;-5,04215;2104,96
172,32801;2,8700;7,272;-5,04182;2107,72
172,52801;2,8733;7,284;-5,04229;2111,16
172,72801;2,8763;7,290;-5,04210;2113,03
172,92801;2,8800;7,299;-5,04214;2115,66
173,12801;2,8833;7,304;-5,04215;2117,21
173,32801;2,8864;7,307;-5,04231;2118,00
173,52801;2,8899;7,314;-5,04198;2119,86
173,72801;2,8932;7,317;-5,04226;2120,73
173,92801;2,8964;7,318;-5,04228;2121,16
174,12801;2,8999;7,320;-5,04211;2121,60
174,32801;2,9032;7,321;-5,04237;2121,90
174,52801;2,9065;7,322;-5,04231;2122,29
174,72801;2,9098;7,323;-5,04222;2122,51
174,92801;2,9133;7,324;-5,04209;2122,86
175,12801;2,9165;7,325;-5,04237;2123,21
175,32801;2,9197;7,327;-5,04209;2123,79
175,52801;2,9233;7,330;-5,04205;2124,50
175,72801;2,9265;7,332;-5,04241;2125,16
175,92801;2,9297;7,334;-5,04235;2125,93
176,12801;2,9333;7,338;-5,04202;2126,92
176,32801;2,9366;7,341;-5,04233;2127,89
176,52801;2,9398;7,345;-5,04234;2128,93
176,72801;2,9432;7,349;-5,04197;2130,25
176,92801;2,9466;7,355;-5,04238;2131,88
177,12801;2,9497;7,361;-5,04201;2133,52
177,32801;2,9531;7,369;-5,04189;2136,01
177,52801;2,9567;7,378;-5,04225;2138,43
177,72801;2,9598;7,389;-5,04215;2141,84
177,92801;2,9631;7,400;-5,04207;2144,93
178,12801;2,9667;7,412;-5,04270;2148,51
178,32801;2,9698;7,418;-5,04217;2150,07
178,52801;2,9730;7,426;-5,04231;2152,45
178,72801;2,9766;7,434;-5,04262;2154,71
178,92801;2,9799;7,437;-5,04246;2155,76
179,12801;2,9830;7,443;-5,04226;2157,42
179,32801;2,9866;7,455;-5,04241;2160,79
179,52801;2,9898;7,464;-5,04218;2163,37
179,72801;2,9931;7,473;-5,04227;2166,05
179,92801;2,9966;7,487;-5,04245;2170,29
180,12801;2,9999;7,501;-5,04200;2174,33
180,32801;3,0032;7,514;-5,04254;2177,96
180,52801;3,0064;7,525;-5,04212;2181,15
180,72801;3,0100;7,540;-5,04234;2185,36
180,92801;3,0132;7,550;-5,04239;2188,30
181,12801;3,0164;7,555;-5,04221;2189,77
181,32801;3,0200;7,567;-5,04228;2193,22
181,52801;3,0232;7,575;-5,04255;2195,66
181,72801;3,0264;7,582;-5,04234;2197,58
181,92801;3,0300;7,589;-5,04227;2199,64
182,12801;3,0332;7,595;-5,04269;2201,31
182,32801;3,0365;7,601;-5,04217;2203,32
182,52801;3,0399;7,609;-5,04248;2205,37
182,72801;3,0433;7,614;-5,04248;2206,88
182,92801;3,0465;7,621;-5,04262;2208,90
183,12801;3,0498;7,623;-5,04239;2209,71
183,32801;3,0533;7,629;-5,04279;2211,26
183,52801;3,0566;7,635;-5,04227;2213,02
183,72801;3,0597;7,637;-5,04251;2213,66
183,92801;3,0633;7,643;-5,04259;2215,30
184,12801;3,0665;7,645;-5,04232;2216,07
184,32801;3,0697;7,652;-5,04249;2218,08
184,52801;3,0733;7,660;-5,04234;2220,21
184,72801;3,0765;7,667;-5,04249;2222,37
184,92801;3,0798;7,671;-5,04241;2223,53
185,12801;3,0833;7,679;-5,04258;2225,77
185,32801;3,0866;7,685;-5,04220;2227,49
185,52801;3,0898;7,692;-5,04288;2229,49
185,72801;3,0931;7,701;-5,04244;2232,23
185,92801;3,0966;7,707;-5,04238;2234,01
186,12801;3,0999;7,716;-5,04289;2236,60
186,32801;3,1031;7,720;-5,04251;2237,67
186,52801;3,1067;7,725;-5,04248;2239,26
186,72801;3,1099;7,730;-5,04268;2240,48
186,92801;3,1130;7,732;-5,04250;2241,03
187,12801;3,1167;7,737;-5,04255;2242,50
187,32801;3,1199;7,737;-5,04258;2242,72
187,52801;3,1230;7,740;-5,04243;2243,52
187,72801;3,1267;7,744;-5,04264;2244,78
187,92801;3,1299;7,749;-5,04250;2246,21
188,12801;3,1331;7,754;-5,04229;2247,50
188,32801;3,1366;7,757;-5,04246;2248,37
188,52801;3,1398;7,763;-5,04251;2250,29
188,72801;3,1432;7,747;-5,04247;2245,44
188,92801;3,1464;7,750;-5,04250;2246,51
189,12801;3,1500;7,756;-5,04259;2248,15
189,32801;3,1532;7,762;-5,04259;2249,81
189,52801;3,1564;7,766;-5,04259;2250,92
189,72801;3,1600;7,773;-5,04254;2252,97
189,92801;3,1632;7,777;-5,04254;2254,17
190,12801;3,1663;7,782;-5,04268;2255,62
190,32801;3,1700;7,789;-5,04273;2257,62
190,52801;3,1733;7,794;-5,04250;2259,14
190,72801;3,1764;7,801;-5,04270;2261,11
190,92801;3,1799;7,808;-5,04266;2263,11
191,12801;3,1833;7,812;-5,04276;2264,32
191,32801;3,1865;7,819;-5,04256;2266,31
191,52801;3,1898;7,821;-5,04296;2266,87
191,72801;3,1933;7,827;-5,04257;2268,62
191,92801;3,1966;7,831;-5,04264;2269,75
192,12801;3,1997;7,833;-5,04279;2270,49
192,32801;3,2034;7,839;-5,04248;2272,06
192,52801;3,2066;7,842;-5,04274;2272,96
192,72801;3,2097;7,847;-5,04266;2274,48
192,92801;3,2133;7,853;-5,04280;2276,29
193,12801;3,2165;7,859;-5,04248;2278,08
193,32801;3,2197;7,863;-5,04293;2279,09
193,52801;3,2233;7,871;-5,04257;2281,34
193,72801;3,2265;7,877;-5,04269;2283,10
193,92801;3,2298;7,882;-5,04245;2284,73
194,12801;3,2331;7,889;-5,04264;2286,53
194,32801;3,2366;7,894;-5,04261;2288,21
194,52801;3,2398;7,899;-5,04252;2289,62
194,72801;3,2431;7,729;-5,04297;2240,23
194,92801;3,2467;7,727;-5,04251;2239,81
195,12801;3,2499;7,731;-5,04259;2240,80
195,32801;3,2531;7,734;-5,04258;2241,79
195,52801;3,2567;7,738;-5,04274;2242,88
195,72801;3,2598;7,742;-5,04237;2244,08
195,92801;3,2630;7,749;-5,04288;2246,00
196,12801;3,2666;7,755;-5,04271;2247,89
196,32801;3,2699;7,761;-5,04245;2249,63
196,52801;3,2732;7,768;-5,04280;2251,46
196,72801;3,2765;7,774;-5,04257;2253,20
196,92801;3,2799;7,781;-5,04275;2255,36
197,12801;3,2831;7,788;-5,04292;2257,34
197,32801;3,2864;7,796;-5,04270;2259,65
197,52801;3,2900;7,803;-5,04279;2261,74
197,72801;3,2932;7,811;-5,04314;2263,99
197,92801;3,2964;7,817;-5,04262;2265,88
198,12801;3,3000;7,824;-5,04292;2267,93
198,32801;3,3032;7,830;-5,04276;2269,51
198,52801;3,3064;7,832;-5,04283;2270,16
198,72801;3,3099;7,836;-5,04296;2271,42
198,92801;3,3132;7,842;-5,04255;2272,94
199,12801;3,3164;7,849;-5,04270;2275,11
199,32801;3,3199;7,852;-5,04292;2276,03
199,52801;3,3233;7,859;-5,04250;2278,08
199,72801;3,3265;7,868;-5,04286;2280,52
199,92801;3,3298;7,877;-5,04321;2283,12
200,12801;3,3333;7,883;-5,04267;2284,90
200,32801;3,3366;7,890;-5,04280;2286,98
200,52801;3,3398;7,895;-5,04313;2288,49
200,72801;3,3434;7,901;-5,04261;2290,15
200,92801;3,3466;7,908;-5,04278;2292,06
201,12801;3,3497;7,911;-5,04321;2292,93
201,32801;3,3533;7,915;-5,04245;2294,09
201,52801;3,3565;7,919;-5,04301;2295,48
201,72801;3,3597;7,921;-5,04294;2295,97
201,92801;3,3632;7,927;-5,04257;2297,56
202,12801;3,3666;7,930;-5,04293;2298,48
202,32801;3,3698;7,934;-5,04290;2299,59
202,52801;3,3732;7,936;-5,04264;2300,26
202,72801;3,3765;7,941;-5,04297;2301,65
202,92801;3,3798;7,943;-5,04298;2302,31
203,12801;3,3831;7,946;-5,04256;2303,31
203,32801;3,3866;7,950;-5,04327;2304,42
203,52801;3,3899;7,955;-5,04284;2305,72
203,72801;3,3931;7,957;-5,04288;2306,45
203,92801;3,3966;7,965;-5,04307;2308,71
204,12801;3,3999;7,967;-5,04285;2309,17
204,32801;3,4030;7,971;-5,04289;2310,32
204,52801;3,4066;7,977;-5,04309;2312,09
204,72801;3,4099;7,983;-5,04281;2313,78
204,92801;3,4131;7,985;-5,04281;2314,37
205,12801;3,4166;7,989;-5,04329;2315,70
205,32801;3,4199;7,993;-5,04272;2316,84
205,52801;3,4232;7,998;-5,04320;2318,16
205,72801;3,4265;7,869;-5,04281;2280,83
205,85601;3,4289;7,418;-5,04287;2150,10
206,05601;3,4321;7,428;-5,04293;2152,94
206,25601;3,4352;7,434;-5,04313;2154,90
206,45601;3,4388;7,444;-5,04270;2157,62
206,65601;3,4420;7,454;-5,04272;2160,58
206,85601;3,4453;7,468;-5,04306;2164,76
207,05601;3,4487;7,481;-5,04273;2168,38
207,25601;3,4520;7,501;-5,04317;2174,10
207,45601;3,4553;7,516;-5,04287;2178,47
207,65601;3,4586;7,533;-5,04291;2183,37
207,85601;3,4621;7,546;-5,04289;2187,30
208,05601;3,4653;7,558;-5,04277;2190,70
208,25601;3,4685;7,568;-5,04274;2193,58
208,45601;3,4721;7,577;-5,04289;2196,28
208,65601;3,4753;7,588;-5,04285;2199,56
208,85601;3,4786;7,595;-5,04283;2201,53
209,05601;3,4821;7,605;-5,04302;2204,26
209,25601;3,4854;7,612;-5,04261;2206,29
209,45601;3,4886;7,620;-5,04303;2208,70
209,65601;3,4921;7,626;-5,04276;2210,39
209,85601;3,4954;7,631;-5,04307;2212,02
210,05601;3,4985;7,634;-5,04269;2212,87
210,25601;3,5019;7,491;-5,04292;2171,41
210,45601;3,5055;7,512;-5,04281;2177,31
210,65601;3,5087;7,530;-5,04296;2182,69
210,85601;3,5119;7,544;-5,04309;2186,64
211,05601;3,5154;7,560;-5,04271;2191,16
211,25601;3,5187;7,569;-5,04285;2193,85
211,45601;3,5218;7,578;-5,04288;2196,46
211,65601;3,5255;7,587;-5,04298;2199,20
211,85601;3,5287;7,597;-5,04282;2201,89
212,05601;3,5318;7,602;-5,04352;2203,59
212,25601;3,5354;7,608;-5,04280;2205,07
212,45601;3,5387;7,615;-5,04271;2207,23
212,65601;3,5419;7,618;-5,04337;2208,24
212,85601;3,5453;7,625;-5,04276;2210,19
213,05601;3,5487;7,632;-5,04277;2212,10
213,25601;3,5519;7,635;-5,04341;2213,06
213,45601;3,5552;7,640;-5,04267;2214,40
213,65601;3,5587;7,645;-5,04277;2216,07
213,85601;3,5620;7,653;-5,04336;2218,28
214,05601;3,5652;7,657;-5,04270;2219,55
214,25601;3,5688;7,665;-5,04303;2221,71
214,45601;3,5720;7,671;-5,04324;2223,53
214,65601;3,5752;7,677;-5,04247;2225,28
214,85601;3,5789;7,685;-5,04322;2227,53
215,05601;3,5820;7,692;-5,04312;2229,62
215,25601;3,5853;7,509;-5,04271;2176,58
215,26401;3,5855;6,254;-5,04172;1812,80
215,26601;3,5856;5,839;-5,04148;1692,45