File: Klausurvorbereitung/Übungen/UE5_Specimen_RawData_3.csv
Texteingaben : Proben-beschriftung;"dpp-PUL6-3"
Allgemein : Startdatum;16.08.2018 16:22:52
Abmessung : Querschnitt;3,45000;mm^2

Zeit;Traversenweg;Last;Dehnung 1;Zugspannung
(sec);(mm);(kN);(%);(MPa)
0,00000;-0,0001;0,084;0,00231;24,37
0,20000;0,0010;0,088;0,00248;25,61
0,40000;0,0054;0,106;0,00418;30,62
0,60000;0,0099;0,136;0,00703;39,37
0,80000;0,0132;0,155;0,00905;44,84
1,00000;0,0164;0,172;0,01080;49,80
1,20000;0,0200;0,184;0,01299;53,28
1,40000;0,0232;0,191;0,01486;55,47
1,60000;0,0264;0,196;0,01679;56,78
1,80000;0,0300;0,202;0,01908;58,41
2,00000;0,0332;0,207;0,02093;59,86
2,20000;0,0364;0,209;0,02276;60,48
2,40000;0,0399;0,211;0,02483;61,19
2,60000;0,0432;0,213;0,02684;61,82
2,80000;0,0464;0,216;0,02871;62,72
3,00000;0,0498;0,219;0,03068;63,57
3,20000;0,0532;0,223;0,03278;64,56
3,40000;0,0565;0,225;0,03469;65,29
3,60000;0,0598;0,230;0,03655;66,53
3,80000;0,0633;0,238;0,03870;68,94
4,00000;0,0665;0,249;0,04055;72,26
4,20000;0,0697;0,261;0,04237;75,78
4,40000;0,0734;0,281;0,04462;81,55
4,60000;0,0765;0,295;0,04646;85,44
4,80000;0,0797;0,308;0,04832;89,20
5,00000;0,0833;0,320;0,05039;92,76
5,20000;0,0865;0,330;0,05231;95,56
5,40000;0,0898;0,337;0,05428;97,60
5,60000;0,0932;0,348;0,05625;100,81
5,80000;0,0966;0,356;0,05824;103,23
6,00000;0,0998;0,367;0,06007;106,26
6,20000;0,1031;0,376;0,06199;109,06
6,40000;0,1066;0,388;0,06405;112,55
6,60000;0,1099;0,400;0,06592;116,02
6,80000;0,1131;0,415;0,06773;120,37
7,00000;0,1167;0,428;0,06986;123,97
7,20000;0,1199;0,441;0,07164;127,81
7,40000;0,1231;0,453;0,07352;131,29
7,60000;0,1267;0,461;0,07552;133,68
7,80000;0,1299;0,467;0,07738;135,32
8,00000;0,1331;0,471;0,07927;136,54
8,20000;0,1365;0,475;0,08130;137,77
8,40000;0,1399;0,479;0,08331;138,95
8,60000;0,1431;0,482;0,08511;139,71
8,80000;0,1466;0,487;0,08711;141,11
9,00000;0,1499;0,490;0,08915;142,10
9,20000;0,1532;0,495;0,09096;143,59
9,40000;0,1564;0,501;0,09276;145,13
9,60000;0,1599;0,508;0,09474;147,38
9,80000;0,1632;0,519;0,09659;150,37
10,00000;0,1664;0,529;0,09841;153,27
10,20000;0,1700;0,541;0,10044;156,80
10,40000;0,1732;0,557;0,10238;161,32
10,60000;0,1765;0,569;0,10426;164,89
10,80000;0,1800;0,589;0,10631;170,79
11,00000;0,1833;0,603;0,10816;174,74
11,20000;0,1864;0,618;0,10998;179,19
11,40000;0,1899;0,629;0,11191;182,35
11,60000;0,1933;0,640;0,11394;185,37
11,80000;0,1965;0,649;0,11580;188,01
12,00000;0,1998;0,655;0,11745;189,91
12,20000;0,2033;0,664;0,11944;192,49
12,40000;0,2066;0,673;0,12136;195,22
12,60000;0,2097;0,679;0,12307;196,83
12,80000;0,2133;0,689;0,12500;199,77
13,00000;0,2166;0,697;0,12685;201,97
13,20000;0,2197;0,704;0,12865;204,19
13,40000;0,2233;0,720;0,13064;208,81
13,60000;0,2266;0,735;0,13245;213,00
13,80000;0,2297;0,749;0,13420;217,07
14,00000;0,2333;0,765;0,13606;221,77
14,20000;0,2365;0,779;0,13806;225,66
14,40000;0,2398;0,784;0,13988;227,36
14,60000;0,2432;0,789;0,14180;228,69
14,80000;0,2466;0,793;0,14369;229,83
15,00000;0,2498;0,796;0,14550;230,61
15,20000;0,2531;0,797;0,14737;231,10
15,40000;0,2566;0,802;0,14931;232,53
15,60000;0,2599;0,806;0,15117;233,50
15,80000;0,2631;0,812;0,15284;235,25
16,00000;0,2667;0,817;0,15487;236,68
16,20000;0,2699;0,820;0,15660;237,79
16,40000;0,2730;0,826;0,15833;239,45
16,60000;0,2767;0,830;0,16025;240,46
16,80000;0,2799;0,834;0,16209;241,72
17,00000;0,2830;0,841;0,16397;243,81
17,20000;0,2865;0,850;0,16590;246,41
17,40000;0,2899;0,862;0,16777;249,92
17,60000;0,2932;0,875;0,16963;253,63
17,80000;0,2965;0,888;0,17141;257,48
18,00000;0,3000;0,900;0,17325;261,00
18,20000;0,3032;0,911;0,17497;263,92
18,40000;0,3063;0,922;0,17680;267,12
18,60000;0,3100;0,934;0,17882;270,62
18,80000;0,3131;0,944;0,18044;273,63
19,00000;0,3164;0,955;0,18218;276,77
19,20000;0,3201;0,972;0,18419;281,85
19,40000;0,3232;0,987;0,18591;286,09
19,60000;0,3264;1,002;0,18772;290,38
19,80000;0,3300;1,016;0,18969;294,47
20,00000;0,3333;1,030;0,19152;298,47
20,20000;0,3365;1,050;0,19327;304,24
20,40000;0,3398;1,064;0,19514;308,48
20,60000;0,3433;1,079;0,19705;312,88
20,80000;0,3466;1,094;0,19880;317,21
21,00000;0,3498;1,103;0,20056;319,68
21,20000;0,3533;1,111;0,20248;322,09
21,40000;0,3565;1,117;0,20424;323,76
21,60000;0,3597;1,120;0,20594;324,53
21,80000;0,3634;1,122;0,20793;325,30
22,00000;0,3665;1,125;0,20969;326,01
22,20000;0,3697;1,127;0,21137;326,66
22,40000;0,3734;1,130;0,21333;327,54
22,60000;0,3765;1,134;0,21508;328,80
22,80000;0,3797;1,139;0,21679;330,18
23,00000;0,3833;1,145;0,21863;331,97
23,20000;0,3865;1,151;0,22048;333,53
23,40000;0,3898;1,157;0,22224;335,39
23,60000;0,3932;1,162;0,22402;336,90
23,80000;0,3966;1,171;0,22592;339,35
24,00000;0,3998;1,180;0,22764;342,00
24,20000;0,4031;1,193;0,22934;345,92
24,40000;0,4066;1,206;0,23137;349,44
24,60000;0,4099;1,217;0,23305;352,78
24,80000;0,4131;1,228;0,23470;356,04
25,00000;0,4167;1,239;0,23666;359,24
25,20000;0,4199;1,250;0,23839;362,28
25,40000;0,4231;1,259;0,24012;364,80
25,60000;0,4266;1,269;0,24197;367,95
25,80000;0,4299;1,276;0,24370;369,91
26,00000;0,4331;1,287;0,24545;373,12
26,20000;0,4366;1,297;0,24734;375,93
26,40000;0,4399;1,304;0,24916;377,87
26,60000;0,4432;1,315;0,25088;381,22
26,80000;0,4465;1,327;0,25263;384,74
27,00000;0,4499;1,339;0,25447;388,11
27,20000;0,4532;1,353;0,25620;392,25
27,40000;0,4563;1,366;0,25790;395,98
27,60000;0,4600;1,375;0,25989;398,55
27,80000;0,4632;1,383;0,26164;400,76
28,00000;0,4664;1,390;0,26325;402,77
28,20000;0,4700;1,397;0,26520;404,85
28,40000;0,4732;1,404;0,26690;406,93
28,60000;0,4764;1,411;0,26859;408,85
28,80000;0,4800;1,422;0,27048;412,17
29,00000;0,4832;1,431;0,27222;414,91
29,20000;0,4865;1,439;0,27398;417,09
29,40000;0,4899;1,448;0,27570;419,68
29,60000;0,4933;1,454;0,27753;421,59
29,80000;0,4966;1,464;0,27930;424,46
30,00000;0,4998;1,471;0,28090;426,30
30,20000;0,5033;1,479;0,28290;428,65
30,40000;0,5066;1,486;0,28455;430,66
30,60000;0,5097;1,493;0,28630;432,86
30,80000;0,5133;1,506;0,28818;436,54
31,00000;0,5166;1,520;0,28980;440,64
31,20000;0,5196;1,533;0,29153;444,26
31,40000;0,5233;1,548;0,29337;448,67
31,60000;0,5266;1,555;0,29517;450,68
31,80000;0,5297;1,563;0,29677;452,92
32,00000;0,5332;1,573;0,29863;456,06
32,20000;0,5366;1,585;0,30038;459,37
32,40000;0,5398;1,597;0,30213;462,84
32,60000;0,5432;1,608;0,30379;466,16
32,80000;0,5466;1,618;0,30554;469,08
33,00000;0,5498;1,628;0,30727;471,89
33,20000;0,5531;1,633;0,30908;473,29
33,40000;0,5566;1,640;0,31086;475,25
33,60000;0,5599;1,649;0,31254;477,93
33,80000;0,5631;1,659;0,31423;480,92
34,00000;0,5667;1,675;0,31612;485,63
34,20000;0,5699;1,685;0,31774;488,53
34,40000;0,5730;1,693;0,31942;490,65
34,60000;0,5766;1,701;0,32122;492,99
34,80000;0,5799;1,707;0,32290;494,68
35,00000;0,5832;1,711;0,32464;496,00
35,20000;0,5865;1,718;0,32631;498,03
35,40000;0,5899;1,723;0,32815;499,46
35,60000;0,5931;1,729;0,32975;501,05
35,80000;0,5964;1,731;0,33149;501,86
36,00000;0,6000;1,735;0,33343;503,00
36,20000;0,6032;1,737;0,33512;503,53
36,40000;0,6064;1,740;0,33668;504,27
36,60000;0,6101;1,744;0,33856;505,38
36,80000;0,6132;1,747;0,34008;506,40
37,00000;0,6164;1,754;0,34176;508,32
37,20000;0,6199;1,761;0,34358;510,57
37,40000;0,6232;1,773;0,34524;514,02
37,60000;0,6264;1,789;0,34690;518,68
37,80000;0,6300;1,808;0,34872;524,00
38,00000;0,6332;1,824;0,35044;528,84
38,20000;0,6365;1,843;0,35211;534,17
38,40000;0,6399;1,858;0,35378;538,44
38,60000;0,6433;1,872;0,35567;542,51
38,80000;0,6465;1,881;0,35730;545,23
39,00000;0,6498;1,891;0,35885;548,01
39,20000;0,6533;1,903;0,36071;551,47
39,40000;0,6566;1,915;0,36230;555,11
39,60000;0,6598;1,927;0,36391;558,42
39,80000;0,6633;1,938;0,36573;561,82
40,00000;0,6665;1,952;0,36735;565,81
40,20000;0,6697;1,963;0,36896;569,01
40,40000;0,6733;1,977;0,37074;573,13
40,60000;0,6766;1,995;0,37244;578,29
40,80000;0,6798;2,005;0,37414;581,22
41,00000;0,6832;2,016;0,37580;584,37
41,20000;0,6866;2,024;0,37764;586,61
41,40000;0,6898;2,030;0,37915;588,53
41,60000;0,6931;2,034;0,38082;589,61
41,80000;0,6967;2,041;0,38264;591,62
42,00000;0,6999;2,046;0,38438;592,97
42,20000;0,7030;2,051;0,38593;594,59
42,40000;0,7066;2,056;0,38777;595,88
42,60000;0,7099;2,059;0,38933;596,90
42,80000;0,7131;2,062;0,39104;597,63
43,00000;0,7167;2,063;0,39295;598,00
43,20000;0,7199;2,064;0,39457;598,33
43,40000;0,7231;2,065;0,39617;598,49
43,60000;0,7267;2,067;0,39785;599,14
43,80000;0,7299;2,069;0,39959;599,85
44,00000;0,7332;2,076;0,40119;601,81
44,20000;0,7365;2,083;0,40275;603,79
44,40000;0,7399;2,096;0,40454;607,58
44,60000;0,7432;2,111;0,40613;611,81
44,80000;0,7464;2,122;0,40779;615,07
45,00000;0,7500;2,138;0,40959;619,71
45,20000;0,7533;2,148;0,41118;622,60
45,40000;0,7564;2,158;0,41273;625,44
45,60000;0,7600;2,169;0,41459;628,63
45,80000;0,7632;2,176;0,41624;630,58
46,00000;0,7664;2,187;0,41786;633,98
46,20000;0,7700;2,198;0,41963;637,02
46,40000;0,7732;2,207;0,42119;639,60
46,60000;0,7764;2,217;0,42281;642,55
46,80000;0,7800;2,227;0,42450;645,61
47,00000;0,7832;2,236;0,42614;648,21
47,20000;0,7865;2,249;0,42775;651,83
47,40000;0,7897;2,260;0,42935;655,05
47,60000;0,7933;2,281;0,43129;661,29
47,80000;0,7966;2,301;0,43289;667,06
48,00000;0,7998;2,314;0,43441;670,59
48,20000;0,8033;2,325;0,43613;674,01
48,40000;0,8066;2,337;0,43786;677,50
48,60000;0,8096;2,344;0,43941;679,32
48,80000;0,8133;2,353;0,44113;682,01
49,00000;0,8166;2,361;0,44281;684,48
49,20000;0,8197;2,369;0,44433;686,59
49,40000;0,8233;2,373;0,44609;687,92
49,60000;0,8266;2,378;0,44774;689,41
49,80000;0,8298;2,384;0,44930;691,10
50,00000;0,8332;2,388;0,45085;692,23
50,20000;0,8366;2,392;0,45263;693,46
50,40000;0,8399;2,398;0,45425;695,22
50,60000;0,8431;2,404;0,45573;696,90
50,80000;0,8467;2,411;0,45758;698,93
51,00000;0,8498;2,423;0,45909;702,23
51,20000;0,8530;2,433;0,46067;705,24
51,40000;0,8566;2,449;0,46238;709,79
51,60000;0,8598;2,463;0,46396;713,97
51,80000;0,8631;2,477;0,46550;717,83
52,00000;0,8666;2,492;0,46725;722,29
52,20000;0,8699;2,503;0,46888;725,57
52,40000;0,8732;2,512;0,47045;728,23
52,60000;0,8765;2,517;0,47204;729,66
52,80000;0,8799;2,522;0,47379;730,93
53,00000;0,8831;2,525;0,47538;731,87
53,20000;0,8864;2,530;0,47692;733,35
53,40000;0,8900;2,536;0,47881;735,05
53,60000;0,8932;2,544;0,48029;737,26
53,80000;0,8964;2,550;0,48180;739,05
54,00000;0,9001;2,560;0,48356;742,05
54,20000;0,9032;2,576;0,48502;746,59
54,40000;0,9063;2,591;0,48658;750,98
54,60000;0,9100;2,604;0,48827;754,89
54,80000;0,9133;2,616;0,48984;758,34
55,00000;0,9165;2,624;0,49136;760,59
55,20000;0,9199;2,630;0,49300;762,31
55,40000;0,9232;2,636;0,49456;763,93
55,60000;0,9265;2,639;0,49622;765,02
55,80000;0,9298;2,642;0,49788;765,84
56,00000;0,9333;2,647;0,49960;767,19
56,20000;0,9365;2,651;0,50112;768,40
56,40000;0,9397;2,655;0,50264;769,69
56,60000;0,9433;2,662;0,50443;771,48
56,80000;0,9465;2,671;0,50587;774,24
56,98800;0,9495;2,679;0,50732;776,53
57,18800;0,9531;2,686;0,50904;778,50
57,38800;0,9563;2,694;0,51058;780,96
57,58800;0,9595;2,703;0,51211;783,39
57,78800;0,9631;2,712;0,51378;786,02
57,98800;0,9663;2,720;0,51542;788,49
58,18800;0,9696;2,735;0,51701;792,78
58,38800;0,9730;2,750;0,51855;797,10
58,58800;0,9764;2,764;0,52024;801,21
58,78800;0,9797;2,777;0,52187;805,06
58,98800;0,9829;2,792;0,52320;809,33
59,18800;0,9865;2,803;0,52508;812,39
59,38800;0,9897;2,815;0,52656;816,02
59,58800;0,9929;2,829;0,52803;820,13
59,78800;0,9964;2,843;0,52966;824,11
59,98800;0,9997;2,854;0,53119;827,14
60,18800;1,0029;2,864;0,52716;830,12
60,38800;1,0063;2,874;0,48508;832,90
60,58800;1,0097;2,880;0,40304;834,72
60,78800;1,0129;2,887;-3,39224;836,75
60,98800;1,0163;2,897;-2,14007;839,62
61,18800;1,0197;2,908;-3,83715;842,87
61,38800;1,0229;2,922;-2,80758;847,00
61,58800;1,0262;2,936;-0,19161;850,91
61,78800;1,0297;2,951;-2,24208;855,32
61,98800;1,0330;2,958;-2,14846;857,53
62,18800;1,0362;2,964;-2,05521;859,14
62,38800;1,0398;2,969;-3,78521;860,61
62,58800;1,0430;2,971;-2,43907;861,25
62,78800;1,0462;2,973;-3,40548;861,63
62,98800;1,0498;2,973;-2,47096;861,86
63,18800;1,0530;2,974;-2,50144;862,03
63,38800;1,0562;2,975;-2,56966;862,23
63,58800;1,0598;2,975;-2,60562;862,45
63,78800;1,0631;2,976;-2,63012;862,74
63,98800;1,0663;2,979;-2,66319;863,37
64,18800;1,0696;2,981;-2,60594;864,02
64,38800;1,0731;2,984;-2,64656;865,06
64,58800;1,0764;2,991;-2,62989;866,87
64,78800;1,0796;2,997;-2,63032;868,69
64,98800;1,0832;3,007;-2,63673;871,62
65,18800;1,0864;3,016;-2,63029;874,09
65,38800;1,0896;3,029;-2,63454;878,02
65,58800;1,0931;3,047;-2,63292;883,30
65,78800;1,0964;3,060;-2,63319;886,84
65,98800;1,0995;3,075;-2,63365;891,41
66,18800;1,1030;3,091;-2,63312;895,83
66,38800;1,1064;3,100;-2,63328;898,68
66,58800;1,1095;3,110;-2,63349;901,43
66,78800;1,1130;3,119;-2,63321;904,07
66,98800;1,1163;3,126;-2,63362;905,97
67,18800;1,1196;3,135;-2,63338;908,65
67,38800;1,1228;3,146;-2,63350;911,92
67,58800;1,1264;3,160;-2,63346;915,92
67,78800;1,1297;3,175;-2,63351;920,18
67,98800;1,1329;3,193;-2,63354;925,64
68,18800;1,1364;3,214;-2,63324;931,47
68,38800;1,1397;3,228;-2,63370;935,56
68,58800;1,1428;3,243;-2,63342;939,92
68,78800;1,1464;3,254;-2,63363;943,14
68,98800;1,1497;3,265;-2,63376;946,26
69,18800;1,1529;3,273;-2,63398;948,72
69,38800;1,1564;3,280;-2,63404;950,80
69,58800;1,1597;3,285;-2,63413;952,11
69,78800;1,1630;3,293;-2,63423;954,53
69,98800;1,1663;3,299;-2,63438;956,36
70,18800;1,1697;3,306;-2,63422;958,27
70,38800;1,1730;3,311;-2,63398;959,82
70,58800;1,1762;3,318;-2,63424;961,68
70,78800;1,1798;3,325;-2,63430;963,74
70,98800;1,1830;3,328;-2,63446;964,77
71,18800;1,1861;3,332;-2,63426;965,91
71,38800;1,1898;3,336;-2,63432;967,09
71,58800;1,1930;3,342;-2,63433;968,81
71,78800;1,1962;3,346;-2,63462;969,96
71,98800;1,1998;3,352;-2,63436;971,74
72,18800;1,2030;3,363;-2,63477;974,90
72,38800;1,2063;3,372;-2,63464;977,25
72,58800;1,2097;3,382;-2,63445;980,31
72,78800;1,2130;3,390;-2,63450;982,55
72,98800;1,2163;3,394;-2,63464;983,88
73,18800;1,2196;3,399;-2,63449;985,19
73,38800;1,2231;3,403;-2,63447;986,32
73,58800;1,2264;3,409;-2,63445;988,21
73,78800;1,2295;3,414;-2,63454;989,63
73,98800;1,2332;3,423;-2,63443;992,31
74,18800;1,2363;3,432;-2,63454;994,90
74,38800;1,2395;3,445;-2,63440;998,65
74,58800;1,2431;3,452;-2,63478;1000,69
74,78800;1,2463;3,462;-2,63450;1003,40
74,98800;1,2495;3,472;-2,63432;1006,24
75,18800;1,2530;3,478;-2,63487;1008,22
75,38800;1,2564;3,492;-2,63468;1012,17
75,58800;1,2597;3,504;-2,63472;1015,67
75,78800;1,2629;3,516;-2,63466;1019,27
75,98800;1,2664;3,535;-2,63472;1024,58
76,18800;1,2697;3,542;-2,63485;1026,81
76,38800;1,2729;3,554;-2,63460;1030,11
76,58800;1,2765;3,564;-2,63488;1033,04
76,78800;1,2797;3,571;-2,63461;1034,95
76,98800;1,2829;3,578;-2,63477;1037,15
77,18800;1,2864;3,585;-2,63473;1039,27
77,38800;1,2897;3,591;-2,63488;1040,89
77,58800;1,2929;3,598;-2,63484;1042,87
77,78800;1,2964;3,602;-2,63482;1044,16
77,98800;1,2997;3,607;-2,63481;1045,55
78,18800;1,3030;3,611;-2,63475;1046,79
78,38800;1,3063;3,616;-2,63494;1047,98
78,58800;1,3097;3,623;-2,63477;1050,06
78,78800;1,3129;3,629;-2,63506;1052,02
78,98800;1,3162;3,637;-2,63489;1054,23
79,18800;1,3198;3,647;-2,63502;1057,06
79,38800;1,3230;3,660;-2,63489;1060,82
79,58800;1,3262;3,675;-2,63512;1065,28
79,78800;1,3298;3,686;-2,63493;1068,50
79,98800;1,3330;3,705;-2,63492;1073,99
80,18800;1,3362;3,719;-2,63500;1077,99
80,38800;1,3397;3,735;-2,63497;1082,58
80,58800;1,3430;3,749;-2,63500;1086,69
80,78800;1,3462;3,759;-2,63494;1089,70
80,98800;1,3497;3,768;-2,63516;1092,25
81,18800;1,3530;3,774;-2,63485;1093,92
81,38800;1,3563;3,781;-2,63511;1096,03
81,58800;1,3595;3,785;-2,63491;1097,18
81,78800;1,3631;3,796;-2,63510;1100,21
81,98800;1,3664;3,806;-2,63493;1103,21
82,18800;1,3696;3,821;-2,63504;1107,43
82,38800;1,3731;3,832;-2,63506;1110,66
82,58800;1,3764;3,844;-2,63523;1114,34
82,78800;1,3796;3,852;-2,63515;1116,53
82,98800;1,3831;3,861;-2,63523;1119,24
83,18800;1,3864;3,865;-2,63504;1120,34
83,38800;1,3895;3,868;-2,63490;1121,26
83,58800;1,3930;3,871;-2,63523;1121,98
83,78800;1,3964;3,873;-2,63516;1122,54
83,98800;1,3996;3,874;-2,63528;1122,88
84,18800;1,4029;3,875;-2,63522;1123,18
84,38800;1,4064;3,877;-2,63516;1123,64
84,58800;1,4096;3,878;-2,63520;1124,01
84,78800;1,4129;3,880;-2,63529;1124,57
84,98800;1,4165;3,882;-2,63499;1125,36
85,18800;1,4197;3,885;-2,63514;1126,12
85,38800;1,4228;3,889;-2,63521;1127,20
85,58800;1,4265;3,895;-2,63512;1129,06
85,78800;1,4296;3,899;-2,63511;1130,22
85,98800;1,4329;3,909;-2,63511;1132,94
86,18800;1,4364;3,918;-2,63513;1135,64
86,38800;1,4397;3,935;-2,63512;1140,49
86,58800;1,4429;3,949;-2,63528;1144,74
86,78800;1,4463;3,965;-2,63505;1149,28
86,98800;1,4497;3,979;-2,63516;1153,28
87,18800;1,4530;3,993;-2,63506;1157,25
87,38800;1,4562;4,007;-2,63524;1161,38
87,58800;1,4598;4,012;-2,63503;1162,83
87,78800;1,4630;4,026;-2,63531;1167,02
87,98800;1,4662;4,034;-2,63516;1169,25
88,18800;1,4699;4,047;-2,63517;1172,99
88,38800;1,4730;4,058;-2,63483;1176,27
88,58800;1,4761;4,070;-2,63502;1179,62
88,78800;1,4798;4,083;-2,63532;1183,44
88,98800;1,4830;4,093;-2,63498;1186,25
89,18800;1,4862;4,102;-2,63544;1189,05
89,38800;1,4897;4,113;-2,63507;1192,25
89,58800;1,4931;4,123;-2,63535;1195,16
89,78800;1,4963;4,136;-2,63515;1198,94
89,98800;1,4996;4,150;-2,63548;1202,85
90,18800;1,5030;4,168;-2,63509;1208,01
90,38800;1,5063;4,184;-2,63552;1212,61
90,58800;1,5095;4,196;-2,63526;1216,10
90,78800;1,5132;4,216;-2,63522;1221,98
90,98800;1,5163;4,220;-2,63543;1223,08
91,18800;1,5195;4,228;-2,63527;1225,51
91,38800;1,5231;4,234;-2,63552;1227,17
91,58800;1,5264;4,237;-2,63518;1228,15
91,78800;1,5295;4,240;-2,63547;1228,99
91,98800;1,5331;4,242;-2,63528;1229,54
92,18800;1,5364;4,243;-2,63547;1229,90
92,38800;1,5396;4,245;-2,63530;1230,35
92,58800;1,5430;4,245;-2,63544;1230,56
92,78800;1,5464;4,246;-2,63541;1230,84
92,98800;1,5497;4,247;-2,63535;1231,09
93,18800;1,5529;4,248;-2,63551;1231,43
93,38800;1,5565;4,250;-2,63540;1232,03
93,58800;1,5597;4,252;-2,63548;1232,53
93,78800;1,5628;4,255;-2,63535;1233,47
93,98800;1,5665;4,259;-2,63558;1234,54
94,18800;1,5697;4,266;-2,63532;1236,49
94,38800;1,5728;4,272;-2,63562;1238,25
94,58800;1,5764;4,283;-2,63544;1241,48
94,78800;1,5797;4,290;-2,63548;1243,45
94,98800;1,5829;4,305;-2,63552;1247,76
95,18800;1,5864;4,317;-2,63562;1251,42
95,38800;1,5897;4,329;-2,63563;1254,92
95,58800;1,5930;4,339;-2,63556;1257,54
95,78800;1,5962;4,347;-2,63555;1260,02
95,98800;1,5997;4,355;-2,63545;1262,27
96,18800;1,6030;4,364;-2,63562;1264,88
96,38800;1,6062;4,372;-2,63542;1267,15
96,58800;1,6098;4,387;-2,63568;1271,56
96,78800;1,6130;4,402;-2,63562;1275,94
96,98800;1,6162;4,417;-2,63550;1280,16
97,18800;1,6197;4,432;-2,63560;1284,75
97,38800;1,6231;4,445;-2,63566;1288,49
97,58800;1,6263;4,457;-2,63559;1292,02
97,78800;1,6297;4,467;-2,63557;1294,85
97,98800;1,6331;4,475;-2,63565;1297,11
98,18800;1,6363;4,483;-2,63560;1299,53
98,38800;1,6397;4,492;-2,63564;1301,92
98,58800;1,6431;4,500;-2,63549;1304,31
98,78800;1,6463;4,507;-2,63566;1306,25
98,98800;1,6495;4,513;-2,63556;1308,23
99,18800;1,6531;4,522;-2,63559;1310,72
99,38800;1,6564;4,528;-2,63559;1312,40
99,58800;1,6595;4,534;-2,63569;1314,25
99,78800;1,6631;4,538;-2,63550;1315,44
99,98800;1,6663;4,543;-2,63579;1316,82
100,18800;1,6695;4,547;-2,63551;1318,05
100,38800;1,6731;4,553;-2,63578;1319,71
100,58800;1,6764;4,559;-2,63581;1321,57
100,78800;1,6796;4,567;-2,63570;1323,67
100,98800;1,6830;4,575;-2,63577;1326,07
101,18800;1,6864;4,588;-2,63573;1329,72
101,38800;1,6897;4,600;-2,63577;1333,47
101,58800;1,6929;4,611;-2,63561;1336,47
101,78800;1,6965;4,627;-2,63583;1341,04
101,98800;1,6997;4,638;-2,63562;1344,46
102,18800;1,7029;4,647;-2,63587;1346,92
102,38800;1,7065;4,657;-2,63567;1349,83
102,58800;1,7097;4,664;-2,63586;1351,86
102,78800;1,7129;4,670;-2,63577;1353,51
102,98800;1,7165;4,678;-2,63588;1355,83
103,18800;1,7197;4,686;-2,63575;1358,22
103,38800;1,7228;4,692;-2,63578;1359,89
103,58800;1,7263;4,703;-2,63600;1363,30
103,78800;1,7297;4,710;-2,63555;1365,20
103,98800;1,7329;4,715;-2,63594;1366,63
104,18800;1,7363;4,719;-2,63568;1367,69
104,38800;1,7397;4,721;-2,63602;1368,54
104,58800;1,7430;4,726;-2,63578;1369,84
104,78800;1,7462;4,730;-2,63588;1370,93
104,98800;1,7498;4,737;-2,63586;1372,92
105,18800;1,7530;4,743;-2,63588;1374,87
105,38801;1,7562;4,751;-2,63595;1377,22
105,58801;1,7598;4,759;-2,63575;1379,38
105,78801;1,7630;4,768;-2,63596;1382,01
105,98801;1,7662;4,774;-2,63574;1383,72
106,18801;1,7698;4,779;-2,63611;1385,17
106,38801;1,7731;4,782;-2,63572;1386,11
106,58801;1,7763;4,786;-2,63601;1387,29
106,78801;1,7797;4,790;-2,63588;1388,42
106,98801;1,7831;4,795;-2,63585;1389,98
107,18801;1,7864;4,800;-2,63576;1391,34
107,38801;1,7896;4,806;-2,63589;1393,05
107,58801;1,7931;4,813;-2,63595;1395,08
107,78801;1,7964;4,821;-2,63580;1397,32
107,98801;1,7995;4,829;-2,63598;1399,65
108,18801;1,8032;4,837;-2,63580;1402,09
108,38801;1,8064;4,847;-2,63597;1404,87
108,58801;1,8095;4,857;-2,63578;1407,69
108,78801;1,8131;4,866;-2,63602;1410,29
108,98801;1,8163;4,876;-2,63577;1413,48
109,18801;1,8195;4,883;-2,63607;1415,43
109,38801;1,8231;4,894;-2,63601;1418,56
109,58801;1,8263;4,902;-2,63586;1420,89
109,78801;1,8296;4,910;-2,63590;1423,30
109,98801;1,8330;4,921;-2,63595;1426,30
110,18801;1,8364;4,934;-2,63585;1430,07
110,38801;1,8396;4,944;-2,63589;1433,12
110,58801;1,8429;4,958;-2,63596;1437,16
110,78801;1,8464;4,972;-2,63586;1441,30
110,98801;1,8497;4,986;-2,63606;1445,23
111,18801;1,8528;4,993;-2,63590;1447,14
111,38801;1,8565;5,004;-2,63597;1450,40
111,58801;1,8597;5,016;-2,63585;1453,91
111,78801;1,8628;5,025;-2,63600;1456,60
111,98801;1,8663;5,041;-2,63600;1461,10
112,18801;1,8697;5,054;-2,63613;1465,03
112,38801;1,8730;5,070;-2,63592;1469,42
112,58801;1,8763;5,083;-2,63607;1473,47
112,78801;1,8798;5,097;-2,63595;1477,45
112,98801;1,8830;5,108;-2,63596;1480,58
113,18801;1,8862;5,119;-2,63605;1483,71
113,38801;1,8898;5,126;-2,63594;1485,88
113,58801;1,8930;5,133;-2,63613;1487,82
113,78801;1,8962;5,135;-2,63598;1488,51
113,98801;1,8998;5,141;-2,63611;1490,22
114,18801;1,9030;5,144;-2,63588;1491,04
114,38801;1,9062;5,146;-2,63611;1491,65
114,58801;1,9097;5,147;-2,63586;1491,98
114,78801;1,9130;5,149;-2,63601;1492,34
114,98801;1,9163;5,149;-2,63594;1492,43
115,18801;1,9197;5,149;-2,63584;1492,48
115,38801;1,9231;5,149;-2,63604;1492,54
115,58801;1,9263;5,149;-2,63587;1492,55
115,78801;1,9296;5,149;-2,63611;1492,61
115,98801;1,9331;5,150;-2,63595;1492,67
116,18801;1,9363;5,150;-2,63619;1492,77
116,38801;1,9395;5,151;-2,63597;1493,15
116,58801;1,9432;5,154;-2,63625;1493,97
116,78801;1,9464;5,158;-2,63608;1494,97
116,98801;1,9495;5,161;-2,63620;1495,91
117,18801;1,9531;5,172;-2,63605;1498,99
117,38801;1,9563;5,182;-2,63615;1501,96
117,58801;1,9595;5,194;-2,63613;1505,40
117,78801;1,9630;5,204;-2,63610;1508,40
117,98801;1,9664;5,214;-2,63616;1511,38
118,18801;1,9696;5,225;-2,63611;1514,54
118,38801;1,9729;5,234;-2,63628;1517,14
118,58801;1,9764;5,246;-2,63593;1520,65
118,78801;1,9796;5,252;-2,63616;1522,45
118,98801;1,9828;5,264;-2,63603;1525,80
119,18801;1,9865;5,274;-2,63614;1528,65
119,38801;1,9897;5,284;-2,63619;1531,53
119,58801;1,9929;5,295;-2,63618;1534,82
119,78801;1,9964;5,305;-2,63605;1537,73
119,98801;1,9997;5,315;-2,63620;1540,72
120,18801;2,0029;5,322;-2,63616;1542,53
120,38801;2,0064;5,328;-2,63604;1544,31
120,58801;2,0097;5,337;-2,63624;1546,86
120,78801;2,0129;5,346;-2,63613;1549,49
120,98801;2,0163;5,355;-2,63632;1552,09
121,18801;2,0198;5,366;-2,63616;1555,27
121,38801;2,0230;5,376;-2,63628;1558,28
121,58801;2,0262;5,388;-2,63619;1561,80
121,78801;2,0298;5,405;-2,63627;1566,53
121,98801;2,0330;5,416;-2,63623;1569,99
122,18801;2,0361;5,426;-2,63622;1572,72
122,38801;2,0399;5,437;-2,63632;1575,80
122,58801;2,0430;5,443;-2,63630;1577,68
122,78801;2,0461;5,449;-2,63631;1579,50
122,98801;2,0497;5,452;-2,63625;1580,31
123,18801;2,0529;5,456;-2,63638;1581,40
123,38801;2,0562;5,461;-2,63617;1582,78
123,58801;2,0597;5,465;-2,63635;1584,09
123,78801;2,0630;5,469;-2,63638;1585,17
123,98801;2,0663;5,472;-2,63634;1586,04
124,18801;2,0696;5,477;-2,63622;1587,56
124,38801;2,0731;5,483;-2,63636;1589,22
124,58801;2,0763;5,491;-2,63624;1591,49
124,78801;2,0795;5,496;-2,63644;1593,05
124,98801;2,0831;5,502;-2,63620;1594,70
125,18801;2,0864;5,511;-2,63625;1597,26
125,38801;2,0895;5,514;-2,63644;1598,27
125,58801;2,0932;5,521;-2,63624;1600,37
125,78801;2,0964;5,527;-2,63644;1602,12
125,98801;2,0995;5,532;-2,63629;1603,57
126,18801;2,1030;5,538;-2,63645;1605,13
126,38801;2,1064;5,544;-2,63619;1607,02
126,58801;2,1096;5,552;-2,63627;1609,35
126,78801;2,1130;5,562;-2,63623;1612,21
126,98801;2,1164;5,573;-2,63638;1615,25
127,18801;2,1196;5,581;-2,63647;1617,82
127,38801;2,1228;5,585;-2,63658;1618,84
127,58801;2,1264;5,592;-2,63640;1620,79
127,78801;2,1297;5,595;-2,63635;1621,67
127,98801;2,1328;5,596;-2,63647;1622,06
128,18801;2,1365;5,597;-2,63627;1622,44
128,38801;2,1397;5,599;-2,63650;1623,01
128,58801;2,1429;5,604;-2,63618;1624,47
128,78801;2,1464;5,611;-2,63642;1626,48
128,98801;2,1497;5,620;-2,63617;1628,89
129,18801;2,1529;5,629;-2,63638;1631,57
129,38801;2,1563;5,640;-2,63635;1634,85
129,58801;2,1597;5,649;-2,63640;1637,29
129,78801;2,1630;5,660;-2,63641;1640,65
129,98801;2,1662;5,669;-2,63629;1643,24
130,18801;2,1698;5,675;-2,63642;1645,01
130,38801;2,1730;5,683;-2,63626;1647,12
130,58801;2,1762;5,688;-2,63660;1648,76
130,78801;2,1799;5,695;-2,63627;1650,73
130,98801;2,1830;5,702;-2,63640;1652,62
131,18801;2,1862;5,709;-2,63625;1654,85
131,38801;2,1898;5,718;-2,63632;1657,52
131,58801;2,1930;5,726;-2,63644;1659,63
131,78801;2,1962;5,734;-2,63640;1662,06
131,98801;2,1997;5,744;-2,63657;1665,05
132,18801;2,2030;5,754;-2,63651;1667,91
132,38801;2,2063;5,761;-2,63651;1669,85
132,58801;2,2096;5,769;-2,63632;1672,21
132,78801;2,2131;5,776;-2,63641;1674,22
132,98801;2,2163;5,780;-2,63624;1675,42
133,18801;2,2195;5,783;-2,63646;1676,25
133,38801;2,2231;5,786;-2,63629;1677,02
133,58801;2,2263;5,789;-2,63632;1678,04
133,78801;2,2295;5,793;-2,63619;1679,18
133,98801;2,2331;5,797;-2,63636;1680,42
134,18801;2,2364;5,807;-2,63635;1683,14
134,38801;2,2396;5,814;-2,63636;1685,28
134,58801;2,2431;5,824;-2,63648;1688,05
134,78801;2,2464;5,838;-2,63641;1692,12
134,98801;2,2497;5,849;-2,63658;1695,25
135,18801;2,2530;5,862;-2,63648;1699,26
135,38801;2,2564;5,875;-2,63649;1702,91
135,58801;2,2597;5,889;-2,63649;1706,85
135,78801;2,2629;5,897;-2,63660;1709,34
135,98801;2,2664;5,910;-2,63650;1712,90
136,18801;2,2696;5,918;-2,63672;1715,35
136,38801;2,2728;5,930;-2,63649;1718,76
136,58801;2,2765;5,941;-2,63649;1722,03
136,78801;2,2797;5,951;-2,63654;1725,04
136,98801;2,2828;5,962;-2,63656;1728,00
137,18801;2,2865;5,972;-2,63633;1730,91
137,38801;2,2896;5,983;-2,63648;1734,09
137,58801;2,2929;5,988;-2,63643;1735,69
137,78801;2,2964;5,995;-2,63632;1737,62
137,98801;2,2997;6,000;-2,63653;1739,21
138,18801;2,3029;6,006;-2,63641;1740,81
138,38801;2,3063;6,011;-2,63667;1742,21
138,58801;2,3097;6,018;-2,63637;1744,41
138,78801;2,3130;6,025;-2,63661;1746,46
138,98801;2,3162;6,032;-2,63624;1748,41
139,18801;2,3198;6,041;-2,63643;1750,97
139,38801;2,3230;6,046;-2,63642;1752,57
139,58801;2,3262;6,050;-2,63656;1753,71
139,78801;2,3298;6,051;-2,63655;1753,98
139,98801;2,3331;6,053;-2,63657;1754,62
140,18801;2,3362;6,054;-2,63664;1754,76
140,38801;2,3397;6,054;-2,63659;1754,84
140,58801;2,3430;6,055;-2,63666;1755,10
140,78801;2,3462;6,057;-2,63648;1755,68
140,98801;2,3497;6,059;-2,63674;1756,24
141,18801;2,3531;6,064;-2,63650;1757,59
141,38801;2,3563;6,066;-2,63673;1758,20
141,58801;2,3596;6,074;-2,63656;1760,44
141,78801;2,3630;6,079;-2,63663;1762,17
141,98801;2,3664;6,088;-2,63666;1764,62
142,18801;2,3695;6,092;-2,63662;1765,89
142,38801;2,3731;6,105;-2,63671;1769,50
142,58801;2,3764;6,114;-2,63660;1772,08
142,78801;2,3795;6,120;-2,63678;1774,00
142,98801;2,3831;6,131;-2,63651;1776,97
143,18801;2,3863;6,142;-2,63678;1780,22
143,38801;2,3895;6,154;-2,63658;1783,83
143,58801;2,3931;6,171;-2,63680;1788,63
143,78801;2,3964;6,181;-2,63649;1791,51
143,98801;2,3996;6,196;-2,63668;1795,95
144,18801;2,4029;6,207;-2,63658;1799,01
144,38801;2,4064;6,213;-2,63660;1800,98
144,58801;2,4097;6,222;-2,63683;1803,56
144,78801;2,4129;6,229;-2,63650;1805,36
144,98801;2,4164;6,239;-2,63672;1808,44
145,18801;2,4198;6,250;-2,63648;1811,59
145,38801;2,4229;6,262;-2,63670;1815,14
145,58801;2,4265;6,279;-2,63653;1820,09
145,78801;2,4297;6,298;-2,63662;1825,54
145,98801;2,4328;6,311;-2,63647;1829,33
146,18801;2,4364;6,324;-2,63669;1833,09
146,38801;2,4397;6,334;-2,63671;1835,93
146,58801;2,4429;6,340;-2,63664;1837,77
146,78801;2,4463;6,347;-2,63674;1839,62
146,98801;2,4497;6,355;-2,63655;1841,89
147,18801;2,4530;6,359;-2,63664;1843,07
147,38801;2,4562;6,365;-2,63654;1844,95
147,58801;2,4597;6,373;-2,63672;1847,17
147,78801;2,4630;6,380;-2,63658;1849,18
147,98801;2,4662;6,385;-2,63664;1850,82
148,18801;2,4698;6,395;-2,63659;1853,53
148,38801;2,4730;6,401;-2,63674;1855,40
148,58801;2,4762;6,406;-2,63671;1856,80
148,78801;2,4798;6,412;-2,63654;1858,65
148,98801;2,4830;6,415;-2,63658;1859,43
149,18801;2,4862;6,419;-2,63658;1860,51
149,38801;2,4896;6,422;-2,63655;1861,35
149,58801;2,4931;6,426;-2,63651;1862,51
149,78801;2,4964;6,430;-2,63661;1863,62
149,98801;2,4996;6,434;-2,63656;1864,92
150,18801;2,5032;6,442;-2,63655;1867,33
150,38801;2,5063;6,448;-2,63653;1868,94
150,58801;2,5095;6,452;-2,63652;1870,20
150,78801;2,5132;6,462;-2,63637;1872,98
150,98801;2,5164;6,466;-2,63666;1874,28
151,18801;2,5195;6,469;-2,63651;1875,02
151,38801;2,5231;6,473;-2,63670;1876,34
151,58801;2,5264;6,478;-2,63654;1877,68
151,78801;2,5295;6,481;-2,63660;1878,64
151,98801;2,5330;6,489;-2,63660;1880,88
152,18801;2,5363;6,495;-2,63655;1882,52
152,38801;2,5396;6,504;-2,63681;1885,21
152,58801;2,5429;6,512;-2,63652;1887,60
152,78801;2,5464;6,522;-2,63677;1890,43
152,98801;2,5496;6,531;-2,63663;1893,10
153,18801;2,5529;6,538;-2,63675;1894,98
153,38801;2,5565;6,547;-2,63658;1897,68
153,58801;2,5597;6,554;-2,63664;1899,71
153,78801;2,5628;6,561;-2,63650;1901,67
153,98801;2,5665;6,569;-2,63666;1903,91
154,18801;2,5697;6,578;-2,63661;1906,81
154,38801;2,5729;6,588;-2,63654;1909,58
154,58801;2,5764;6,604;-2,63670;1914,06
154,78801;2,5797;6,621;-2,63650;1919,11
154,98801;2,5829;6,634;-2,63676;1922,99
155,18801;2,5863;6,651;-2,63651;1927,93
155,38801;2,5898;6,664;-2,63690;1931,47
155,58801;2,5930;6,671;-2,63657;1933,61
155,78801;2,5962;6,677;-2,63671;1935,24
155,98801;2,5998;6,683;-2,63661;1937,07
156,18801;2,6030;6,687;-2,63668;1938,17
156,38801;2,6062;6,688;-2,63675;1938,64
156,58801;2,6098;6,693;-2,63675;1939,88
156,78801;2,6130;6,696;-2,63692;1940,85
156,98801;2,6162;6,701;-2,63670;1942,36
157,18801;2,6198;6,707;-2,63696;1944,08
157,38801;2,6230;6,717;-2,63658;1946,86
157,58801;2,6262;6,725;-2,63676;1949,14
157,78801;2,6297;6,734;-2,63650;1951,79
157,98801;2,6331;6,744;-2,63676;1954,82
158,18801;2,6363;6,753;-2,63653;1957,38
158,38801;2,6396;6,762;-2,63671;1960,08
158,58801;2,6431;6,771;-2,63669;1962,63
158,78801;2,6463;6,783;-2,63666;1966,20
158,98801;2,6495;6,791;-2,63681;1968,49
159,18801;2,6531;6,803;-2,63670;1971,79
159,38801;2,6564;6,816;-2,63691;1975,73
159,58801;2,6595;6,824;-2,63676;1977,95
159,78801;2,6632;6,839;-2,63691;1982,21
159,98801;2,6664;6,849;-2,63679;1985,35
160,18801;2,6695;6,858;-2,63690;1987,77
160,38801;2,6730;6,863;-2,63675;1989,33
160,58801;2,6763;6,868;-2,63680;1990,64
160,78801;2,6796;6,871;-2,63672;1991,68
160,98801;2,6830;6,875;-2,63673;1992,71
161,18801;2,6864;6,879;-2,63681;1993,97
161,38801;2,6896;6,889;-2,63666;1996,73
161,58801;2,6929;6,895;-2,63686;1998,62
161,78801;2,6964;6,907;-2,63677;2002,07
161,98801;2,6996;6,916;-2,63674;2004,66
162,18801;2,7029;6,924;-2,63685;2007,05
162,38801;2,7064;6,930;-2,63685;2008,72
162,58801;2,7097;6,936;-2,63676;2010,32
162,78801;2,7129;6,941;-2,63693;2011,90
162,98801;2,7165;6,944;-2,63681;2012,70
163,18801;2,7197;6,950;-2,63686;2014,43
163,38801;2,7229;6,952;-2,63692;2015,14
163,58801;2,7263;6,960;-2,63697;2017,25
163,78801;2,7298;6,965;-2,63668;2018,79
163,98801;2,7330;6,968;-2,63690;2019,82
164,18801;2,7363;6,974;-2,63685;2021,57
164,38801;2,7398;6,980;-2,63686;2023,27
164,58801;2,7430;6,984;-2,63681;2024,27
164,78801;2,7462;6,987;-2,63689;2025,27
164,98801;2,7498;6,993;-2,63709;2027,04
165,18801;2,7530;6,998;-2,63700;2028,35
165,38801;2,7561;7,002;-2,63714;2029,58
165,58801;2,7598;7,007;-2,63679;2031,09
165,78801;2,7630;7,014;-2,63699;2032,91
165,98801;2,7662;7,021;-2,63680;2035,05
166,18801;2,7697;7,030;-2,63688;2037,80
166,38801;2,7730;7,041;-2,63673;2040,91
166,58801;2,7763;7,052;-2,63684;2044,10
166,78801;2,7796;7,061;-2,63703;2046,63
166,98801;2,7831;7,070;-2,63682;2049,35
167,18801;2,7863;7,081;-2,63723;2052,42
167,38801;2,7896;7,088;-2,63697;2054,47
167,58801;2,7931;7,095;-2,63717;2056,55
167,78801;2,7963;7,104;-2,63687;2059,07
167,98801;2,7995;7,113;-2,63712;2061,79
168,18801;2,8032;7,124;-2,63698;2064,94
168,38801;2,8064;7,135;-2,63713;2068,10
168,58801;2,8095;7,146;-2,63707;2071,28
168,78801;2,8131;7,157;-2,63706;2074,46
168,98801;2,8163;7,169;-2,63700;2077,98
169,18801;2,8196;7,179;-2,63687;2080,76
169,38801;2,8230;7,188;-2,63696;2083,61
169,58801;2,8264;7,199;-2,63680;2086,79
169,78801;2,8297;7,206;-2,63700;2088,63
169,98801;2,8329;7,214;-2,63669;2090,95
170,18801;2,8365;7,218;-2,63702;2092,28
170,38801;2,8397;7,227;-2,63689;2094,80
170,58801;2,8428;7,233;-2,63690;2096,59
170,78801;2,8464;7,242;-2,63701;2099,18
170,98801;2,8497;7,250;-2,63692;2101,50
171,18801;2,8529;7,259;-2,63698;2103,94
171,38801;2,8564;7,274;-2,63682;2108,36
171,58801;2,8597;7,284;-2,63702;2111,25
171,78801;2,8629;7,294;-2,63680;2114,19
171,98801;2,8664;7,302;-2,63697;2116,46
172,18801;2,8697;7,309;-2,63689;2118,47
172,38801;2,8730;7,312;-2,63712;2119,50
172,58801;2,8763;7,316;-2,63696;2120,56
172,78801;2,8798;7,318;-2,63711;2121,15
172,98801;2,8830;7,319;-2,63708;2121,50
173,18801;2,8862;7,320;-2,63704;2121,79
173,38801;2,8898;7,322;-2,63714;2122,21
173,58801;2,8930;7,323;-2,63702;2122,58
173,78801;2,8961;7,324;-2,63714;2122,80
173,98801;2,8998;7,325;-2,63695;2123,28
174,18801;2,9030;7,327;-2,63719;2123,85
174,38801;2,9062;7,329;-2,63696;2124,47
174,58801;2,9097;7,333;-2,63709;2125,48
174,78801;2,9130;7,336;-2,63688;2126,41
174,98801;2,9162;7,340;-2,63705;2127,57
175,18801;2,9197;7,344;-2,63688;2128,56
175,38801;2,9231;7,349;-2,63716;2130,22
175,58801;2,9263;7,355;-2,63688;2131,78
175,78801;2,9296;7,360;-2,63694;2133,35
175,98801;2,9331;7,370;-2,63686;2136,22
176,18801;2,9363;7,382;-2,63689;2139,85
176,38801;2,9395;7,391;-2,63688;2142,37
176,58801;2,9431;7,405;-2,63690;2146,51
176,78801;2,9464;7,416;-2,63694;2149,55
176,98801;2,9496;7,424;-2,63690;2151,89
177,18801;2,9532;7,431;-2,63692;2153,98
177,38801;2,9564;7,439;-2,63689;2156,21
177,58801;2,9596;7,444;-2,63703;2157,65
177,78801;2,9630;7,453;-2,63677;2160,35
177,98801;2,9664;7,466;-2,63694;2164,13
178,18801;2,9697;7,479;-2,63688;2167,75
178,38801;2,9730;7,489;-2,63692;2170,65
178,58801;2,9765;7,511;-2,63687;2177,17
178,78801;2,9797;7,527;-2,63700;2181,65
178,98801;2,9829;7,536;-2,63708;2184,21
179,18801;2,9864;7,552;-2,63686;2188,85
179,38801;2,9896;7,560;-2,63701;2191,37
179,58801;2,9928;7,567;-2,63689;2193,42
179,78801;2,9964;7,578;-2,63696;2196,59
179,98801;2,9996;7,586;-2,63668;2198,77
180,18801;3,0029;7,594;-2,63719;2201,13
180,38801;3,0064;7,601;-2,63674;2203,26
180,58801;3,0097;7,608;-2,63696;2205,21
180,78801;3,0129;7,615;-2,63689;2207,28
180,98801;3,0163;7,622;-2,63680;2209,15
181,18801;3,0197;7,627;-2,63699;2210,62
181,38801;3,0230;7,632;-2,63685;2212,24
181,58801;3,0262;7,636;-2,63697;2213,39
181,78801;3,0298;7,641;-2,63683;2214,85
181,98801;3,0330;7,649;-2,63715;2217,13
182,18801;3,0362;7,655;-2,63678;2218,72
182,38801;3,0398;7,662;-2,63702;2220,95
182,58801;3,0431;7,670;-2,63692;2223,17
182,78801;3,0462;7,675;-2,63703;2224,71
182,98801;3,0498;7,684;-2,63698;2227,24
183,18801;3,0530;7,695;-2,63697;2230,58
183,38801;3,0562;7,701;-2,63709;2232,32
183,58801;3,0597;7,710;-2,63705;2234,86
183,78801;3,0630;7,718;-2,63728;2237,21
183,98801;3,0663;7,725;-2,63704;2239,05
184,18801;3,0695;7,729;-2,63733;2240,30
184,38801;3,0731;7,733;-2,63705;2241,42
184,58801;3,0764;7,737;-2,63719;2242,72
184,78801;3,0795;7,741;-2,63705;2243,82
184,98801;3,0831;7,745;-2,63710;2245,05
185,18801;3,0863;7,749;-2,63707;2246,22
185,38801;3,0895;7,754;-2,63708;2247,51
185,58801;3,0931;7,763;-2,63715;2250,18
185,78801;3,0963;7,769;-2,63706;2251,91
185,98801;3,0996;7,774;-2,63710;2253,27
186,18801;3,1030;7,781;-2,63707;2255,43
186,38801;3,1064;7,788;-2,63709;2257,40
186,58801;3,1097;7,797;-2,63694;2260,04
186,78801;3,1129;7,801;-2,63698;2261,18
186,98801;3,1165;7,809;-2,63686;2263,61
187,18801;3,1197;7,817;-2,63700;2265,80
187,38801;3,1229;7,821;-2,63713;2266,95
187,58801;3,1265;7,828;-2,63696;2268,98
187,78801;3,1297;7,833;-2,63705;2270,38
187,98801;3,1328;7,837;-2,63705;2271,71
188,18801;3,1365;7,843;-2,63703;2273,38
188,38801;3,1397;7,851;-2,63715;2275,73
188,58801;3,1428;7,856;-2,63713;2277,08
188,78801;3,1464;7,864;-2,63694;2279,45
188,98801;3,1497;7,875;-2,63706;2282,58
189,18801;3,1529;7,882;-2,63702;2284,66
189,38801;3,1563;7,893;-2,63707;2287,71
189,58801;3,1597;7,897;-2,63698;2289,06
189,78801;3,1630;7,905;-2,63706;2291,43
189,98801;3,1662;7,908;-2,63698;2292,22
190,18801;3,1698;7,915;-2,63698;2294,33
190,38801;3,1730;7,921;-2,63686;2295,87
190,58801;3,1762;7,926;-2,63705;2297,36
190,78801;3,1798;7,931;-2,63693;2298,83
190,98801;3,1830;7,935;-2,63689;2300,08
191,18801;3,1862;7,939;-2,63701;2301,30
191,38801;3,1898;7,945;-2,63687;2302,98
191,58801;3,1931;7,950;-2,63715;2304,26
191,78801;3,1963;7,957;-2,63696;2306,46
191,98801;3,1996;7,964;-2,63721;2308,27
192,18801;3,2031;7,971;-2,63694;2310,47
192,38801;3,2063;7,978;-2,63726;2312,42
192,58801;3,2096;7,983;-2,63701;2314,00
192,78801;3,2132;7,995;-2,63708;2317,31
192,98801;3,2163;8,002;-2,63712;2319,41
193,18801;3,2195;8,008;-2,63721;2321,07
193,38801;3,2232;8,020;-2,63713;2324,63
193,58801;3,2263;8,031;-2,63719;2327,87
193,78801;3,2295;8,039;-2,63719;2330,26
193,98801;3,2331;8,052;-2,63711;2333,88
194,18801;3,2364;8,063;-2,63728;2337,17
194,38801;3,2396;8,073;-2,63700;2339,97
194,58801;3,2431;8,082;-2,63728;2342,51
194,78801;3,2463;8,087;-2,63702;2344,02
194,98801;3,2496;8,092;-2,63723;2345,62
195,18801;3,2530;8,099;-2,63702;2347,46
195,38801;3,2564;8,109;-2,63704;2350,41
195,58801;3,2597;8,115;-2,63719;2352,04
195,78801;3,2629;8,125;-2,63693;2355,07
195,98801;3,2665;8,142;-2,63719;2359,87
196,18801;3,2697;8,150;-2,63690;2362,22
196,38801;3,2728;8,163;-2,63717;2366,06
196,58801;3,2765;8,172;-2,63683;2368,57
196,78801;3,2797;8,180;-2,63724;2370,93
196,98801;3,2829;8,185;-2,63689;2372,60
197,18801;3,2864;8,193;-2,63699;2374,79
197,38801;3,2897;8,174;-2,63695;2369,35
197,58801;3,2929;8,180;-2,63703;2370,95
197,78801;3,2963;8,187;-2,63713;2373,08
197,98801;3,2997;8,194;-2,63714;2375,13
198,18801;3,3030;8,199;-2,63723;2376,63
198,38801;3,3063;8,207;-2,63700;2378,96
198,58801;3,3098;8,211;-2,63731;2379,91
198,78801;3,3130;8,215;-2,63705;2381,13
198,98801;3,3162;8,219;-2,63719;2382,27
199,18801;3,3198;8,221;-2,63710;2382,95
199,38801;3,3230;8,224;-2,63723;2383,73
199,58801;3,3262;8,226;-2,63721;2384,36
199,78801;3,3298;8,227;-2,63720;2384,73
199,98801;3,3330;8,229;-2,63712;2385,23
200,18801;3,3363;8,230;-2,63714;2385,53
200,38801;3,3398;8,208;-2,63723;2379,05
200,58801;3,3430;8,212;-2,63702;2380,40
200,78801;3,3463;8,217;-2,63698;2381,74
200,98801;3,3496;8,221;-2,63705;2382,88
201,18801;3,3531;8,225;-2,63697;2383,98
201,38801;3,3564;8,226;-2,63694;2384,37
201,58801;3,3595;8,228;-2,63709;2384,87
201,78801;3,3631;8,230;-2,63685;2385,47
201,98801;3,3664;8,232;-2,63681;2386,07
202,18801;3,3695;8,234;-2,63721;2386,73
202,38801;3,3732;8,236;-2,63709;2387,24
202,58801;3,3764;8,239;-2,63712;2388,06
202,78801;3,3795;8,243;-2,63713;2389,31
202,98801;3,3831;8,250;-2,63710;2391,40
203,18801;3,3864;8,256;-2,63704;2393,03
203,38801;3,3896;8,263;-2,63712;2395,15
203,58801;3,3930;8,272;-2,63714;2397,75
203,78801;3,3964;8,282;-2,63715;2400,64
203,98801;3,3997;8,289;-2,63707;2402,69
204,18801;3,4029;8,298;-2,63715;2405,10
204,38801;3,4064;8,303;-2,63695;2406,53
204,58801;3,4097;8,309;-2,63721;2408,49
204,78801;3,4129;8,316;-2,63696;2410,35
204,98801;3,4164;8,324;-2,63730;2412,82
205,18801;3,4197;8,334;-2,63700;2415,68
205,38801;3,4228;8,341;-2,63715;2417,58
205,58801;3,4265;8,350;-2,63723;2420,26
205,78801;3,4298;8,360;-2,63719;2423,12
205,98801;3,4329;8,369;-2,63720;2425,85
206,18801;3,4363;8,379;-2,63705;2428,63
206,38801;3,4397;8,387;-2,63725;2431,12
206,58801;3,4429;8,397;-2,63705;2433,94
206,78801;3,4463;8,410;-2,63729;2437,77
206,98801;3,4498;8,427;-2,63713;2442,54
207,18801;3,4531;8,436;-2,63733;2445,19
207,38801;3,4562;8,443;-2,63710;2447,22
207,58801;3,4599;8,452;-2,63727;2449,90
207,78801;3,4629;8,454;-2,63719;2450,39
207,98801;3,4661;8,455;-2,63721;2450,86
208,18801;3,4698;8,465;-2,63720;2453,51
208,38801;3,4730;8,473;-2,63704;2455,93
208,58801;3,4762;8,480;-2,63721;2457,85
208,78801;3,4797;8,485;-2,63705;2459,35
208,98801;3,4830;8,492;-2,63725;2461,47
209,18801;3,4863;8,497;-2,63681;2462,95
209,38801;3,4896;8,211;-2,63704;2379,89
209,58801;3,4931;8,214;-2,63709;2380,86
209,78801;3,4963;8,219;-2,63713;2382,35
209,98801;3,4996;8,223;-2,63706;2383,35
210,18801;3,5031;8,225;-2,63699;2384,10
210,38801;3,5064;8,227;-2,63721;2384,75
210,58801;3,5095;8,228;-2,63685;2384,94
210,78801;3,5132;8,231;-2,63706;2385,75
210,98801;3,5163;8,232;-2,63693;2386,19
211,18801;3,5195;8,234;-2,63709;2386,81
211,38801;3,5231;8,238;-2,63694;2387,84
211,58801;3,5264;8,242;-2,63716;2389,08
211,78801;3,5296;8,249;-2,63704;2390,88
211,98801;3,5330;8,258;-2,63713;2393,65
212,18801;3,5363;8,268;-2,63710;2396,59
212,38801;3,5396;8,267;-2,63713;2396,14
212,58801;3,5430;8,276;-2,63709;2398,97
212,78801;3,5464;8,287;-2,63721;2402,00
212,98801;3,5497;8,276;-2,63715;2398,84
213,18801;3,5528;8,281;-2,63708;2400,27
213,38801;3,5565;8,291;-2,63712;2403,16
213,58801;3,5597;7,939;-2,63672;2301,03
213,78801;3,5629;7,945;-2,63719;2302,76
213,98801;3,5664;7,950;-2,63706;2304,40
214,18801;3,5697;7,957;-2,63717;2306,40
214,38801;3,5729;7,965;-2,63706;2308,83
214,58801;3,5764;7,976;-2,63723;2311,79
214,78801;3,5797;7,985;-2,63704;2314,41
214,98801;3,5830;7,994;-2,63725;2317,01
215,18801;3,5863;8,002;-2,63717;2319,46
215,38801;3,5898;8,012;-2,63729;2322,46
215,58801;3,5930;8,026;-2,63729;2326,25
215,78801;3,5963;8,018;-2,63717;2324,17
215,98801;3,5999;8,033;-2,63718;2328,44
216,18801;3,6031;8,047;-2,63726;2332,60
216,38801;3,6062;8,062;-2,63719;2336,86
216,58801;3,6098;8,071;-2,63724;2339,53
216,78801;3,6130;8,081;-2,63741;2342,28
216,98801;3,6162;8,025;-2,63728;2325,97
217,18801;3,6197;8,036;-2,63739;2329,39
217,38801;3,6230;8,051;-2,63710;2333,68
217,58801;3,6262;7,947;-2,63728;2303,36
217,78801;3,6297;7,955;-2,63747;2305,74
217,98801;3,6330;7,964;-2,63708;2308,55
218,18801;3,6363;7,974;-2,63733;2311,17
218,38801;3,6396;7,980;-2,63722;2313,00
218,58801;3,6431;7,929;-2,63742;2298,27
218,78801;3,6463;7,911;-2,63716;2293,15
218,95801;3,6490;7,916;-2,63682;2294,61