File: Klausurvorbereitung/Übungen/UE5_Specimen_RawData_1.csv
Texteingaben : Proben-beschriftung;"dpp-PUL6-1"
Allgemein : Startdatum;16.08.2018 16:07:51
Abmessung : Querschnitt;3,45000;mm^2

Zeit;Traversenweg;Last;Dehnung 1;Zugspannung
(sec);(mm);(kN);(%);(MPa)
0,00000;0,0000;0,060;0,00037;17,33
0,20000;0,0012;0,064;0,00048;18,52
0,40000;0,0059;0,076;0,00224;22,06
0,60000;0,0100;0,098;0,00469;28,45
0,80000;0,0132;0,121;0,00660;34,99
1,00000;0,0168;0,145;0,00862;41,95
1,20000;0,0200;0,161;0,01048;46,70
1,40000;0,0232;0,174;0,01218;50,48
1,60000;0,0267;0,185;0,01417;53,67
1,80000;0,0300;0,193;0,01617;55,85
2,00000;0,0333;0,200;0,01797;57,88
2,20000;0,0366;0,203;0,01981;58,81
2,40000;0,0401;0,206;0,02186;59,74
2,60000;0,0433;0,209;0,02376;60,46
2,80000;0,0465;0,212;0,02556;61,43
3,00000;0,0501;0,215;0,02755;62,38
3,20000;0,0534;0,217;0,02936;63,03
3,40000;0,0565;0,220;0,03109;63,77
3,60000;0,0602;0,223;0,03318;64,71
3,80000;0,0634;0,228;0,03497;66,13
4,00000;0,0665;0,235;0,03666;68,01
4,20000;0,0701;0,244;0,03860;70,61
4,40000;0,0733;0,257;0,04048;74,42
4,60000;0,0766;0,269;0,04218;78,12
4,80000;0,0800;0,288;0,04402;83,44
5,00000;0,0834;0,303;0,04591;87,88
5,20000;0,0866;0,317;0,04763;91,84
5,40000;0,0899;0,325;0,04939;94,21
5,60000;0,0934;0,334;0,05135;96,83
5,80000;0,0966;0,344;0,05308;99,74
6,00000;0,0998;0,353;0,05484;102,40
6,20000;0,1035;0,365;0,05685;105,68
6,40000;0,1067;0,373;0,05859;108,19
6,60000;0,1099;0,383;0,06028;110,94
6,80000;0,1135;0,396;0,06216;114,64
7,00000;0,1167;0,407;0,06392;117,95
7,20000;0,1199;0,423;0,06571;122,64
7,40000;0,1233;0,437;0,06745;126,74
7,60000;0,1267;0,449;0,06926;130,09
7,80000;0,1300;0,457;0,07107;132,54
8,00000;0,1333;0,466;0,07280;134,96
8,20000;0,1368;0,472;0,07469;136,74
8,40000;0,1400;0,474;0,07628;137,43
8,60000;0,1431;0,478;0,07796;138,60
8,80000;0,1468;0,482;0,07998;139,62
9,00000;0,1500;0,485;0,08170;140,67
9,20000;0,1531;0,489;0,08320;141,68
9,40000;0,1568;0,494;0,08505;143,23
9,60000;0,1601;0,500;0,08684;144,96
9,80000;0,1632;0,509;0,08851;147,40
10,00000;0,1667;0,518;0,09036;150,23
10,20000;0,1700;0,531;0,09207;153,98
10,40000;0,1732;0,540;0,09373;156,38
10,60000;0,1767;0,551;0,09538;159,58
10,80000;0,1800;0,569;0,09722;165,03
11,00000;0,1833;0,583;0,09886;168,99
11,20000;0,1865;0,599;0,10052;173,77
11,40000;0,1901;0,617;0,10236;178,97
11,60000;0,1933;0,632;0,10411;183,05
11,80000;0,1965;0,639;0,10575;185,33
12,00000;0,2001;0,648;0,10767;187,92
12,20000;0,2034;0,656;0,10931;190,19
12,40000;0,2065;0,665;0,11107;192,74
12,60000;0,2102;0,672;0,11289;194,75
12,80000;0,2134;0,681;0,11458;197,44
13,00000;0,2166;0,689;0,11629;199,85
13,20000;0,2200;0,699;0,11800;202,47
13,40000;0,2234;0,710;0,11978;205,74
13,60000;0,2266;0,724;0,12148;209,72
13,80000;0,2300;0,736;0,12313;213,35
14,00000;0,2335;0,758;0,12513;219,57
14,20000;0,2366;0,772;0,12686;223,89
14,40000;0,2398;0,780;0,12841;226,16
14,60000;0,2434;0,787;0,13033;228,02
14,80000;0,2467;0,791;0,13191;229,17
15,00000;0,2498;0,793;0,13365;229,78
15,20000;0,2535;0,796;0,13554;230,79
15,40000;0,2567;0,798;0,13721;231,39
15,60000;0,2599;0,802;0,13877;232,47
15,80000;0,2634;0,807;0,14068;234,00
16,00000;0,2667;0,813;0,14244;235,77
16,20000;0,2699;0,817;0,14407;236,87
16,40000;0,2733;0,823;0,14585;238,67
16,60000;0,2768;0,829;0,14769;240,22
16,80000;0,2800;0,833;0,14939;241,45
17,00000;0,2833;0,837;0,15102;242,69
17,20000;0,2867;0,845;0,15299;244,86
17,40000;0,2901;0,855;0,15473;247,87
17,60000;0,2932;0,868;0,15635;251,67
17,80000;0,2968;0,886;0,15821;256,76
18,00000;0,3001;0,897;0,15990;260,02
18,20000;0,3032;0,907;0,16150;262,84
18,40000;0,3068;0,919;0,16337;266,43
18,60000;0,3100;0,929;0,16502;269,22
18,80000;0,3131;0,941;0,16670;272,77
19,00000;0,3167;0,955;0,16858;276,93
19,20000;0,3201;0,971;0,17026;281,46
19,40000;0,3232;0,984;0,17191;285,22
19,60000;0,3267;0,998;0,17359;289,33
19,80000;0,3300;1,014;0,17547;294,06
20,00000;0,3333;1,027;0,17712;297,55
20,20000;0,3365;1,043;0,17870;302,38
20,40000;0,3401;1,062;0,18063;307,92
20,60000;0,3433;1,077;0,18232;312,09
20,80000;0,3466;1,090;0,18393;316,00
21,00000;0,3501;1,104;0,18570;320,07
21,20000;0,3534;1,111;0,18734;321,91
21,40000;0,3565;1,116;0,18891;323,41
21,60000;0,3601;1,118;0,19084;324,19
21,80000;0,3634;1,122;0,19256;325,26
22,00000;0,3666;1,125;0,19429;326,04
22,20000;0,3700;1,127;0,19593;326,74
22,40000;0,3734;1,131;0,19784;327,94
22,60000;0,3767;1,134;0,19949;328,64
22,80000;0,3799;1,139;0,20111;330,23
23,00000;0,3834;1,145;0,20308;332,00
23,20000;0,3867;1,152;0,20467;333,86
23,40000;0,3898;1,158;0,20634;335,65
23,60000;0,3935;1,165;0,20825;337,61
23,80000;0,3967;1,174;0,21000;340,28
24,00000;0,3998;1,182;0,21160;342,70
24,20000;0,4034;1,195;0,21343;346,41
24,40000;0,4066;1,209;0,21507;350,31
24,60000;0,4099;1,222;0,21674;354,22
24,80000;0,4134;1,231;0,21846;356,90
25,00000;0,4167;1,244;0,22030;360,60
25,20000;0,4200;1,252;0,22195;363,02
25,40000;0,4233;1,263;0,22355;366,03
25,60000;0,4267;1,274;0,22534;369,25
25,80000;0,4300;1,281;0,22701;371,28
26,00000;0,4332;1,290;0,22864;374,02
26,20000;0,4368;1,301;0,23064;377,14
26,40000;0,4401;1,309;0,23219;379,56
26,60000;0,4432;1,319;0,23378;382,19
26,80000;0,4469;1,337;0,23572;387,52
27,00000;0,4501;1,348;0,23723;390,83
27,20000;0,4531;1,362;0,23886;394,71
27,40000;0,4567;1,371;0,24073;397,47
27,60000;0,4600;1,380;0,24238;400,04
27,80000;0,4632;1,386;0,24406;401,87
28,00000;0,4667;1,394;0,24578;404,16
28,20000;0,4700;1,403;0,24748;406,62
28,40000;0,4733;1,410;0,24911;408,61
28,60000;0,4766;1,418;0,25072;411,12
28,80000;0,4801;1,431;0,25254;414,91
29,00000;0,4833;1,439;0,25429;416,98
29,20000;0,4865;1,448;0,25585;419,66
29,40000;0,4902;1,459;0,25779;422,88
29,60000;0,4934;1,465;0,25948;424,67
29,80000;0,4966;1,473;0,26107;427,07
30,00000;0,5001;1,481;0,26274;429,23
30,20000;0,5034;1,487;0,26441;431,12
30,40000;0,5065;1,496;0,26606;433,65
30,60000;0,5102;1,509;0,26773;437,38
30,80000;0,5134;1,523;0,26945;441,48
31,00000;0,5166;1,536;0,27105;445,28
31,20000;0,5200;1,548;0,27276;448,75
31,40000;0,5234;1,557;0,27461;451,35
31,60000;0,5266;1,565;0,27618;453,62
31,80000;0,5299;1,578;0,27785;457,39
32,00000;0,5334;1,590;0,27961;460,75
32,20000;0,5368;1,603;0,28126;464,60
32,40000;0,5398;1,612;0,28280;467,18
32,60000;0,5435;1,622;0,28462;470,24
32,80000;0,5466;1,631;0,28621;472,65
33,00000;0,5498;1,637;0,28785;474,45
33,20000;0,5535;1,646;0,28976;477,04
33,40000;0,5566;1,659;0,29141;480,78
33,60000;0,5599;1,670;0,29296;484,16
33,80000;0,5634;1,680;0,29468;487,04
34,00000;0,5667;1,690;0,29640;489,78
34,20000;0,5699;1,699;0,29800;492,42
34,40000;0,5732;1,704;0,29956;494,01
34,60000;0,5767;1,711;0,30133;496,01
34,80000;0,5800;1,717;0,30307;497,67
35,00000;0,5832;1,722;0,30474;499,21
35,20000;0,5868;1,728;0,30654;500,82
35,40000;0,5900;1,731;0,30815;501,86
35,60000;0,5932;1,735;0,30967;502,80
35,80000;0,5968;1,737;0,31147;503,42
36,00000;0,6000;1,740;0,31309;504,30
36,20000;0,6031;1,743;0,31454;505,14
36,40000;0,6068;1,748;0,31630;506,79
36,60000;0,6100;1,755;0,31789;508,84
36,80000;0,6132;1,764;0,31944;511,19
37,00000;0,6167;1,777;0,32110;515,20
37,20000;0,6200;1,792;0,32275;519,56
37,40000;0,6232;1,811;0,32445;524,98
37,60000;0,6266;1,832;0,32609;530,88
37,80000;0,6300;1,845;0,32793;534,71
38,00000;0,6334;1,861;0,32947;539,29
38,20000;0,6365;1,872;0,33111;542,47
38,40000;0,6401;1,885;0,33293;546,33
38,60000;0,6433;1,897;0,33457;549,84
38,80000;0,6465;1,907;0,33616;552,76
39,00000;0,6501;1,919;0,33800;556,22
39,20000;0,6533;1,934;0,33964;560,58
39,40000;0,6566;1,946;0,34124;563,98
39,60000;0,6600;1,961;0,34301;568,50
39,80000;0,6634;1,974;0,34456;572,23
40,00000;0,6666;1,990;0,34619;576,78
40,20000;0,6699;2,004;0,34786;580,73
40,40000;0,6734;2,015;0,34970;583,95
40,60000;0,6767;2,022;0,35132;585,97
40,80000;0,6799;2,028;0,35290;587,80
41,00000;0,6835;2,035;0,35473;589,80
41,20000;0,6867;2,041;0,35637;591,71
41,40000;0,6898;2,046;0,35787;593,03
41,60000;0,6934;2,051;0,35974;594,55
41,80000;0,6966;2,055;0,36123;595,75
42,00000;0,6999;2,058;0,36281;596,52
42,20000;0,7034;2,061;0,36458;597,41
42,40000;0,7067;2,063;0,36618;597,91
42,60000;0,7099;2,064;0,36777;598,19
42,80000;0,7133;2,065;0,36941;598,51
43,00000;0,7167;2,067;0,37121;599,04
43,20000;0,7199;2,071;0,37288;600,31
43,40000;0,7232;2,078;0,37442;602,27
43,60000;0,7268;2,087;0,37622;604,98
43,80000;0,7300;2,103;0,37784;609,47
44,00000;0,7332;2,115;0,37939;613,17
44,20000;0,7368;2,131;0,38113;617,77
44,40000;0,7400;2,142;0,38261;620,85
44,60000;0,7431;2,155;0,38409;624,57
44,80000;0,7468;2,163;0,38580;627,08
45,00000;0,7500;2,173;0,38734;629,93
45,20000;0,7533;2,183;0,38886;632,65
45,40000;0,7567;2,197;0,39040;636,71
45,60000;0,7600;2,206;0,39194;639,42
45,80000;0,7633;2,218;0,39354;642,94
46,00000;0,7666;2,225;0,39510;644,82
46,20000;0,7701;2,235;0,39688;647,74
46,40000;0,7734;2,248;0,39842;651,71
46,60000;0,7765;2,263;0,39998;656,05
46,80000;0,7802;2,283;0,40177;661,68
47,00000;0,7834;2,302;0,40317;667,32
47,20000;0,7865;2,313;0,40473;670,38
47,40000;0,7901;2,327;0,40650;674,48
47,60000;0,7933;2,338;0,40808;677,62
47,80000;0,7965;2,349;0,40967;680,79
48,00000;0,8001;2,355;0,41132;682,62
48,20000;0,8033;2,365;0,41297;685,52
48,40000;0,8066;2,370;0,41454;687,04
48,60000;0,8099;2,377;0,41622;688,85
48,80000;0,8134;2,382;0,41790;690,42
49,00000;0,8166;2,386;0,41946;691,62
49,20000;0,8199;2,391;0,42105;692,90
49,40000;0,8235;2,395;0,42281;694,31
49,60000;0,8267;2,401;0,42436;696,06
49,80000;0,8298;2,409;0,42588;698,28
50,00000;0,8335;2,418;0,42767;700,88
50,20000;0,8367;2,431;0,42926;704,72
50,40000;0,8398;2,445;0,43080;708,80
50,60000;0,8435;2,461;0,43247;713,41
50,80000;0,8467;2,477;0,43408;717,86
51,00000;0,8498;2,489;0,43564;721,53
51,20000;0,8534;2,502;0,43736;725,21
51,40000;0,8567;2,512;0,43900;728,10
51,60000;0,8599;2,518;0,44064;729,85
51,80000;0,8633;2,521;0,44208;730,69
52,00000;0,8667;2,526;0,44377;732,06
52,20000;0,8701;2,529;0,44535;732,99
52,40000;0,8732;2,537;0,44674;735,25
52,60000;0,8768;2,542;0,44844;736,78
52,80000;0,8800;2,552;0,44994;739,79
53,00000;0,8832;2,566;0,45135;743,81
53,20000;0,8868;2,582;0,45308;748,47
53,40000;0,8900;2,596;0,45471;752,49
53,60000;0,8932;2,610;0,45629;756,54
53,80000;0,8968;2,619;0,45788;758,99
54,00000;0,9001;2,628;0,45947;761,81
54,20000;0,9032;2,633;0,46102;763,11
54,40000;0,9066;2,638;0,46255;764,68
54,60000;0,9100;2,642;0,46426;765,93
54,80000;0,9133;2,646;0,46593;766,97
55,00000;0,9166;2,650;0,46744;768,06
55,20000;0,9201;2,657;0,46924;770,06
55,40000;0,9234;2,662;0,47072;771,62
55,60000;0,9265;2,671;0,47223;774,22
55,80000;0,9301;2,678;0,47391;776,34
56,00000;0,9334;2,688;0,47557;779,02
56,20000;0,9365;2,694;0,47709;780,89
56,40000;0,9401;2,706;0,47878;784,32
56,60000;0,9433;2,713;0,48032;786,41
56,80000;0,9466;2,727;0,48181;790,52
57,00000;0,9500;2,742;0,48342;794,77
57,20000;0,9533;2,758;0,48507;799,28
57,40000;0,9566;2,771;0,48661;803,25
57,60000;0,9599;2,786;0,48814;807,60
57,80000;0,9634;2,799;0,48989;811,25
58,00000;0,9667;2,813;0,49130;815,27
58,20000;0,9699;2,825;0,49273;818,81
58,40000;0,9735;2,841;0,49445;823,62
58,60000;0,9767;2,852;0,49596;826,72
58,80000;0,9798;2,862;0,49761;829,63
59,00000;0,9835;2,873;0,49925;832,69
59,20000;0,9867;2,879;0,50076;834,61
59,40000;0,9899;2,888;0,50237;837,12
59,60000;0,9933;2,902;0,50393;841,03
59,80000;0,9967;2,915;0,50556;844,89
59,96800;0,9995;2,926;0,50686;848,15
60,16800;1,0027;2,940;0,50840;852,29
60,36800;1,0063;2,955;0,51024;856,45
60,56800;1,0095;2,963;0,51176;858,84
60,76800;1,0126;2,968;0,51325;860,26
60,96800;1,0163;2,971;0,51504;861,21
61,16800;1,0195;2,972;0,51653;861,47
61,36800;1,0226;2,973;0,51810;861,73
61,56800;1,0262;2,974;0,51985;861,89
61,76800;1,0295;2,974;0,52136;862,05
61,96800;1,0327;2,975;0,52296;862,22
62,16800;1,0362;2,976;0,52456;862,67
62,36800;1,0395;2,978;0,52614;863,06
62,56800;1,0428;2,981;0,52774;864,05
62,76800;1,0461;2,984;0,52921;864,93
62,96800;1,0495;2,990;0,53089;866,61
63,16800;1,0528;2,997;0,53233;868,77
63,36800;1,0559;3,006;0,53379;871,19
63,56800;1,0596;3,020;0,53547;875,45
63,76800;1,0628;3,033;0,53696;879,21
63,96800;1,0660;3,048;0,53841;883,57
64,16800;1,0696;3,068;0,54015;889,14
64,36800;1,0728;3,079;0,54167;892,58
64,56800;1,0760;3,096;0,54310;897,35
64,76800;1,0796;3,106;0,54474;900,16
64,96800;1,0829;3,115;0,54618;902,99
65,16800;1,0861;3,124;0,54774;905,53
65,36800;1,0894;3,133;0,54933;908,25
65,56800;1,0929;3,144;0,55105;911,23
65,76800;1,0960;3,159;0,55246;915,59
65,96800;1,0993;3,174;0,55398;919,96
66,16800;1,1029;3,194;0,55566;925,88
66,36800;1,1061;3,214;0,55728;931,68
66,56800;1,1093;3,231;0,55866;936,52
66,76800;1,1129;3,246;0,56040;940,95
66,96800;1,1162;3,257;0,56191;943,93
67,16800;1,1193;3,268;0,56345;947,22
67,36800;1,1229;3,274;0,56514;948,97
67,56800;1,1261;3,284;0,56672;951,88
67,76800;1,1293;3,289;0,56820;953,41
67,96800;1,1329;3,297;0,56977;955,75
68,16800;1,1362;3,302;0,57140;957,00
68,36800;1,1394;3,310;0,57285;959,34
68,56800;1,1427;3,317;0,57422;961,55
68,76800;1,1462;3,322;0,57584;962,96
68,96800;1,1494;3,329;0,57737;964,95
69,16800;1,1527;3,332;0,57880;965,87
69,36800;1,1563;3,337;0,58046;967,28
69,56800;1,1595;3,342;0,58190;968,67
69,76800;1,1627;3,347;0,58332;970,25
69,96800;1,1663;3,355;0,58511;972,43
70,16800;1,1695;3,365;0,58655;975,46
70,36800;1,1726;3,375;0,58795;978,29
70,56800;1,1762;3,383;0,58962;980,52
70,76800;1,1795;3,391;0,59119;982,84
70,96800;1,1827;3,396;0,59269;984,39
71,16800;1,1861;3,401;0,59416;985,71
71,36800;1,1896;3,407;0,59581;987,60
71,56800;1,1927;3,413;0,59729;989,29
71,76800;1,1960;3,423;0,59877;992,10
71,96800;1,1995;3,434;0,60039;995,35
72,16800;1,2028;3,441;0,60185;997,50
72,36800;1,2060;3,451;0,60333;1000,42
72,56800;1,2096;3,461;0,60503;1003,27
72,76800;1,2128;3,470;0,60654;1005,88
72,96800;1,2160;3,484;0,60794;1009,93
73,16800;1,2196;3,498;0,60957;1014,04
73,36800;1,2228;3,511;0,61114;1017,63
73,56800;1,2261;3,527;0,61259;1022,42
73,76800;1,2295;3,540;0,61421;1026,06
73,96800;1,2329;3,552;0,61576;1029,52
74,16800;1,2361;3,561;0,61716;1032,25
74,36800;1,2394;3,567;0,61871;1034,02
74,56800;1,2429;3,579;0,62029;1037,32
74,76800;1,2461;3,584;0,62171;1038,88
74,96800;1,2493;3,590;0,62322;1040,62
75,16800;1,2530;3,597;0,62490;1042,53
75,36800;1,2562;3,602;0,62634;1043,94
75,56800;1,2593;3,608;0,62779;1045,73
75,76800;1,2630;3,612;0,62940;1047,10
75,96800;1,2661;3,617;0,63090;1048,30
76,16800;1,2693;3,626;0,63230;1051,07
76,36800;1,2728;3,635;0,63391;1053,68
76,56800;1,2761;3,644;0,63542;1056,09
76,76800;1,2794;3,655;0,63687;1059,44
76,96800;1,2827;3,668;0,63837;1063,31
77,16800;1,2861;3,686;0,64009;1068,35
77,36800;1,2895;3,701;0,64163;1072,87
77,56800;1,2926;3,719;0,64292;1078,02
77,76800;1,2963;3,736;0,64465;1083,03
77,96800;1,2995;3,749;0,64610;1086,81
78,16800;1,3027;3,760;0,64756;1089,78
78,36800;1,3063;3,768;0,64917;1092,31
78,56800;1,3095;3,778;0,65068;1095,00
78,76800;1,3126;3,785;0,65208;1097,19
78,96800;1,3162;3,794;0,65367;1099,66
79,16800;1,3195;3,804;0,65526;1102,74
79,36800;1,3228;3,815;0,65672;1105,72
79,56800;1,3261;3,828;0,65810;1109,43
79,76800;1,3296;3,841;0,65975;1113,36
79,96800;1,3328;3,852;0,66116;1116,56
80,16800;1,3360;3,859;0,66257;1118,52
80,36800;1,3396;3,865;0,66416;1120,23
80,56800;1,3428;3,868;0,66567;1121,19
80,76800;1,3459;3,871;0,66707;1122,16
80,96800;1,3496;3,873;0,66886;1122,59
81,16800;1,3528;3,874;0,67026;1122,96
81,36800;1,3560;3,875;0,67163;1123,33
81,56800;1,3595;3,876;0,67331;1123,56
81,76800;1,3628;3,878;0,67480;1124,10
81,96800;1,3660;3,880;0,67626;1124,78
82,16800;1,3695;3,883;0,67775;1125,59
82,36800;1,3728;3,888;0,67924;1127,01
82,56800;1,3761;3,893;0,68062;1128,54
82,76800;1,3794;3,900;0,68196;1130,57
82,96800;1,3829;3,910;0,68360;1133,32
83,16800;1,3861;3,918;0,68508;1135,78
83,36800;1,3894;3,932;0,68664;1139,82
83,56800;1,3929;3,952;0,68828;1145,59
83,76800;1,3962;3,970;0,68967;1150,63
83,96800;1,3993;3,981;0,69101;1153,98
84,16800;1,4030;3,997;0,69266;1158,43
84,36800;1,4062;4,011;0,69414;1162,66
84,56800;1,4093;4,020;0,69553;1165,10
84,76800;1,4128;4,034;0,69705;1169,35
84,96800;1,4162;4,043;0,69861;1172,01
85,16800;1,4194;4,053;0,70010;1174,85
85,36800;1,4228;4,069;0,70151;1179,37
85,56800;1,4262;4,080;0,70307;1182,68
85,76800;1,4294;4,092;0,70449;1186,07
85,96800;1,4326;4,104;0,70596;1189,67
86,16800;1,4363;4,115;0,70774;1192,66
86,36800;1,4394;4,128;0,70915;1196,48
86,56800;1,4426;4,143;0,71062;1200,78
86,76800;1,4463;4,159;0,71235;1205,63
86,96800;1,4495;4,175;0,71378;1210,22
87,16800;1,4527;4,191;0,71515;1214,86
87,36800;1,4562;4,205;0,71681;1218,70
87,56800;1,4595;4,220;0,71833;1223,11
87,76800;1,4627;4,227;0,71983;1225,29
87,96800;1,4662;4,233;0,72138;1226,93
88,16800;1,4695;4,237;0,72289;1228,25
88,36800;1,4728;4,241;0,72435;1229,20
88,56800;1,4761;4,243;0,72588;1229,72
88,76800;1,4796;4,244;0,72758;1230,10
88,96800;1,4828;4,245;0,72903;1230,51
89,16800;1,4860;4,246;0,73051;1230,66
89,36800;1,4896;4,247;0,73218;1231,01
89,56800;1,4928;4,248;0,73359;1231,40
89,76800;1,4960;4,249;0,73511;1231,73
89,96800;1,4996;4,251;0,73677;1232,22
90,16800;1,5028;4,255;0,73812;1233,45
90,36800;1,5060;4,260;0,73964;1234,83
90,56800;1,5095;4,266;0,74122;1236,42
90,76800;1,5128;4,274;0,74277;1238,88
90,96800;1,5161;4,285;0,74434;1241,94
91,16800;1,5194;4,297;0,74578;1245,46
91,36800;1,5229;4,313;0,74745;1250,07
91,56800;1,5261;4,325;0,74880;1253,57
91,76800;1,5293;4,335;0,75033;1256,41
91,96800;1,5329;4,344;0,75200;1259,08
92,16800;1,5361;4,350;0,75347;1260,76
92,36800;1,5394;4,361;0,75495;1264,14
92,56800;1,5429;4,370;0,75650;1266,81
92,76800;1,5462;4,387;0,75811;1271,60
92,96800;1,5493;4,402;0,75950;1275,86
93,16800;1,5530;4,424;0,76127;1282,19
93,36800;1,5561;4,439;0,76273;1286,76
93,56800;1,5594;4,450;0,76424;1289,73
93,76800;1,5628;4,463;0,76583;1293,72
93,96800;1,5662;4,474;0,76733;1296,92
94,16800;1,5695;4,482;0,76889;1299,18
94,36800;1,5727;4,492;0,77030;1302,12
94,56800;1,5762;4,500;0,77202;1304,49
94,76800;1,5795;4,509;0,77349;1306,83
94,96800;1,5826;4,515;0,77495;1308,71
95,16800;1,5863;4,523;0,77661;1311,11
95,36800;1,5895;4,530;0,77810;1312,91
95,56800;1,5926;4,536;0,77957;1314,78
95,76800;1,5963;4,541;0,78125;1316,13
95,96800;1,5995;4,546;0,78272;1317,72
96,16800;1,6027;4,551;0,78418;1319,22
96,36800;1,6061;4,557;0,78574;1320,87
96,56800;1,6095;4,567;0,78736;1323,82
96,76800;1,6127;4,577;0,78880;1326,66
96,96800;1,6160;4,588;0,79029;1329,98
97,16800;1,6195;4,601;0,79196;1333,76
97,36800;1,6228;4,621;0,79341;1339,37
97,56800;1,6260;4,635;0,79487;1343,42
97,76800;1,6296;4,644;0,79664;1346,05
97,96800;1,6329;4,657;0,79808;1349,78
98,16800;1,6359;4,665;0,79948;1352,05
98,36800;1,6396;4,671;0,80126;1353,96
98,56800;1,6429;4,680;0,80269;1356,43
98,76800;1,6459;4,686;0,80413;1358,23
98,96800;1,6496;4,695;0,80569;1360,92
99,16800;1,6528;4,707;0,80723;1364,48
99,36800;1,6560;4,711;0,80877;1365,62
99,56800;1,6595;4,718;0,81029;1367,57
99,76800;1,6628;4,722;0,81188;1368,66
99,96800;1,6662;4,725;0,81338;1369,65
100,16800;1,6693;4,729;0,81480;1370,64
100,36800;1,6729;4,739;0,81648;1373,49
100,56800;1,6761;4,745;0,81792;1375,44
100,76800;1,6793;4,755;0,81934;1378,27
100,96800;1,6830;4,765;0,82107;1381,18
101,16800;1,6861;4,772;0,82250;1383,11
101,36800;1,6893;4,778;0,82400;1385,00
101,56800;1,6929;4,783;0,82561;1386,46
101,76800;1,6962;4,786;0,82708;1387,33
101,96800;1,6994;4,791;0,82856;1388,78
102,16800;1,7028;4,796;0,83012;1390,18
102,36800;1,7062;4,803;0,83170;1392,24
102,56800;1,7094;4,810;0,83314;1394,12
102,76800;1,7127;4,816;0,83462;1395,95
102,96800;1,7162;4,826;0,83630;1398,85
103,16800;1,7194;4,837;0,83775;1402,13
103,36800;1,7227;4,849;0,83922;1405,63
103,56800;1,7263;4,860;0,84094;1408,84
103,76800;1,7295;4,872;0,84234;1412,10
103,96800;1,7326;4,881;0,84387;1414,67
104,16800;1,7363;4,892;0,84554;1418,00
104,36800;1,7395;4,901;0,84702;1420,49
104,56800;1,7426;4,911;0,84844;1423,35
104,76800;1,7462;4,924;0,85007;1427,38
104,96800;1,7494;4,936;0,85160;1430,73
105,16800;1,7527;4,956;0,85306;1436,54
105,36801;1,7562;4,968;0,85455;1440,03
105,56801;1,7595;4,982;0,85615;1443,94
105,76801;1,7628;4,995;0,85763;1447,82
105,96801;1,7660;5,006;0,85905;1451,01
106,16801;1,7695;5,022;0,86075;1455,77
106,36801;1,7728;5,031;0,86210;1458,39
106,56801;1,7760;5,049;0,86357;1463,41
106,76801;1,7796;5,068;0,86530;1469,00
106,96801;1,7828;5,086;0,86668;1474,29
107,16801;1,7860;5,099;0,86808;1478,06
107,36801;1,7896;5,114;0,86972;1482,31
107,56801;1,7928;5,122;0,87121;1484,70
107,76801;1,7960;5,129;0,87274;1486,72
107,96801;1,7995;5,136;0,87421;1488,65
108,16801;1,8029;5,140;0,87583;1489,98
108,36801;1,8061;5,144;0,87728;1491,08
108,56801;1,8094;5,146;0,87876;1491,68
108,76801;1,8129;5,148;0,88031;1492,07
108,96801;1,8161;5,148;0,88173;1492,29
109,16801;1,8193;5,149;0,88315;1492,40
109,36801;1,8229;5,149;0,88488;1492,46
109,56801;1,8261;5,149;0,88629;1492,50
109,76801;1,8293;5,149;0,88771;1492,51
109,96801;1,8329;5,150;0,88932;1492,62
110,16801;1,8362;5,150;0,89073;1492,75
110,36801;1,8393;5,152;0,89216;1493,42
110,56801;1,8429;5,157;0,89378;1494,86
110,76801;1,8462;5,160;0,89524;1495,77
110,96801;1,8494;5,173;0,89676;1499,34
111,16801;1,8527;5,183;0,89818;1502,43
111,36801;1,8562;5,198;0,89981;1506,63
111,56801;1,8595;5,210;0,90121;1510,01
111,76801;1,8626;5,225;0,90257;1514,51
111,96801;1,8663;5,237;0,90418;1517,98
112,16801;1,8695;5,247;0,89366;1520,83
112,36801;1,8727;5,257;0,88095;1523,64
112,56801;1,8763;5,268;0,38646;1526,96
112,76801;1,8795;5,282;-2,89461;1530,97
112,96801;1,8826;5,293;-4,42434;1534,19
113,16801;1,8862;5,306;-3,15933;1537,83
113,36801;1,8894;5,316;-3,92712;1540,83
113,56801;1,8926;5,325;-3,51981;1543,62
113,76801;1,8961;5,335;-3,31929;1546,46
113,96801;1,8995;5,344;-2,61751;1549,08
114,16801;1,9028;5,353;-2,77014;1551,56
114,36801;1,9060;5,367;-3,40973;1555,74
114,56801;1,9095;5,384;-3,40084;1560,50
114,76801;1,9128;5,397;-2,82303;1564,41
114,96801;1,9160;5,415;-3,39199;1569,69
115,16801;1,9196;5,430;-3,85135;1573,84
115,36801;1,9228;5,437;-3,32528;1575,87
115,56801;1,9260;5,444;-2,97262;1577,95
115,76801;1,9296;5,450;-3,95146;1579,83
115,96801;1,9328;5,455;-3,77745;1581,30
116,16801;1,9360;5,459;-3,19845;1582,45
116,36801;1,9395;5,465;-3,62223;1584,02
116,56801;1,9429;5,469;-3,31590;1585,30
116,76801;1,9461;5,474;-3,52457;1586,68
116,96801;1,9494;5,482;-3,39138;1588,97
117,16801;1,9529;5,489;-3,47492;1591,05
117,36801;1,9562;5,495;-3,42306;1592,82
117,56801;1,9593;5,503;-3,45596;1594,98
117,76801;1,9629;5,512;-3,43462;1597,72
117,96801;1,9661;5,521;-3,44908;1600,17
118,16801;1,9693;5,526;-3,43967;1601,83
118,36801;1,9729;5,533;-3,44593;1603,84
118,56801;1,9762;5,539;-3,44183;1605,54
118,76801;1,9793;5,547;-3,44489;1607,75
118,96801;1,9828;5,556;-3,44285;1610,30
119,16801;1,9861;5,569;-3,44414;1614,19
119,36801;1,9894;5,580;-3,44388;1617,27
119,56801;1,9928;5,588;-3,44368;1619,85
119,76801;1,9962;5,593;-3,44406;1621,09
119,96801;1,9994;5,595;-3,44385;1621,79
120,16801;2,0026;5,597;-3,44387;1622,20
120,36801;2,0062;5,600;-3,44388;1623,27
120,56801;2,0094;5,603;-3,44413;1624,16
120,76801;2,0126;5,612;-3,44407;1626,71
120,96801;2,0163;5,627;-3,44393;1631,08
121,16801;2,0195;5,638;-3,44428;1634,07
121,36801;2,0227;5,651;-3,44410;1638,10
121,56801;2,0263;5,662;-3,44421;1641,15
121,76801;2,0295;5,671;-3,44440;1643,72
121,96801;2,0327;5,679;-3,44439;1646,12
122,16801;2,0361;5,686;-3,44431;1648,26
122,36801;2,0395;5,697;-3,44458;1651,18
122,56801;2,0428;5,699;-3,44429;1651,98
122,76801;2,0461;5,712;-3,44453;1655,53
122,96801;2,0496;5,723;-3,44452;1658,72
123,16801;2,0528;5,733;-3,44439;1661,73
123,36801;2,0559;5,742;-3,44461;1664,47
123,56801;2,0596;5,755;-3,44449;1668,17
123,76801;2,0628;5,764;-3,44456;1670,84
123,96801;2,0660;5,774;-3,44461;1673,49
124,16801;2,0696;5,780;-3,44471;1675,35
124,36801;2,0728;5,782;-3,44500;1676,05
124,56801;2,0760;5,786;-3,44441;1677,18
124,76801;2,0795;5,791;-3,44494;1678,48
124,96801;2,0828;5,797;-3,44486;1680,42
125,16801;2,0861;5,808;-3,44474;1683,41
125,36801;2,0894;5,816;-3,44505;1685,82
125,56801;2,0929;5,829;-3,44471;1689,54
125,76801;2,0961;5,846;-3,44519;1694,38
125,96801;2,0994;5,859;-3,44485;1698,15
126,16801;2,1029;5,876;-3,44512;1703,13
126,36801;2,1062;5,889;-3,44486;1706,84
126,56801;2,1093;5,902;-3,44548;1710,64
126,76801;2,1129;5,914;-3,44481;1714,17
126,96801;2,1162;5,925;-3,44532;1717,50
127,16801;2,1194;5,936;-3,44488;1720,45
127,36801;2,1228;5,949;-3,44530;1724,21
127,56801;2,1261;5,962;-3,44516;1728,01
127,76801;2,1293;5,970;-3,44519;1730,46
127,96801;2,1328;5,981;-3,44552;1733,57
128,16801;2,1362;5,988;-3,44501;1735,66
128,36801;2,1395;5,995;-3,44561;1737,62
128,56801;2,1427;6,000;-3,44514;1739,06
128,76801;2,1462;6,005;-3,44555;1740,68
128,96801;2,1494;6,011;-3,44518;1742,33
129,16801;2,1526;6,018;-3,44551;1744,40
129,36801;2,1562;6,025;-3,44538;1746,48
129,56801;2,1595;6,034;-3,44542;1748,94
129,76801;2,1627;6,040;-3,44565;1750,60
129,96801;2,1662;6,046;-3,44532;1752,34
130,16801;2,1695;6,050;-3,44563;1753,54
130,36801;2,1727;6,052;-3,44525;1754,18
130,56801;2,1762;6,053;-3,44572;1754,55
130,76801;2,1795;6,054;-3,44527;1754,83
130,96801;2,1828;6,055;-3,44588;1754,95
131,16801;2,1861;6,056;-3,44552;1755,29
131,36801;2,1896;6,059;-3,44551;1756,10
131,56801;2,1929;6,060;-3,44576;1756,50
131,76801;2,1959;6,063;-3,44526;1757,34
131,96801;2,1996;6,069;-3,44583;1759,09
132,16801;2,2028;6,075;-3,44565;1760,86
132,36801;2,2060;6,085;-3,44577;1763,87
132,56801;2,2096;6,094;-3,44551;1766,52
132,76801;2,2129;6,102;-3,44611;1768,58
132,96801;2,2159;6,111;-3,44549;1771,40
133,16801;2,2195;6,120;-3,44590;1773,99
133,36801;2,2228;6,129;-3,44590;1776,40
133,56801;2,2260;6,137;-3,44549;1778,98
133,76801;2,2295;6,148;-3,44604;1782,02
133,96801;2,2328;6,162;-3,44550;1786,15
134,16801;2,2361;6,177;-3,44579;1790,32
134,36801;2,2394;6,189;-3,44588;1794,05
134,56801;2,2429;6,201;-3,44598;1797,37
134,76801;2,2461;6,212;-3,44572;1800,65
134,96801;2,2493;6,220;-3,44600;1802,85
135,16801;2,2529;6,228;-3,44594;1805,35
135,36801;2,2562;6,238;-3,44571;1808,08
135,56801;2,2593;6,248;-3,44598;1810,90
135,76801;2,2629;6,262;-3,44610;1815,05
135,96801;2,2662;6,278;-3,44586;1819,71
136,16801;2,2693;6,295;-3,44594;1824,64
136,36801;2,2728;6,310;-3,44596;1828,96
136,56801;2,2762;6,324;-3,44623;1832,92
136,76801;2,2795;6,331;-3,44552;1835,18
136,96801;2,2828;6,341;-3,44612;1837,97
137,16801;2,2862;6,348;-3,44603;1839,94
137,36801;2,2895;6,353;-3,44583;1841,35
137,56801;2,2926;6,358;-3,44621;1842,84
137,76801;2,2963;6,365;-3,44636;1844,90
137,96801;2,2994;6,371;-3,44601;1846,62
138,16801;2,3026;6,377;-3,44634;1848,55
138,36801;2,3063;6,385;-3,44629;1850,68
138,56801;2,3094;6,393;-3,44595;1852,94
138,76801;2,3127;6,397;-3,44624;1854,22
138,96801;2,3162;6,405;-3,44625;1856,43
139,16801;2,3195;6,409;-3,44615;1857,78
139,36801;2,3227;6,415;-3,44592;1859,56
139,56801;2,3261;6,417;-3,44661;1860,13
139,76801;2,3295;6,421;-3,44600;1861,09
139,96801;2,3328;6,424;-3,44643;1862,04
140,16801;2,3361;6,427;-3,44636;1862,96
140,36801;2,3396;6,434;-3,44636;1864,87
140,56801;2,3428;6,444;-3,44625;1867,70
140,76801;2,3459;6,449;-3,44634;1869,20
140,96801;2,3497;6,455;-3,44664;1871,11
141,16801;2,3528;6,461;-3,44588;1872,85
141,36801;2,3559;6,467;-3,44681;1874,43
141,56801;2,3596;6,471;-3,44622;1875,51
141,76801;2,3628;6,474;-3,44658;1876,54
141,96801;2,3660;6,479;-3,44616;1877,88
142,16801;2,3695;6,482;-3,44655;1878,95
142,36801;2,3728;6,489;-3,44651;1881,00
142,56801;2,3761;6,496;-3,44636;1882,93
142,76801;2,3794;6,504;-3,44651;1885,27
142,96801;2,3829;6,513;-3,44626;1887,92
143,16801;2,3861;6,523;-3,44693;1890,81
143,36801;2,3893;6,530;-3,44617;1892,86
143,56801;2,3929;6,539;-3,44675;1895,40
143,76801;2,3961;6,546;-3,44616;1897,37
143,96801;2,3994;6,553;-3,44682;1899,30
144,16801;2,4029;6,562;-3,44637;1902,09
144,36801;2,4062;6,570;-3,44636;1904,40
144,56801;2,4094;6,580;-3,44643;1907,12
144,76801;2,4128;6,589;-3,44660;1909,82
144,96801;2,4162;6,604;-3,44668;1914,34
145,16801;2,4194;6,618;-3,44658;1918,31
145,36801;2,4228;6,632;-3,44666;1922,37
145,56801;2,4262;6,652;-3,44604;1927,97
145,76801;2,4295;6,661;-3,44698;1930,69
145,96801;2,4327;6,669;-3,44621;1933,16
146,16801;2,4362;6,679;-3,44672;1935,90
146,36801;2,4395;6,684;-3,44664;1937,36
146,56801;2,4426;6,687;-3,44610;1938,18
146,76801;2,4462;6,690;-3,44706;1939,10
146,96801;2,4495;6,693;-3,44642;1939,96
147,16801;2,4527;6,696;-3,44663;1940,79
147,36801;2,4562;6,702;-3,44674;1942,47
147,56801;2,4595;6,708;-3,44677;1944,49
147,76801;2,4627;6,716;-3,44649;1946,81
147,96801;2,4662;6,724;-3,44682;1949,09
148,16801;2,4695;6,736;-3,44673;1952,38
148,36801;2,4728;6,744;-3,44666;1954,88
148,56801;2,4760;6,755;-3,44720;1958,07
148,76801;2,4795;6,764;-3,44637;1960,60
148,96801;2,4828;6,774;-3,44700;1963,56
149,16801;2,4860;6,781;-3,44649;1965,61
149,36801;2,4896;6,792;-3,44678;1968,68
149,56801;2,4928;6,804;-3,44671;1972,29
149,76801;2,4960;6,813;-3,44685;1974,81
149,96801;2,4996;6,825;-3,44657;1978,30
150,16801;2,5029;6,839;-3,44690;1982,19
150,36801;2,5060;6,849;-3,44694;1985,31
150,56801;2,5094;6,858;-3,44651;1987,91
150,76801;2,5128;6,864;-3,44695;1989,54
150,96801;2,5161;6,866;-3,44651;1990,24
151,16801;2,5194;6,869;-3,44705;1991,13
151,36801;2,5229;6,872;-3,44661;1992,00
151,56801;2,5262;6,880;-3,44686;1994,16
151,76801;2,5293;6,885;-3,44703;1995,67
151,96801;2,5328;6,897;-3,44669;1999,24
152,16801;2,5361;6,905;-3,44708;2001,50
152,36801;2,5393;6,917;-3,44673;2004,93
152,56801;2,5429;6,924;-3,44700;2006,93
152,76801;2,5461;6,931;-3,44680;2009,08
152,96801;2,5494;6,935;-3,44701;2010,06
153,16801;2,5529;6,939;-3,44665;2011,32
153,36801;2,5562;6,943;-3,44715;2012,36
153,56801;2,5594;6,948;-3,44673;2013,90
153,76801;2,5627;6,952;-3,44700;2015,00
153,96801;2,5662;6,958;-3,44723;2016,91
154,16801;2,5695;6,962;-3,44652;2018,01
154,36801;2,5727;6,968;-3,44728;2019,63
154,56801;2,5763;6,973;-3,44664;2021,16
154,76801;2,5795;6,978;-3,44711;2022,74
154,96801;2,5826;6,985;-3,44678;2024,53
155,16801;2,5863;6,989;-3,44709;2025,93
155,36801;2,5895;6,993;-3,44695;2027,01
155,56801;2,5926;7,001;-3,44694;2029,33
155,76801;2,5963;7,005;-3,44717;2030,41
155,96801;2,5995;7,012;-3,44661;2032,56
156,16801;2,6027;7,018;-3,44739;2034,32
156,36801;2,6061;7,029;-3,44703;2037,45
156,56801;2,6095;7,042;-3,44711;2041,13
156,76801;2,6128;7,053;-3,44676;2044,45
156,96801;2,6161;7,065;-3,44736;2047,80
157,16801;2,6195;7,075;-3,44695;2050,80
157,36801;2,6228;7,084;-3,44687;2053,31
157,56801;2,6260;7,093;-3,44717;2055,90
157,76801;2,6296;7,104;-3,44691;2059,23
157,96801;2,6328;7,113;-3,44733;2061,87
158,16801;2,6360;7,127;-3,44673;2065,70
158,36801;2,6396;7,139;-3,44726;2069,14
158,56801;2,6428;7,154;-3,44683;2073,72
158,76801;2,6460;7,165;-3,44720;2076,77
158,96801;2,6496;7,176;-3,44717;2080,01
159,16801;2,6528;7,186;-3,44720;2082,95
159,36801;2,6560;7,199;-3,44699;2086,64
159,56801;2,6594;7,207;-3,44740;2088,97
159,76801;2,6629;7,215;-3,44716;2091,23
159,96801;2,6662;7,222;-3,44697;2093,47
160,16801;2,6694;7,228;-3,44720;2095,15
160,36801;2,6729;7,234;-3,44698;2096,81
160,56801;2,6761;7,246;-3,44759;2100,38
160,76801;2,6792;7,255;-3,44669;2102,81
160,96801;2,6830;7,270;-3,44715;2107,24
161,16801;2,6862;7,281;-3,44716;2110,40
161,36801;2,6893;7,292;-3,44694;2113,60
161,56801;2,6928;7,303;-3,44712;2116,89
161,76801;2,6961;7,309;-3,44716;2118,57
161,96801;2,6993;7,313;-3,44710;2119,67
162,16801;2,7027;7,316;-3,44719;2120,67
162,36801;2,7062;7,319;-3,44733;2121,45
162,56801;2,7094;7,321;-3,44759;2121,91
162,76801;2,7127;7,322;-3,44698;2122,18
162,96801;2,7162;7,323;-3,44748;2122,51
163,16801;2,7195;7,324;-3,44717;2122,95
163,36801;2,7227;7,326;-3,44755;2123,42
163,56801;2,7263;7,329;-3,44701;2124,26
163,76801;2,7295;7,332;-3,44733;2125,23
163,96801;2,7327;7,335;-3,44707;2126,22
164,16801;2,7362;7,340;-3,44735;2127,67
164,36801;2,7395;7,344;-3,44690;2128,77
164,56801;2,7428;7,351;-3,44766;2130,66
164,76801;2,7461;7,355;-3,44726;2131,92
164,96801;2,7495;7,364;-3,44701;2134,63
165,16801;2,7527;7,375;-3,44805;2137,70
165,36801;2,7561;7,388;-3,44707;2141,55
165,56801;2,7596;7,400;-3,44744;2144,87
165,76801;2,7628;7,413;-3,44733;2148,82
165,96801;2,7660;7,425;-3,44737;2152,04
166,16801;2,7696;7,431;-3,44747;2153,98
166,36801;2,7728;7,441;-3,44733;2156,78
166,56801;2,7760;7,450;-3,44740;2159,34
166,76801;2,7796;7,461;-3,44738;2162,60
166,96801;2,7828;7,475;-3,44765;2166,76
167,16801;2,7860;7,494;-3,44676;2172,13
167,36801;2,7896;7,508;-3,44805;2176,38
167,56801;2,7928;7,527;-3,44719;2181,70
167,76801;2,7961;7,539;-3,44721;2185,35
167,96801;2,7994;7,553;-3,44741;2189,16
168,16801;2,8029;7,565;-3,44748;2192,86
168,36801;2,8061;7,575;-3,44763;2195,67
168,56801;2,8094;7,582;-3,44743;2197,79
168,76801;2,8129;7,595;-3,44784;2201,36
168,96801;2,8162;7,603;-3,44716;2203,69
169,16801;2,8193;7,609;-3,44834;2205,53
169,36801;2,8229;7,617;-3,44671;2207,81
169,56801;2,8262;7,624;-3,44793;2209,90
169,76801;2,8294;7,628;-3,44743;2210,99
169,96801;2,8329;7,637;-3,44739;2213,70
170,16801;2,8362;7,639;-3,44756;2214,32
170,36801;2,8393;7,647;-3,44722;2216,40
170,56801;2,8428;7,653;-3,44781;2218,34
170,76801;2,8461;7,662;-3,44725;2220,73
170,96801;2,8494;7,670;-3,44764;2223,26
171,16801;2,8527;7,676;-3,44745;2224,91
171,36801;2,8562;7,687;-3,44789;2228,04
171,56801;2,8595;7,695;-3,44689;2230,42
171,76801;2,8626;7,702;-3,44792;2232,38
171,96801;2,8662;7,718;-3,44758;2237,21
172,16801;2,8694;7,725;-3,44740;2239,10
172,36801;2,8726;7,730;-3,44805;2240,58
172,56801;2,8762;7,736;-3,44719;2242,21
172,76801;2,8795;7,739;-3,44775;2243,25
172,96801;2,8826;7,742;-3,44770;2244,13
173,16801;2,8863;7,748;-3,44733;2245,92
173,36801;2,8895;7,755;-3,44767;2247,69
173,56801;2,8927;7,761;-3,44793;2249,51
173,76801;2,8961;7,767;-3,44719;2251,39
173,96801;2,8996;7,774;-3,44745;2253,33
174,16801;2,9029;7,783;-3,44783;2256,04
174,36801;2,9060;7,791;-3,44714;2258,33
174,56801;2,9096;7,800;-3,44805;2260,81
174,76801;2,9128;7,807;-3,44775;2262,83
174,96801;2,9159;7,813;-3,44730;2264,78
175,16801;2,9196;7,823;-3,44814;2267,56
175,36801;2,9228;7,827;-3,44778;2268,80
175,56801;2,9259;7,833;-3,44733;2270,47
175,76801;2,9295;7,838;-3,44802;2271,84
175,96801;2,9328;7,845;-3,44787;2273,94
176,16801;2,9360;7,852;-3,44716;2275,85
176,36801;2,9395;7,861;-3,44824;2278,61
176,56801;2,9428;7,870;-3,44734;2281,21
176,76801;2,9461;7,881;-3,44785;2284,24
176,96801;2,9494;7,889;-3,44759;2286,74
177,16801;2,9529;7,898;-3,44799;2289,19
177,36801;2,9561;7,904;-3,44760;2291,07
177,56801;2,9594;7,911;-3,44761;2293,02
177,76801;2,9629;7,917;-3,44800;2294,79
177,96801;2,9662;7,921;-3,44734;2296,05
178,16801;2,9693;7,928;-3,44803;2298,09
178,36801;2,9730;7,934;-3,44742;2299,70
178,56801;2,9762;7,938;-3,44815;2300,74
178,76801;2,9794;7,945;-3,44777;2302,78
178,96801;2,9828;7,950;-3,44782;2304,27
179,16801;2,9862;7,958;-3,44804;2306,66
179,36801;2,9894;7,965;-3,44766;2308,62
179,56801;2,9928;7,973;-3,44820;2311,12
179,76801;2,9962;7,982;-3,44731;2313,67
179,96801;2,9995;7,990;-3,44807;2315,95
180,16801;3,0027;7,999;-3,44755;2318,59
180,36801;3,0063;8,007;-3,44790;2320,91
180,56801;3,0094;8,018;-3,44761;2323,99
180,76801;3,0126;8,030;-3,44803;2327,64
180,96801;3,0162;8,044;-3,44746;2331,47
181,16801;3,0194;8,058;-3,44803;2335,79
181,36801;3,0227;8,067;-3,44784;2338,30
181,56801;3,0262;8,077;-3,44775;2341,27
181,76801;3,0295;8,084;-3,44804;2343,28
181,96801;3,0327;8,092;-3,44738;2345,38
182,16801;3,0361;8,099;-3,44811;2347,48
182,36801;3,0395;8,108;-3,44737;2350,01
182,56801;3,0428;8,120;-3,44786;2353,73
182,76801;3,0461;8,131;-3,44781;2356,82
182,96801;3,0496;8,144;-3,44779;2360,53
183,16801;3,0529;8,159;-3,44786;2365,06
183,36801;3,0559;8,166;-3,44786;2367,03
183,56801;3,0596;8,178;-3,44796;2370,49
183,76801;3,0628;8,185;-3,44759;2372,59
183,96801;3,0660;8,191;-3,44817;2374,30
184,16801;3,0696;8,198;-3,44755;2376,26
184,36801;3,0728;8,205;-3,44802;2378,16
184,56801;3,0761;8,208;-3,44771;2379,02
184,76801;3,0795;8,214;-3,44773;2380,77
184,96801;3,0828;8,216;-3,44773;2381,50
185,16801;3,0860;8,220;-3,44788;2382,59
185,36801;3,0893;8,221;-3,44781;2383,03
185,56801;3,0929;8,225;-3,44753;2383,96
185,76801;3,0961;8,226;-3,44800;2384,45
185,96801;3,0993;8,228;-3,44766;2384,83
186,16801;3,1029;8,229;-3,44799;2385,18
186,36801;3,1061;8,230;-3,44776;2385,58
186,56801;3,1093;8,230;-3,44806;2385,42
186,76801;3,1129;8,231;-3,44786;2385,78
186,94801;3,1159;7,849;-3,44822;2275,21
187,14801;3,1191;7,822;-3,44761;2267,39
187,34801;3,1225;7,829;-3,44823;2269,14
187,54801;3,1259;7,836;-3,44847;2271,32
187,74801;3,1291;7,845;-3,44743;2273,77
187,94801;3,1324;7,850;-3,44867;2275,51
188,14801;3,1359;7,865;-3,44775;2279,80
188,34801;3,1391;7,877;-3,44818;2283,28
188,54801;3,1423;7,885;-3,44820;2285,49
188,74801;3,1459;7,897;-3,44812;2288,88
188,94801;3,1492;7,904;-3,44793;2291,06
189,14801;3,1523;7,911;-3,44851;2293,18
189,34801;3,1559;7,919;-3,44783;2295,31
189,54801;3,1591;7,924;-3,44840;2296,91
189,74801;3,1623;7,931;-3,44801;2298,72
189,94801;3,1659;7,936;-3,44762;2300,35
190,14801;3,1691;7,943;-3,44886;2302,42
190,34801;3,1724;7,949;-3,44778;2303,95
190,54801;3,1758;7,902;-3,44814;2290,55
190,74801;3,1792;7,912;-3,44819;2293,27
190,94801;3,1824;7,913;-3,44819;2293,61
191,14801;3,1857;7,919;-3,44807;2295,31
191,34801;3,1892;7,926;-3,44843;2297,51
191,54801;3,1925;7,931;-3,44800;2298,97
191,74801;3,1957;7,937;-3,44827;2300,52
191,94801;3,1993;7,943;-3,44842;2302,32
192,14801;3,2025;7,655;-3,44803;2218,72
192,34801;3,2056;7,649;-3,44832;2217,00
192,54801;3,2092;7,658;-3,44789;2219,65
192,74801;3,2125;7,654;-3,44842;2218,63
192,94801;3,2158;7,660;-3,44852;2220,28
193,14801;3,2191;7,642;-3,44812;2215,19
193,34801;3,2226;7,311;-3,44828;2119,05
193,51801;3,2253;7,313;-3,44811;2119,84