File: Klausurvorbereitung/Übungen/UE5_Specimen_RawData_2.csv
Texteingaben : Proben-beschriftung;"dpp-PUL6-2"
Allgemein : Startdatum;16.08.2018 16:15:53
Abmessung : Querschnitt;3,45000;mm^2

Zeit;Traversenweg;Last;Dehnung 1;Zugspannung
(sec);(mm);(kN);(%);(MPa)
0,00000;0,0000;0,089;0,00021;25,67
0,20000;0,0010;0,088;0,00035;25,37
0,40000;0,0054;0,101;0,00199;29,41
0,60000;0,0099;0,137;0,00475;39,57
0,80000;0,0133;0,155;0,00673;45,01
1,00000;0,0164;0,172;0,00853;49,89
1,20000;0,0200;0,184;0,01067;53,20
1,40000;0,0232;0,193;0,01259;55,89
1,60000;0,0265;0,198;0,01455;57,36
1,80000;0,0299;0,202;0,01648;58,59
2,00000;0,0333;0,206;0,01853;59,65
2,20000;0,0365;0,209;0,02051;60,63
2,40000;0,0398;0,211;0,02232;61,15
2,60000;0,0433;0,214;0,02445;62,02
2,80000;0,0466;0,217;0,02642;62,89
3,00000;0,0498;0,221;0,02826;63,94
3,20000;0,0534;0,224;0,03040;64,83
3,40000;0,0567;0,227;0,03237;65,70
3,60000;0,0598;0,232;0,03419;67,17
3,80000;0,0634;0,240;0,03623;69,67
4,00000;0,0667;0,255;0,03828;73,82
4,20000;0,0698;0,267;0,04011;77,46
4,40000;0,0733;0,285;0,04205;82,51
4,60000;0,0767;0,300;0,04405;86,96
4,80000;0,0799;0,316;0,04593;91,68
5,00000;0,0832;0,325;0,04778;94,11
5,20000;0,0867;0,334;0,04990;96,74
5,40000;0,0899;0,344;0,05178;99,57
5,60000;0,0931;0,353;0,05361;102,21
5,80000;0,0967;0,361;0,05571;104,73
6,00000;0,0999;0,371;0,05763;107,51
6,20000;0,1031;0,383;0,05957;111,07
6,40000;0,1067;0,395;0,06163;114,53
6,60000;0,1099;0,407;0,06352;117,93
6,80000;0,1132;0,421;0,06543;122,02
7,00000;0,1167;0,435;0,06733;126,20
7,20000;0,1200;0,447;0,06934;129,67
7,40000;0,1232;0,458;0,07120;132,62
7,60000;0,1265;0,465;0,07307;134,79
7,80000;0,1300;0,471;0,07514;136,54
8,00000;0,1333;0,474;0,07709;137,50
8,20000;0,1365;0,479;0,07890;138,86
8,40000;0,1401;0,483;0,08102;140,04
8,60000;0,1433;0,485;0,08279;140,52
8,80000;0,1464;0,489;0,08463;141,81
9,00000;0,1501;0,494;0,08682;143,18
9,20000;0,1533;0,500;0,08869;145,06
9,40000;0,1564;0,509;0,09036;147,43
9,60000;0,1601;0,515;0,09244;149,20
9,80000;0,1633;0,527;0,09429;152,72
10,00000;0,1665;0,539;0,09617;156,36
10,20000;0,1700;0,551;0,09801;159,62
10,40000;0,1733;0,565;0,09993;163,73
10,60000;0,1766;0,580;0,10184;168,26
10,80000;0,1798;0,599;0,10362;173,76
11,00000;0,1833;0,618;0,10569;179,03
11,20000;0,1866;0,629;0,10752;182,27
11,40000;0,1898;0,637;0,10927;184,67
11,60000;0,1933;0,645;0,11131;187,06
11,80000;0,1966;0,656;0,11324;190,06
12,00000;0,1998;0,663;0,11502;192,15
12,20000;0,2034;0,672;0,11710;194,70
12,40000;0,2066;0,680;0,11891;197,15
12,60000;0,2098;0,687;0,12076;199,25
12,80000;0,2134;0,695;0,12274;201,51
13,00000;0,2166;0,707;0,12457;204,81
13,20000;0,2199;0,720;0,12645;208,67
13,40000;0,2232;0,733;0,12829;212,58
13,60000;0,2267;0,750;0,13025;217,32
13,80000;0,2299;0,767;0,13211;222,41
14,00000;0,2332;0,776;0,13385;224,94
14,20000;0,2368;0,786;0,13594;227,76
14,40000;0,2399;0,790;0,13770;228,99
14,60000;0,2431;0,792;0,13954;229,71
14,80000;0,2467;0,796;0,14157;230,58
15,00000;0,2500;0,798;0,14342;231,34
15,20000;0,2531;0,802;0,14520;232,35
15,40000;0,2567;0,806;0,14715;233,54
15,60000;0,2600;0,812;0,14897;235,24
15,80000;0,2631;0,816;0,15081;236,55
16,00000;0,2666;0,822;0,15261;238,28
16,20000;0,2699;0,827;0,15459;239,66
16,40000;0,2732;0,831;0,15634;240,99
16,60000;0,2766;0,837;0,15820;242,59
16,80000;0,2800;0,843;0,16020;244,37
17,00000;0,2833;0,853;0,16205;247,37
17,20000;0,2865;0,863;0,16383;250,15
17,40000;0,2900;0,877;0,16576;254,30
17,60000;0,2933;0,892;0,16768;258,57
17,80000;0,2964;0,905;0,16939;262,24
18,00000;0,3001;0,917;0,17144;265,76
18,20000;0,3033;0,925;0,17329;268,02
18,40000;0,3065;0,937;0,17502;271,55
18,60000;0,3101;0,947;0,17704;274,58
18,80000;0,3133;0,962;0,17882;278,98
19,00000;0,3164;0,977;0,18060;283,04
19,20000;0,3199;0,994;0,18254;288,18
19,40000;0,3234;1,012;0,18449;293,24
19,60000;0,3266;1,024;0,18620;296,88
19,80000;0,3299;1,039;0,18797;301,18
20,00000;0,3333;1,061;0,19004;307,47
20,20000;0,3365;1,076;0,19169;311,77
20,40000;0,3398;1,089;0,19355;315,51
20,60000;0,3433;1,101;0,19562;319,05
20,80000;0,3466;1,108;0,19733;321,14
21,00000;0,3498;1,113;0,19917;322,66
21,20000;0,3534;1,118;0,20108;324,06
21,40000;0,3566;1,122;0,20293;325,24
21,60000;0,3598;1,123;0,20464;325,51
21,80000;0,3633;1,127;0,20651;326,58
22,00000;0,3667;1,130;0,20835;327,48
22,20000;0,3699;1,133;0,21021;328,42
22,40000;0,3732;1,138;0,21200;329,74
22,60000;0,3767;1,143;0,21389;331,22
22,80000;0,3800;1,150;0,21568;333,29
23,00000;0,3831;1,156;0,21746;335,07
23,20000;0,3867;1,164;0,21943;337,32
23,40000;0,3900;1,172;0,22125;339,67
23,60000;0,3930;1,178;0,22301;341,32
23,80000;0,3968;1,192;0,22504;345,41
24,00000;0,3999;1,205;0,22669;349,32
24,20000;0,4031;1,217;0,22850;352,67
24,40000;0,4067;1,227;0,23039;355,70
24,60000;0,4099;1,240;0,23215;359,48
24,80000;0,4131;1,249;0,23395;362,15
25,00000;0,4166;1,258;0,23578;364,71
25,20000;0,4200;1,268;0,23778;367,65
25,40000;0,4233;1,279;0,23948;370,84
25,60000;0,4265;1,289;0,24118;373,55
25,80000;0,4300;1,297;0,24325;376,03
26,00000;0,4332;1,305;0,24496;378,23
26,20000;0,4365;1,314;0,24663;380,97
26,40000;0,4401;1,326;0,24862;384,33
26,60000;0,4433;1,339;0,25037;388,01
26,80000;0,4464;1,354;0,25206;392,56
27,00000;0,4501;1,366;0,25412;395,93
27,20000;0,4533;1,376;0,25591;398,98
27,40000;0,4564;1,383;0,25758;400,82
27,60000;0,4599;1,390;0,25939;402,97
27,80000;0,4633;1,398;0,26123;405,34
28,00000;0,4666;1,407;0,26305;407,77
28,20000;0,4699;1,415;0,26484;410,18
28,40000;0,4733;1,426;0,26670;413,45
28,60000;0,4766;1,432;0,26843;414,93
28,80000;0,4797;1,440;0,27019;417,48
29,00000;0,4834;1,451;0,27222;420,56
29,20000;0,4866;1,459;0,27387;423,00
29,40000;0,4898;1,467;0,27549;425,26
29,60000;0,4935;1,476;0,27758;427,85
29,80000;0,4966;1,482;0,27934;429,55
30,00000;0,4998;1,489;0,28105;431,70
30,20000;0,5034;1,502;0,28294;435,44
30,40000;0,5066;1,514;0,28463;438,70
30,60000;0,5099;1,526;0,28642;442,38
30,80000;0,5133;1,542;0,28821;446,95
31,00000;0,5167;1,551;0,29005;449,46
31,20000;0,5199;1,560;0,29173;452,05
31,40000;0,5232;1,569;0,29347;454,88
31,60000;0,5267;1,579;0,29551;457,78
31,80000;0,5299;1,593;0,29722;461,63
32,00000;0,5332;1,603;0,29893;464,51
32,20000;0,5367;1,615;0,30100;468,21
32,40000;0,5400;1,627;0,30271;471,53
32,60000;0,5431;1,632;0,30433;472,91
32,80000;0,5468;1,641;0,30633;475,59
33,00000;0,5499;1,649;0,30792;478,04
33,20000;0,5531;1,660;0,30969;481,20
33,40000;0,5567;1,672;0,31165;484,73
33,60000;0,5599;1,684;0,31335;488,17
33,80000;0,5631;1,693;0,31509;490,73
34,00000;0,5667;1,700;0,31694;492,88
34,20000;0,5700;1,707;0,31877;494,78
34,40000;0,5732;1,713;0,32053;496,55
34,60000;0,5765;1,718;0,32213;498,02
34,80000;0,5800;1,724;0,32409;499,67
35,00000;0,5833;1,728;0,32586;500,81
35,20000;0,5865;1,732;0,32755;501,90
35,40000;0,5900;1,735;0,32940;502,89
35,60000;0,5933;1,739;0,33122;503,93
35,80000;0,5965;1,739;0,33283;504,14
36,00000;0,6001;1,743;0,33475;505,21
36,20000;0,6033;1,749;0,33639;507,07
36,40000;0,6064;1,754;0,33812;508,28
36,60000;0,6100;1,763;0,33997;511,06
36,80000;0,6133;1,775;0,34175;514,63
37,00000;0,6165;1,792;0,34339;519,52
37,20000;0,6199;1,812;0,34513;525,09
37,40000;0,6233;1,830;0,34695;530,46
37,60000;0,6265;1,846;0,34862;534,98
37,80000;0,6298;1,862;0,35032;539,57
38,00000;0,6333;1,873;0,35220;542,80
38,20000;0,6366;1,884;0,35395;546,07
38,40000;0,6398;1,895;0,35558;549,14
38,60000;0,6434;1,910;0,35747;553,60
38,80000;0,6466;1,921;0,35920;556,74
39,00000;0,6498;1,932;0,36086;560,03
39,20000;0,6533;1,945;0,36265;563,83
39,40000;0,6566;1,957;0,36436;567,30
39,60000;0,6599;1,973;0,36616;571,80
39,80000;0,6632;1,986;0,36788;575,70
40,00000;0,6667;1,999;0,36968;579,49
40,20000;0,6699;2,012;0,37132;583,19
40,40000;0,6732;2,021;0,37297;585,67
40,60000;0,6767;2,027;0,37492;587,61
40,80000;0,6800;2,033;0,37665;589,40
41,00000;0,6831;2,039;0,37817;591,08
41,20000;0,6868;2,045;0,38011;592,85
41,40000;0,6900;2,051;0,38182;594,49
41,60000;0,6931;2,053;0,38339;595,21
41,80000;0,6967;2,059;0,38513;596,79
42,00000;0,6999;2,062;0,38680;597,61
42,20000;0,7032;2,063;0,38849;597,85
42,40000;0,7066;2,064;0,39021;598,21
42,60000;0,7100;2,064;0,39194;598,34
42,80000;0,7133;2,066;0,39359;598,98
43,00000;0,7165;2,069;0,39523;599,65
43,20000;0,7200;2,075;0,39715;601,45
43,40000;0,7232;2,086;0,39883;604,53
43,60000;0,7264;2,097;0,40048;607,82
43,80000;0,7301;2,112;0,40223;612,09
44,00000;0,7333;2,126;0,40394;616,29
44,20000;0,7365;2,138;0,40549;619,71
44,40000;0,7400;2,149;0,40739;622,99
44,60000;0,7433;2,160;0,40895;626,11
44,80000;0,7464;2,166;0,41066;627,93
45,00000;0,7500;2,179;0,41252;631,71
45,20000;0,7533;2,187;0,41423;634,02
45,40000;0,7566;2,200;0,41586;637,82
45,60000;0,7599;2,211;0,41742;640,74
45,80000;0,7633;2,220;0,41920;643,43
46,00000;0,7666;2,228;0,42087;645,89
46,20000;0,7698;2,238;0,42242;648,65
46,40000;0,7734;2,254;0,42421;653,32
46,60000;0,7767;2,274;0,42595;659,14
46,80000;0,7798;2,289;0,42751;663,47
47,00000;0,7835;2,308;0,42939;669,13
47,20000;0,7867;2,319;0,43096;672,21
47,40000;0,7897;2,332;0,43247;675,86
47,60000;0,7933;2,341;0,43426;678,64
47,80000;0,7966;2,348;0,43587;680,58
48,00000;0,7998;2,356;0,43756;682,96
48,20000;0,8033;2,364;0,43916;685,25
48,40000;0,8066;2,372;0,44095;687,57
48,60000;0,8098;2,378;0,44249;689,19
48,80000;0,8131;2,382;0,44413;690,50
49,00000;0,8166;2,387;0,44593;691,98
49,20000;0,8199;2,391;0,44748;693,03
49,40000;0,8232;2,396;0,44915;694,51
49,60000;0,8267;2,401;0,45100;696,06
49,80000;0,8300;2,410;0,45261;698,43
50,00000;0,8331;2,419;0,45407;701,10
50,20000;0,8368;2,433;0,45594;705,24
50,40000;0,8399;2,446;0,45749;709,11
50,60000;0,8431;2,462;0,45912;713,68
50,80000;0,8467;2,475;0,46089;717,51
51,00000;0,8500;2,489;0,46251;721,55
51,20000;0,8532;2,501;0,46409;724,80
51,40000;0,8566;2,509;0,46567;727,26
51,60000;0,8600;2,516;0,46743;729,26
51,80000;0,8632;2,521;0,46893;730,61
52,00000;0,8665;2,525;0,47058;731,81
52,20000;0,8700;2,531;0,47232;733,58
52,40000;0,8733;2,535;0,47396;734,66
52,60000;0,8765;2,542;0,47546;736,80
52,80000;0,8801;2,550;0,47720;739,11
53,00000;0,8833;2,561;0,47874;742,45
53,20000;0,8865;2,577;0,48030;746,90
53,40000;0,8900;2,592;0,48210;751,28
53,60000;0,8933;2,603;0,48370;754,61
53,80000;0,8965;2,614;0,48526;757,79
54,00000;0,9000;2,625;0,48692;760,86
54,20000;0,9033;2,631;0,48861;762,61
54,40000;0,9065;2,638;0,49012;764,53
54,60000;0,9098;2,641;0,49171;765,44
54,80000;0,9133;2,644;0,49351;766,47
55,00000;0,9166;2,648;0,49506;767,47
55,20000;0,9198;2,652;0,49662;768,76
55,40000;0,9234;2,659;0,49844;770,71
55,60000;0,9267;2,668;0,49997;773,19
55,80000;0,9298;2,674;0,50155;775,12
56,00000;0,9334;2,682;0,50320;777,30
56,20000;0,9366;2,691;0,50482;780,01
56,38600;0,9395;2,696;0,50630;781,44
56,58600;0,9431;2,706;0,50796;784,39
56,78600;0,9464;2,718;0,50967;787,71
56,98600;0,9497;2,731;0,51124;791,73
57,18600;0,9530;2,744;0,51290;795,34
57,38600;0,9564;2,759;0,51458;799,85
57,58600;0,9597;2,776;0,51611;804,64
57,78600;0,9629;2,787;0,51758;807,78
57,98600;0,9665;2,802;0,51942;812,12
58,18600;0,9698;2,815;0,52104;815,96
58,38600;0,9729;2,825;0,52251;818,79
58,58600;0,9766;2,839;0,52421;822,88
58,78600;0,9797;2,852;0,52579;826,68
58,98600;0,9829;2,861;0,52736;829,31
59,18600;0,9865;2,872;0,52903;832,37
59,38600;0,9897;2,879;0,53066;834,60
59,58600;0,9930;2,887;0,53223;836,91
59,78600;0,9963;2,897;0,53389;839,82
59,98600;0,9998;2,913;0,53554;844,31
60,18600;1,0030;2,930;0,52390;849,34
60,38600;1,0062;2,942;0,37611;852,79
60,58600;1,0098;2,951;-1,66959;855,45
60,78600;1,0131;2,964;-3,45241;859,10
60,98600;1,0162;2,967;-3,46024;859,98
61,18600;1,0199;2,971;-3,03345;861,05
61,38600;1,0231;2,972;-2,80912;861,48
61,58600;1,0262;2,973;-2,49106;861,75
61,78600;1,0298;2,974;-3,95625;861,91
61,98600;1,0330;2,974;-1,19144;862,12
62,18600;1,0363;2,975;-3,28206;862,27
62,38600;1,0397;2,976;-3,70741;862,54
62,58600;1,0431;2,977;-3,93840;863,01
62,78600;1,0463;2,979;-3,96448;863,50
62,98600;1,0496;2,982;-2,88970;864,26
63,18600;1,0531;2,986;-3,95500;865,56
63,38600;1,0564;2,994;-3,31892;867,78
63,58600;1,0595;3,002;-3,25946;870,05
63,78600;1,0631;3,012;-3,80524;872,90
63,98600;1,0664;3,026;-3,38618;876,97
64,18600;1,0696;3,041;-3,31224;881,44
64,38600;1,0732;3,055;-3,72078;885,60
64,58600;1,0764;3,072;-3,41407;890,53
64,78600;1,0795;3,085;-3,35521;894,31
64,98600;1,0831;3,098;-3,66420;897,99
65,18600;1,0864;3,108;-3,42874;900,74
65,38600;1,0897;3,116;-3,38900;903,33
65,58600;1,0930;3,128;-3,62371;906,62
65,78600;1,0965;3,135;-3,43676;908,62
65,98600;1,0996;3,146;-3,41523;911,97
66,18600;1,1029;3,160;-3,59363;916,01
66,38600;1,1065;3,178;-3,44264;921,02
66,58600;1,1097;3,195;-3,43559;926,05
66,78600;1,1129;3,212;-3,57092;930,96
66,98600;1,1165;3,230;-3,44684;936,37
67,18600;1,1198;3,245;-3,45119;940,48
67,38600;1,1229;3,256;-3,55336;943,64
67,58600;1,1265;3,267;-3,45058;947,08
67,78600;1,1297;3,274;-3,46326;948,87
67,98600;1,1329;3,281;-3,53892;951,07
68,18600;1,1364;3,289;-3,45439;953,30
68,38600;1,1397;3,296;-3,47230;955,29
68,58600;1,1430;3,303;-3,52754;957,26
68,78600;1,1463;3,308;-3,45797;958,97
68,98600;1,1498;3,315;-3,47908;961,00
69,18600;1,1530;3,321;-3,51847;962,68
69,38600;1,1563;3,326;-3,46149;963,92
69,58600;1,1598;3,331;-3,48411;965,56
69,78600;1,1631;3,334;-3,51110;966,43
69,98600;1,1662;3,339;-3,46482;967,80
70,18600;1,1699;3,344;-3,48751;969,29
70,38600;1,1731;3,351;-3,50512;971,21
70,58600;1,1762;3,357;-3,46775;973,18
70,78600;1,1798;3,371;-3,48968;977,22
70,98600;1,1831;3,378;-3,50022;979,12
71,18600;1,1863;3,388;-3,47090;982,14
71,38600;1,1897;3,395;-3,49105;983,92
71,58600;1,1931;3,398;-3,49676;984,97
71,78600;1,1963;3,402;-3,47363;986,11
71,98600;1,1996;3,408;-3,49183;987,84
72,18600;1,2031;3,415;-3,49380;989,93
72,38600;1,2063;3,424;-3,47596;992,49
72,58600;1,2095;3,431;-3,49253;994,44
72,78600;1,2132;3,445;-3,49141;998,68
72,98600;1,2164;3,453;-3,47832;1000,83
73,18600;1,2196;3,463;-3,49224;1003,71
73,38600;1,2231;3,473;-3,48990;1006,55
73,58600;1,2264;3,482;-3,47980;1009,35
73,78600;1,2296;3,494;-3,49216;1012,64
73,98600;1,2331;3,507;-3,48843;1016,55
74,18600;1,2364;3,521;-3,48161;1020,72
74,38600;1,2397;3,535;-3,49189;1024,72
74,58600;1,2429;3,549;-3,48751;1028,61
74,78600;1,2465;3,557;-3,48317;1030,91
74,98600;1,2497;3,566;-3,49140;1033,70
75,18600;1,2529;3,575;-3,48692;1036,35
75,38600;1,2565;3,582;-3,48409;1038,12
75,58600;1,2598;3,589;-3,49102;1040,29
75,78600;1,2628;3,595;-3,48645;1042,09
75,98600;1,2665;3,600;-3,48535;1043,54
76,18600;1,2697;3,605;-3,49032;1044,96
76,38600;1,2728;3,610;-3,48631;1046,31
76,58600;1,2764;3,614;-3,48613;1047,55
76,78600;1,2797;3,621;-3,48979;1049,60
76,98600;1,2830;3,629;-3,48630;1051,75
77,18600;1,2863;3,636;-3,48673;1053,94
77,38600;1,2898;3,648;-3,48958;1057,42
77,58600;1,2930;3,659;-3,48635;1060,52
77,78600;1,2962;3,672;-3,48732;1064,34
77,98600;1,2998;3,688;-3,48930;1068,94
78,18600;1,3030;3,704;-3,48668;1073,66
78,38600;1,3062;3,718;-3,48762;1077,73
78,58600;1,3099;3,736;-3,48905;1082,94
78,78600;1,3131;3,749;-3,48665;1086,77
78,98600;1,3162;3,760;-3,48786;1089,99
79,18600;1,3198;3,768;-3,48868;1092,25
79,38600;1,3231;3,775;-3,48700;1094,29
79,58600;1,3264;3,781;-3,48809;1096,02
79,78600;1,3296;3,788;-3,48852;1098,11
79,98600;1,3331;3,798;-3,48717;1100,94
80,18600;1,3364;3,812;-3,48811;1104,86
80,38600;1,3396;3,823;-3,48833;1108,24
80,58600;1,3431;3,833;-3,48742;1111,16
80,78600;1,3464;3,848;-3,48831;1115,31
80,98600;1,3495;3,856;-3,48800;1117,68
81,18600;1,3532;3,863;-3,48752;1119,65
81,38600;1,3564;3,866;-3,48837;1120,59
81,58600;1,3595;3,870;-3,48810;1121,62
81,78600;1,3631;3,872;-3,48758;1122,24
81,98600;1,3663;3,873;-3,48841;1122,73
82,18600;1,3696;3,874;-3,48787;1123,02
82,38600;1,3731;3,876;-3,48791;1123,36
82,58600;1,3764;3,877;-3,48847;1123,71
82,78600;1,3797;3,878;-3,48778;1124,13
82,98600;1,3829;3,881;-3,48823;1124,93
83,18600;1,3864;3,883;-3,48829;1125,64
83,38600;1,3897;3,887;-3,48787;1126,57
83,58600;1,3929;3,894;-3,48810;1128,73
83,78600;1,3965;3,899;-3,48843;1130,17
83,98600;1,3997;3,907;-3,48784;1132,50
84,18600;1,4029;3,915;-3,48843;1134,80
84,38600;1,4065;3,927;-3,48828;1138,22
84,58600;1,4098;3,946;-3,48798;1143,63
84,78600;1,4129;3,958;-3,48830;1147,12
84,98600;1,4163;3,979;-3,48827;1153,26
85,18600;1,4198;3,991;-3,48788;1156,70
85,38600;1,4230;4,005;-3,48841;1160,92
85,58600;1,4264;4,015;-3,48831;1163,76
85,78600;1,4298;4,024;-3,48791;1166,40
85,98600;1,4330;4,035;-3,48853;1169,57
86,18600;1,4362;4,043;-3,48808;1171,80
86,38600;1,4398;4,054;-3,48824;1174,98
86,58600;1,4430;4,068;-3,48855;1179,10
86,78600;1,4462;4,082;-3,48824;1183,20
86,98600;1,4499;4,091;-3,48805;1185,86
87,18600;1,4531;4,101;-3,48852;1188,82
87,38600;1,4562;4,111;-3,48831;1191,63
87,58600;1,4598;4,123;-3,48801;1195,01
87,78600;1,4630;4,136;-3,48854;1198,71
87,98600;1,4663;4,151;-3,48841;1203,25
88,18600;1,4698;4,164;-3,48820;1207,05
88,38600;1,4731;4,181;-3,48829;1211,95
88,58600;1,4764;4,200;-3,48839;1217,43
88,78600;1,4796;4,208;-3,48833;1219,72
88,98600;1,4832;4,220;-3,48849;1223,20
89,18600;1,4864;4,227;-3,48836;1225,28
89,38600;1,4895;4,232;-3,48838;1226,55
89,58600;1,4932;4,237;-3,48837;1228,01
89,78600;1,4964;4,241;-3,48861;1229,13
89,98600;1,4996;4,242;-3,48842;1229,53
90,18600;1,5032;4,243;-3,48846;1229,93
90,38600;1,5064;4,245;-3,48866;1230,35
90,58600;1,5096;4,245;-3,48851;1230,49
90,78600;1,5130;4,246;-3,48856;1230,83
90,98600;1,5164;4,247;-3,48851;1231,06
91,18600;1,5197;4,248;-3,48853;1231,44
91,38600;1,5230;4,249;-3,48854;1231,66
91,58600;1,5265;4,251;-3,48860;1232,23
91,78600;1,5297;4,254;-3,48831;1233,16
91,98600;1,5329;4,257;-3,48870;1233,98
92,18600;1,5365;4,263;-3,48847;1235,53
92,38600;1,5397;4,269;-3,48877;1237,49
92,58600;1,5429;4,279;-3,48869;1240,23
92,78600;1,5465;4,287;-3,48847;1242,71
92,98600;1,5497;4,300;-3,48874;1246,45
93,18600;1,5529;4,313;-3,48874;1250,27
93,38600;1,5565;4,324;-3,48859;1253,31
93,58600;1,5597;4,333;-3,48857;1255,85
93,78600;1,5629;4,342;-3,48875;1258,56
93,98600;1,5663;4,347;-3,48835;1259,93
94,18600;1,5697;4,357;-3,48869;1262,78
94,38600;1,5731;4,364;-3,48858;1265,00
94,58600;1,5762;4,373;-3,48887;1267,49
94,78600;1,5798;4,387;-3,48871;1271,72
94,98600;1,5831;4,401;-3,48858;1275,59
95,18600;1,5862;4,416;-3,48882;1279,90
95,38600;1,5899;4,429;-3,48871;1283,74
95,58600;1,5931;4,445;-3,48874;1288,45
95,78600;1,5962;4,455;-3,48870;1291,42
95,98600;1,5999;4,467;-3,48882;1294,79
96,18600;1,6030;4,476;-3,48852;1297,26
96,38600;1,6062;4,482;-3,48882;1299,02
96,58600;1,6098;4,490;-3,48884;1301,31
96,78600;1,6130;4,498;-3,48872;1303,76
96,98600;1,6163;4,505;-3,48871;1305,78
97,18600;1,6196;4,511;-3,48889;1307,53
97,38600;1,6231;4,518;-3,48860;1309,60
97,58600;1,6263;4,524;-3,48889;1311,17
97,78600;1,6296;4,529;-3,48911;1312,88
97,98600;1,6332;4,535;-3,48850;1314,42
98,18600;1,6364;4,538;-3,48904;1315,49
98,38600;1,6395;4,542;-3,48897;1316,46
98,58600;1,6432;4,547;-3,48865;1318,11
98,78600;1,6464;4,553;-3,48918;1319,68
98,98600;1,6495;4,558;-3,48905;1321,16
99,18600;1,6531;4,566;-3,48860;1323,54
99,38600;1,6564;4,573;-3,48902;1325,44
99,58600;1,6596;4,583;-3,48886;1328,35
99,78600;1,6630;4,594;-3,48846;1331,66
99,98600;1,6664;4,607;-3,48916;1335,24
100,18600;1,6698;4,619;-3,48911;1338,83
100,38600;1,6729;4,630;-3,48861;1342,17
100,58600;1,6765;4,640;-3,48931;1345,05
100,78600;1,6796;4,653;-3,48882;1348,57
100,98600;1,6829;4,658;-3,48881;1350,08
101,18600;1,6865;4,665;-3,48927;1352,09
101,38600;1,6897;4,673;-3,48888;1354,39
101,58600;1,6929;4,677;-3,48876;1355,66
101,78600;1,6965;4,686;-3,48914;1358,20
101,98600;1,6997;4,692;-3,48882;1359,95
102,18600;1,7030;4,700;-3,48874;1362,40
102,38600;1,7064;4,706;-3,48949;1364,03
102,58600;1,7098;4,713;-3,48865;1366,16
102,78600;1,7130;4,717;-3,48896;1367,34
102,98600;1,7163;4,721;-3,48924;1368,45
103,18600;1,7198;4,724;-3,48886;1369,32
103,38600;1,7229;4,729;-3,48897;1370,65
103,58600;1,7262;4,735;-3,48922;1372,36
103,78600;1,7299;4,741;-3,48876;1374,28
103,98600;1,7331;4,750;-3,48897;1376,77
104,18600;1,7362;4,759;-3,48941;1379,35
104,38600;1,7399;4,768;-3,48860;1382,01
104,58600;1,7431;4,770;-3,48905;1382,72
104,78600;1,7462;4,778;-3,48893;1384,81
104,98600;1,7498;4,782;-3,48887;1386,13
105,18600;1,7530;4,785;-3,48886;1386,90
105,38601;1,7563;4,789;-3,48911;1388,14
105,58601;1,7597;4,794;-3,48877;1389,62
105,78601;1,7631;4,799;-3,48898;1390,97
105,98601;1,7664;4,805;-3,48915;1392,87
106,18601;1,7695;4,810;-3,48869;1394,28
106,38601;1,7731;4,820;-3,48917;1397,14
106,58601;1,7763;4,827;-3,48910;1399,17
106,78601;1,7796;4,838;-3,48890;1402,32
106,98601;1,7832;4,846;-3,48901;1404,60
107,18601;1,7864;4,858;-3,48923;1408,25
107,38601;1,7896;4,865;-3,48877;1410,08
107,58601;1,7931;4,877;-3,48923;1413,72
107,78601;1,7964;4,885;-3,48912;1415,89
107,98601;1,7996;4,894;-3,48880;1418,47
108,18601;1,8031;4,904;-3,48913;1421,51
108,38601;1,8065;4,915;-3,48908;1424,54
108,58601;1,8097;4,926;-3,48918;1427,80
108,78601;1,8130;4,941;-3,48916;1432,04
108,98601;1,8165;4,954;-3,48936;1435,97
109,18601;1,8197;4,966;-3,48915;1439,41
109,38601;1,8228;4,978;-3,48942;1442,92
109,58601;1,8265;4,989;-3,48930;1445,97
109,78601;1,8297;5,002;-3,48918;1449,73
109,98601;1,8329;5,011;-3,48919;1452,48
110,18601;1,8365;5,023;-3,48930;1455,89
110,38601;1,8397;5,037;-3,48921;1460,10
110,58601;1,8429;5,053;-3,48916;1464,56
110,78601;1,8464;5,069;-3,48930;1469,36
110,98601;1,8497;5,084;-3,48927;1473,57
111,18601;1,8530;5,101;-3,48919;1478,69
111,38601;1,8563;5,111;-3,48939;1481,41
111,58601;1,8598;5,119;-3,48931;1483,82
111,78601;1,8630;5,129;-3,48928;1486,52
111,98601;1,8662;5,134;-3,48928;1488,21
112,18601;1,8698;5,139;-3,48939;1489,51
112,38601;1,8731;5,143;-3,48929;1490,61
112,58601;1,8762;5,146;-3,48920;1491,62
112,78601;1,8799;5,148;-3,48944;1492,13
112,98601;1,8831;5,149;-3,48922;1492,36
113,18601;1,8862;5,149;-3,48922;1492,47
113,38601;1,8898;5,149;-3,48922;1492,52
113,58601;1,8930;5,149;-3,48919;1492,55
113,78601;1,8962;5,149;-3,48921;1492,55
113,98601;1,8997;5,149;-3,48933;1492,58
114,18601;1,9031;5,150;-3,48932;1492,76
114,38601;1,9064;5,151;-3,48904;1492,90
114,58601;1,9096;5,152;-3,48960;1493,47
114,78601;1,9131;5,158;-3,48925;1494,93
114,98601;1,9163;5,166;-3,48943;1497,50
115,18601;1,9195;5,175;-3,48941;1500,05
115,38601;1,9232;5,188;-3,48944;1503,84
115,58601;1,9264;5,200;-3,48918;1507,37
115,78601;1,9296;5,214;-3,48945;1511,32
115,98601;1,9331;5,229;-3,48929;1515,53
116,18601;1,9364;5,241;-3,48936;1519,05
116,38601;1,9396;5,252;-3,48939;1522,22
116,58601;1,9430;5,264;-3,48937;1525,71
116,78601;1,9464;5,275;-3,48957;1529,03
116,98601;1,9497;5,287;-3,48940;1532,58
117,18601;1,9529;5,296;-3,48960;1535,10
117,38601;1,9565;5,311;-3,48949;1539,41
117,58601;1,9598;5,320;-3,48967;1542,05
117,78601;1,9629;5,328;-3,48932;1544,38
117,98601;1,9665;5,338;-3,48957;1547,13
118,18601;1,9697;5,348;-3,48933;1550,02
118,38601;1,9729;5,359;-3,48926;1553,35
118,58601;1,9765;5,374;-3,48929;1557,59
118,78601;1,9797;5,390;-3,48904;1562,35
118,98601;1,9829;5,406;-3,48936;1566,95
119,18601;1,9864;5,421;-3,48950;1571,26
119,38601;1,9897;5,433;-3,48956;1574,84
119,58601;1,9930;5,441;-3,48931;1577,22
119,78601;1,9963;5,447;-3,48963;1578,87
119,98601;1,9998;5,454;-3,48946;1580,78
120,18601;2,0030;5,458;-3,48955;1582,07
120,38601;2,0062;5,461;-3,48958;1582,96
120,58601;2,0098;5,469;-3,48946;1585,17
120,78601;2,0130;5,473;-3,48946;1586,40
120,98601;2,0162;5,478;-3,48953;1587,88
121,18601;2,0199;5,488;-3,48960;1590,65
121,38601;2,0231;5,497;-3,48956;1593,21
121,58601;2,0263;5,503;-3,48965;1595,19
121,78601;2,0298;5,511;-3,48958;1597,37
121,98601;2,0331;5,517;-3,48958;1599,11
122,18601;2,0363;5,525;-3,48968;1601,31
122,38601;2,0396;5,529;-3,48961;1602,74
122,58601;2,0431;5,536;-3,48957;1604,55
122,78601;2,0464;5,546;-3,48996;1607,53
122,98601;2,0496;5,555;-3,48949;1610,10
123,18601;2,0532;5,568;-3,48954;1613,86
123,38601;2,0564;5,576;-3,48968;1616,25
123,58601;2,0595;5,586;-3,48961;1619,01
123,78601;2,0632;5,592;-3,48972;1620,81
123,98601;2,0664;5,595;-3,48975;1621,82
124,18601;2,0695;5,597;-3,48949;1622,18
124,38601;2,0732;5,600;-3,48977;1623,15
124,58601;2,0763;5,602;-3,48986;1623,80
124,78601;2,0796;5,609;-3,48943;1625,74
124,98601;2,0830;5,621;-3,48969;1629,14
125,18601;2,0864;5,636;-3,48946;1633,71
125,38601;2,0896;5,651;-3,48962;1637,87
125,58601;2,0930;5,661;-3,48969;1640,74
125,78601;2,0964;5,670;-3,48972;1643,35
125,98601;2,0997;5,678;-3,48957;1645,88
126,18601;2,1029;5,686;-3,48969;1648,10
126,38601;2,1065;5,697;-3,48977;1651,30
126,58601;2,1097;5,704;-3,48972;1653,25
126,78601;2,1129;5,712;-3,48963;1655,52
126,98601;2,1165;5,723;-3,48974;1658,98
127,18601;2,1197;5,734;-3,48967;1662,15
127,38601;2,1230;5,745;-3,48963;1665,23
127,58601;2,1264;5,759;-3,48996;1669,26
127,78601;2,1297;5,766;-3,48958;1671,26
127,98601;2,1329;5,775;-3,48978;1673,90
128,18601;2,1364;5,780;-3,48968;1675,42
128,38601;2,1398;5,784;-3,48977;1676,42
128,58601;2,1430;5,789;-3,48977;1677,84
128,78601;2,1463;5,791;-3,48990;1678,64
128,98601;2,1498;5,799;-3,48985;1680,73
129,18601;2,1530;5,811;-3,48998;1684,37
129,38601;2,1562;5,821;-3,49012;1687,27
129,58601;2,1598;5,835;-3,48978;1691,34
129,78601;2,1631;5,852;-3,49017;1696,16
129,98601;2,1662;5,867;-3,48990;1700,52
130,18601;2,1698;5,887;-3,49011;1706,37
130,38601;2,1730;5,896;-3,48998;1709,07
130,58601;2,1763;5,909;-3,49032;1712,77
130,78601;2,1798;5,924;-3,49031;1717,05
130,98601;2,1831;5,936;-3,49001;1720,59
131,18601;2,1864;5,950;-3,49006;1724,51
131,38601;2,1896;5,960;-3,49004;1727,53
131,58601;2,1931;5,971;-3,48982;1730,68
131,78601;2,1964;5,981;-3,48982;1733,63
131,98601;2,1996;5,987;-3,48997;1735,29
132,18601;2,2032;5,995;-3,48975;1737,65
132,38601;2,2064;6,001;-3,48979;1739,36
132,58601;2,2096;6,007;-3,48983;1741,08
132,78601;2,2132;6,015;-3,48992;1743,39
132,98601;2,2164;6,021;-3,48960;1745,21
133,18601;2,2195;6,029;-3,48978;1747,46
133,38601;2,2231;6,037;-3,48979;1749,86
133,58601;2,2264;6,045;-3,48957;1752,04
133,78601;2,2296;6,050;-3,48991;1753,62
133,98601;2,2331;6,051;-3,48988;1753,82
134,18601;2,2364;6,053;-3,48954;1754,57
134,38601;2,2396;6,054;-3,48989;1754,68
134,58601;2,2429;6,055;-3,48983;1754,95
134,78601;2,2464;6,056;-3,48959;1755,29
134,98601;2,2497;6,058;-3,48986;1755,83
135,18601;2,2529;6,060;-3,48984;1756,52
135,38601;2,2565;6,062;-3,48972;1757,13
135,58601;2,2597;6,068;-3,48983;1758,95
135,78601;2,2629;6,074;-3,48989;1760,52
135,98601;2,2665;6,084;-3,48975;1763,55
136,18601;2,2698;6,094;-3,49000;1766,28
136,38601;2,2729;6,102;-3,48970;1768,67
136,58601;2,2764;6,114;-3,48975;1772,04
136,78601;2,2797;6,122;-3,48997;1774,38
136,98601;2,2831;6,133;-3,48994;1777,63
137,18601;2,2863;6,142;-3,48974;1780,34
137,38601;2,2898;6,153;-3,49000;1783,36
137,58601;2,2930;6,173;-3,48985;1789,27
137,78601;2,2961;6,184;-3,48964;1792,53
137,98601;2,2998;6,198;-3,49023;1796,47
138,18601;2,3030;6,210;-3,48978;1800,14
138,38601;2,3062;6,216;-3,48962;1801,73
138,58601;2,3099;6,228;-3,49013;1805,10
138,78601;2,3130;6,236;-3,48970;1807,58
138,98601;2,3162;6,246;-3,48961;1810,43
139,18601;2,3198;6,265;-3,49011;1816,05
139,38601;2,3230;6,281;-3,48984;1820,47
139,58601;2,3263;6,298;-3,48968;1825,48
139,78601;2,3296;6,310;-3,49010;1829,11
139,98601;2,3331;6,328;-3,48969;1834,08
140,18601;2,3364;6,337;-3,49002;1836,84
140,38601;2,3396;6,343;-3,48983;1838,63
140,58601;2,3432;6,350;-3,49004;1840,57
140,78601;2,3464;6,356;-3,48982;1842,34
140,98601;2,3495;6,362;-3,48987;1844,19
141,18601;2,3532;6,371;-3,48992;1846,54
141,38601;2,3564;6,377;-3,49004;1848,48
141,58601;2,3595;6,385;-3,49007;1850,65
141,78601;2,3631;6,392;-3,48995;1852,81
141,98601;2,3664;6,400;-3,49013;1855,14
142,18601;2,3696;6,406;-3,48991;1856,74
142,38601;2,3730;6,411;-3,48998;1858,23
142,58601;2,3764;6,417;-3,48986;1859,87
142,78601;2,3797;6,420;-3,48989;1860,73
142,98601;2,3830;6,423;-3,48992;1861,66
143,18601;2,3865;6,427;-3,49012;1862,80
143,38601;2,3897;6,433;-3,48996;1864,62
143,58601;2,3929;6,437;-3,48989;1865,93
143,78601;2,3965;6,445;-3,49000;1868,24
143,98601;2,3997;6,454;-3,48993;1870,85
144,18601;2,4029;6,460;-3,48989;1872,57
144,38601;2,4065;6,467;-3,49010;1874,43
144,58601;2,4097;6,470;-3,49003;1875,36
144,78601;2,4130;6,474;-3,49000;1876,50
144,98601;2,4164;6,478;-3,49024;1877,81
145,18601;2,4198;6,484;-3,49008;1879,50
145,38601;2,4230;6,490;-3,48999;1881,14
145,58601;2,4263;6,499;-3,49004;1883,74
145,78601;2,4298;6,507;-3,48998;1886,18
145,98601;2,4331;6,520;-3,48992;1889,79
146,18601;2,4363;6,528;-3,49022;1892,29
146,38601;2,4398;6,538;-3,48992;1895,01
146,58601;2,4430;6,544;-3,49010;1896,79
146,78601;2,4462;6,552;-3,49011;1899,03
146,98601;2,4498;6,561;-3,49000;1901,82
147,18601;2,4531;6,571;-3,49003;1904,60
147,38601;2,4563;6,583;-3,48997;1908,11
147,58601;2,4598;6,600;-3,49003;1912,90
147,78601;2,4630;6,612;-3,49014;1916,49
147,98601;2,4662;6,628;-3,49010;1921,01
148,18601;2,4697;6,647;-3,48997;1926,80
148,38601;2,4731;6,659;-3,49027;1930,19
148,58601;2,4763;6,672;-3,48993;1933,90
148,78601;2,4796;6,677;-3,49011;1935,47
148,98601;2,4831;6,683;-3,49015;1937,18
149,18601;2,4864;6,686;-3,48997;1937,97
149,38601;2,4895;6,689;-3,49000;1938,92
149,58601;2,4931;6,692;-3,49021;1939,75
149,78601;2,4964;6,697;-3,49001;1941,29
149,98601;2,4996;6,703;-3,49005;1942,81
150,18601;2,5032;6,710;-3,49042;1944,82
150,38601;2,5065;6,719;-3,48975;1947,60
150,58601;2,5096;6,732;-3,49022;1951,41
150,78601;2,5130;6,740;-3,49024;1953,68
150,98601;2,5164;6,753;-3,49009;1957,43
151,18601;2,5197;6,763;-3,48999;1960,35
151,38601;2,5230;6,774;-3,49034;1963,40
151,58601;2,5265;6,783;-3,48998;1966,23
151,78601;2,5297;6,794;-3,49001;1969,38
151,98601;2,5329;6,805;-3,49039;1972,44
152,18601;2,5365;6,821;-3,49002;1976,97
152,38601;2,5397;6,835;-3,49008;1981,28
152,58601;2,5429;6,849;-3,49010;1985,19
152,78601;2,5465;6,858;-3,49023;1987,71
152,98601;2,5497;6,863;-3,49001;1989,39
153,18601;2,5529;6,868;-3,49019;1990,71
153,38601;2,5565;6,871;-3,49017;1991,67
153,58601;2,5597;6,876;-3,49001;1992,95
153,78601;2,5629;6,879;-3,49010;1993,92
153,98601;2,5663;6,888;-3,49025;1996,55
154,18601;2,5698;6,900;-3,49018;1999,94
154,38601;2,5731;6,910;-3,49014;2002,78
154,58601;2,5762;6,918;-3,49029;2005,11
154,78601;2,5798;6,930;-3,49004;2008,66
154,98601;2,5830;6,934;-3,49028;2009,83
155,18601;2,5862;6,938;-3,49029;2011,00
155,38601;2,5899;6,943;-3,49012;2012,50
155,58601;2,5931;6,948;-3,49016;2013,79
155,78601;2,5962;6,954;-3,49039;2015,73
155,98601;2,5998;6,958;-3,49013;2016,87
156,18601;2,6030;6,964;-3,49006;2018,53
156,38601;2,6063;6,970;-3,49030;2020,34
156,58601;2,6097;6,976;-3,49007;2021,94
156,78601;2,6131;6,980;-3,49023;2023,28
156,98601;2,6164;6,986;-3,49044;2024,78
157,18601;2,6196;6,991;-3,49015;2026,43
157,38601;2,6231;6,996;-3,49022;2027,93
157,58601;2,6264;7,000;-3,49048;2028,87
157,78601;2,6295;7,007;-3,49035;2030,90
157,98601;2,6331;7,013;-3,49008;2032,80
158,18601;2,6363;7,022;-3,49011;2035,42
158,38601;2,6396;7,030;-3,49033;2037,69
158,58601;2,6431;7,040;-3,48997;2040,57
158,78601;2,6464;7,055;-3,49045;2044,79
158,98601;2,6496;7,066;-3,49039;2048,14
159,18601;2,6531;7,076;-3,49011;2051,12
159,38601;2,6564;7,086;-3,49027;2054,01
159,58601;2,6596;7,096;-3,49046;2056,79
159,78601;2,6630;7,102;-3,49011;2058,68
159,98601;2,6665;7,112;-3,49012;2061,43
160,18601;2,6697;7,124;-3,49057;2065,07
160,38601;2,6730;7,137;-3,49030;2068,56
160,58601;2,6765;7,148;-3,49024;2072,01
160,78601;2,6797;7,163;-3,49034;2076,17
160,98601;2,6828;7,175;-3,49038;2079,59
161,18601;2,6865;7,185;-3,48997;2082,47
161,38601;2,6897;7,196;-3,49049;2085,89
161,58601;2,6929;7,204;-3,49005;2088,21
161,78601;2,6964;7,212;-3,49012;2090,43
161,98601;2,6997;7,220;-3,49060;2092,70
162,18601;2,7029;7,225;-3,49023;2094,34
162,38601;2,7063;7,234;-3,49025;2096,92
162,58601;2,7097;7,242;-3,49052;2099,26
162,78601;2,7130;7,255;-3,49009;2102,91
162,98601;2,7162;7,268;-3,49002;2106,70
163,18601;2,7198;7,280;-3,49076;2110,29
163,38601;2,7230;7,291;-3,49004;2113,22
163,58601;2,7262;7,299;-3,49034;2115,77
163,78601;2,7298;7,306;-3,49045;2117,72
163,98601;2,7331;7,313;-3,49031;2119,64
164,18601;2,7363;7,316;-3,49039;2120,56
164,38601;2,7398;7,318;-3,49010;2121,15
164,58601;2,7431;7,321;-3,49034;2121,98
164,78601;2,7464;7,322;-3,49007;2122,18
164,98601;2,7497;7,323;-3,49018;2122,52
165,18601;2,7531;7,323;-3,49034;2122,68
165,38601;2,7563;7,324;-3,49028;2123,04
165,58601;2,7597;7,326;-3,49038;2123,45
165,78601;2,7632;7,328;-3,49051;2124,06
165,98601;2,7664;7,332;-3,49026;2125,13
166,18601;2,7695;7,335;-3,49049;2126,21
166,38601;2,7732;7,340;-3,49050;2127,62
166,58601;2,7764;7,344;-3,49034;2128,62
166,78601;2,7795;7,348;-3,49052;2129,80
166,98601;2,7832;7,356;-3,49045;2132,04
167,18601;2,7864;7,363;-3,49058;2134,31
167,38601;2,7896;7,377;-3,49038;2138,25
167,58601;2,7931;7,387;-3,49049;2141,22
167,78601;2,7964;7,399;-3,49039;2144,61
167,98601;2,7996;7,411;-3,49008;2148,09
168,18601;2,8029;7,423;-3,49037;2151,66
168,38601;2,8064;7,431;-3,49027;2154,01
168,58601;2,8097;7,437;-3,49028;2155,78
168,78601;2,8129;7,444;-3,49039;2157,60
168,98601;2,8165;7,454;-3,49043;2160,67
169,18601;2,8197;7,472;-3,49038;2165,93
169,38601;2,8229;7,482;-3,49037;2168,76
169,58601;2,8265;7,502;-3,49054;2174,57
169,78601;2,8298;7,520;-3,49044;2179,80
169,98601;2,8329;7,532;-3,49065;2183,26
170,18601;2,8365;7,548;-3,49069;2187,71
170,38601;2,8397;7,560;-3,49041;2191,44
170,58601;2,8429;7,567;-3,49046;2193,42
170,78601;2,8464;7,578;-3,49056;2196,44
170,98601;2,8497;7,586;-3,49045;2198,77
171,18601;2,8529;7,594;-3,49013;2201,14
171,38601;2,8563;7,601;-3,49051;2203,21
171,58601;2,8598;7,610;-3,49042;2205,92
171,78601;2,8631;7,616;-3,49042;2207,66
171,98601;2,8662;7,623;-3,49084;2209,42
172,18601;2,8698;7,629;-3,49077;2211,29
172,38601;2,8730;7,634;-3,49057;2212,87
172,58601;2,8762;7,639;-3,49087;2214,11
172,78601;2,8798;7,646;-3,49058;2216,33
172,98601;2,8831;7,653;-3,49017;2218,35
173,18601;2,8862;7,659;-3,49090;2220,13
173,38601;2,8898;7,669;-3,49008;2222,81
173,58601;2,8931;7,675;-3,49060;2224,67
173,78601;2,8963;7,684;-3,49078;2227,18
173,98601;2,8996;7,696;-3,49039;2230,87
174,18601;2,9031;7,705;-3,49058;2233,32
174,38601;2,9064;7,713;-3,49071;2235,53
174,58601;2,9096;7,721;-3,49028;2237,92
174,78601;2,9131;7,728;-3,49063;2239,90
174,98601;2,9164;7,734;-3,49100;2241,78
175,18601;2,9195;7,737;-3,49036;2242,56
175,38601;2,9232;7,741;-3,49100;2243,68
175,58601;2,9264;7,744;-3,49074;2244,54
175,78601;2,9295;7,750;-3,49061;2246,26
175,98601;2,9331;7,755;-3,49077;2247,96
176,18601;2,9364;7,739;-3,49080;2243,24
176,38601;2,9396;7,744;-3,49047;2244,51
176,58601;2,9431;7,749;-3,49077;2245,98
176,78601;2,9464;7,756;-3,49078;2248,01
176,98601;2,9496;7,761;-3,49047;2249,61
177,18601;2,9529;7,769;-3,49089;2251,81
177,38601;2,9564;7,777;-3,49063;2254,12
177,58601;2,9597;7,784;-3,49067;2256,34
177,78601;2,9629;7,792;-3,49067;2258,69
177,98601;2,9665;7,802;-3,49062;2261,32
178,18601;2,9697;7,807;-3,49038;2262,89
178,38601;2,9729;7,814;-3,49064;2264,92
178,58601;2,9765;7,822;-3,49037;2267,33
178,78601;2,9798;7,829;-3,49046;2269,40
178,98601;2,9830;7,835;-3,49033;2271,01
179,18601;2,9864;7,840;-3,49054;2272,57
179,38601;2,9897;7,847;-3,49064;2274,55
179,58601;2,9929;7,856;-3,49010;2277,00
179,78601;2,9963;7,865;-3,49072;2279,81
179,98601;2,9998;7,876;-3,49032;2282,80
180,18601;3,0031;7,882;-3,49016;2284,60
180,38601;3,0062;7,893;-3,49050;2287,83
180,58601;3,0099;7,900;-3,49012;2289,78
180,78601;3,0130;7,907;-3,49024;2291,77
180,98601;3,0162;7,911;-3,49054;2292,98
181,18601;3,0198;7,920;-3,49042;2295,66
181,38601;3,0230;7,924;-3,49039;2296,95
181,58601;3,0262;7,930;-3,49059;2298,62
181,78601;3,0298;7,935;-3,49050;2299,94
181,98601;3,0330;7,940;-3,49028;2301,35
182,18601;3,0363;7,946;-3,49067;2303,18
182,38601;3,0396;7,952;-3,49042;2304,98
182,58601;3,0431;7,958;-3,49034;2306,60
182,78601;3,0464;7,967;-3,49078;2309,17
182,98601;3,0496;7,973;-3,49040;2310,97
183,18601;3,0532;7,982;-3,49052;2313,77
183,38601;3,0564;7,991;-3,49067;2316,30
183,58601;3,0595;7,998;-3,49065;2318,27
183,78601;3,0632;8,009;-3,49043;2321,52
183,98601;3,0664;8,019;-3,49056;2324,23
184,18601;3,0695;8,030;-3,49043;2327,59
184,38601;3,0731;8,043;-3,49040;2331,32
184,58601;3,0764;8,056;-3,49033;2335,17
184,78601;3,0797;8,069;-3,49078;2338,93
184,98601;3,0830;8,079;-3,49034;2341,88
185,18601;3,0864;8,086;-3,49051;2343,78
185,38601;3,0896;8,091;-3,49071;2345,23
185,58601;3,0929;8,098;-3,49043;2347,30
185,78601;3,0965;8,108;-3,49081;2350,22
185,98601;3,0997;8,116;-3,49045;2352,35
186,18601;3,1029;8,123;-3,49061;2354,37
186,38601;3,1065;8,137;-3,49055;2358,60
186,58601;3,1097;8,153;-3,49063;2363,33
186,78601;3,1129;8,161;-3,49050;2365,43
186,98601;3,1165;8,173;-3,49078;2369,03
187,18601;3,1197;8,183;-3,49059;2371,96
187,38601;3,1230;8,189;-3,49061;2373,76
187,58601;3,1264;8,193;-3,49068;2374,91
187,78601;3,1298;8,203;-3,49040;2377,62
187,98601;3,1330;8,206;-3,49077;2378,63
188,18601;3,1363;8,212;-3,49050;2380,26
188,38601;3,1398;8,216;-3,49062;2381,38
188,58601;3,1430;8,219;-3,49058;2382,35
188,78601;3,1462;8,222;-3,49067;2383,17
188,98601;3,1498;8,225;-3,49053;2383,98
189,18601;3,1531;8,226;-3,49072;2384,31
189,38601;3,1562;8,227;-3,49068;2384,72
189,58601;3,1598;8,229;-3,49075;2385,20
189,78601;3,1630;8,230;-3,49063;2385,63
189,98601;3,1662;8,232;-3,49060;2386,07
190,18601;3,1698;8,234;-3,49081;2386,62
190,38601;3,1730;8,237;-3,49052;2387,59
190,58601;3,1762;8,239;-3,49069;2388,01
190,78601;3,1797;8,244;-3,49059;2389,69
190,98601;3,1830;8,251;-3,49071;2391,69
191,18601;3,1863;8,256;-3,49062;2393,03
191,38601;3,1896;8,262;-3,49077;2394,79
191,58601;3,1931;8,272;-3,49057;2397,54
191,78601;3,1964;8,280;-3,49054;2400,14
191,98601;3,1996;8,287;-3,49066;2402,00
192,18601;3,2031;8,296;-3,49050;2404,59
192,38601;3,2064;8,302;-3,49070;2406,42
192,58601;3,2095;8,306;-3,49070;2407,52
192,78601;3,2132;8,313;-3,49060;2409,60
192,98601;3,2164;8,319;-3,49063;2411,42
193,18601;3,2196;8,326;-3,49071;2413,38
193,38601;3,2230;8,335;-3,49050;2415,83
193,58601;3,2265;8,342;-3,49079;2417,90
193,78601;3,2296;8,347;-3,49066;2419,53
193,98601;3,2330;8,358;-3,49060;2422,62
194,18601;3,2364;8,368;-3,49069;2425,62
194,38601;3,2397;8,377;-3,49061;2428,24
194,58601;3,2429;8,382;-3,49061;2429,68
194,78601;3,2465;8,394;-3,49069;2433,03
194,98601;3,2497;8,404;-3,49057;2436,03
195,18601;3,2528;8,417;-3,49067;2439,76
195,38601;3,2564;8,424;-3,49071;2441,86
195,58601;3,2597;8,439;-3,49068;2446,07
195,78601;3,2629;8,448;-3,49077;2448,64
195,98601;3,2665;8,456;-3,49057;2451,15
196,18601;3,2697;8,466;-3,49074;2453,94
196,38601;3,2730;8,472;-3,49057;2455,69
196,58601;3,2763;8,477;-3,49065;2457,16
196,78601;3,2798;8,483;-3,49054;2458,95
196,98601;3,2830;8,488;-3,49065;2460,38
197,18601;3,2863;8,494;-3,49055;2461,95
197,38601;3,2898;8,503;-3,49061;2464,54
197,58601;3,2931;8,512;-3,49056;2467,30
197,78601;3,2962;8,517;-3,49056;2468,71
197,87801;3,2981;7,414;-3,48970;2148,91
197,88201;3,2982;6,538;-3,48852;1895,18