File: Klausurvorbereitung/Übungen/UE5_Specimen_RawData_5.csv
Texteingaben : Proben-beschriftung;"dpp-PUL6-5"
Allgemein : Startdatum;16.08.2018 16:37:44
Abmessung : Querschnitt;3,45000;mm^2

Zeit;Traversenweg;Last;Dehnung 1;Zugspannung
(sec);(mm);(kN);(%);(MPa)
0,00000;0,0001;0,057;0,00606;16,50
0,20000;0,0027;0,065;0,00717;18,92
0,40000;0,0064;0,079;0,00979;23,01
0,60000;0,0101;0,097;0,01213;28,22
0,80000;0,0133;0,122;0,01434;35,27
1,00000;0,0165;0,142;0,01648;41,08
1,20000;0,0201;0,162;0,01881;47,07
1,40000;0,0234;0,174;0,02098;50,51
1,60000;0,0265;0,186;0,02311;53,98
1,80000;0,0300;0,195;0,02543;56,45
2,00000;0,0333;0,199;0,02776;57,80
2,20000;0,0366;0,204;0,02996;59,12
2,40000;0,0399;0,207;0,03202;60,09
2,60000;0,0434;0,210;0,03433;60,88
2,80000;0,0467;0,214;0,03653;61,93
3,00000;0,0498;0,215;0,03864;62,34
3,20000;0,0535;0,217;0,04095;62,97
3,40000;0,0567;0,221;0,04303;64,03
3,60000;0,0598;0,223;0,04513;64,68
3,80000;0,0635;0,228;0,04750;66,08
4,00000;0,0667;0,234;0,04949;67,85
4,20000;0,0699;0,239;0,05157;69,32
4,40000;0,0734;0,254;0,05375;73,71
4,60000;0,0767;0,271;0,05598;78,66
4,80000;0,0800;0,286;0,05803;82,92
5,00000;0,0833;0,302;0,06018;87,48
5,20000;0,0867;0,315;0,06246;91,26
5,40000;0,0901;0,324;0,06462;94,06
5,60000;0,0933;0,332;0,06666;96,29
5,80000;0,0969;0,344;0,06900;99,60
6,00000;0,1000;0,353;0,07103;102,38
6,20000;0,1031;0,361;0,07307;104,50
6,40000;0,1068;0,373;0,07536;108,03
6,60000;0,1100;0,383;0,07746;111,07
6,80000;0,1132;0,393;0,07956;113,81
7,00000;0,1167;0,404;0,08170;117,24
7,20000;0,1200;0,421;0,08381;121,99
7,40000;0,1232;0,434;0,08593;125,88
7,60000;0,1267;0,447;0,08799;129,70
7,80000;0,1300;0,457;0,09018;132,33
8,00000;0,1333;0,465;0,09231;134,87
8,20000;0,1366;0,470;0,09431;136,23
8,40000;0,1401;0,476;0,09650;138,04
8,60000;0,1433;0,478;0,09863;138,68
8,80000;0,1465;0,482;0,10049;139,76
9,00000;0,1501;0,487;0,10286;141,05
9,20000;0,1534;0,490;0,10481;141,95
9,40000;0,1565;0,493;0,10682;142,90
9,60000;0,1602;0,498;0,10900;144,28
9,80000;0,1634;0,506;0,11107;146,66
10,00000;0,1666;0,515;0,11315;149,31
10,20000;0,1700;0,524;0,11522;152,00
10,40000;0,1734;0,539;0,11728;156,21
10,60000;0,1766;0,546;0,11930;158,36
10,80000;0,1800;0,562;0,12137;162,81
11,00000;0,1834;0,582;0,12361;168,66
11,20000;0,1867;0,597;0,12560;173,00
11,40000;0,1899;0,615;0,12753;178,21
11,60000;0,1934;0,628;0,12985;181,90
11,80000;0,1967;0,634;0,13182;183,90
12,00000;0,1998;0,644;0,13374;186,67
12,20000;0,2034;0,654;0,13594;189,59
12,40000;0,2067;0,662;0,13796;191,87
12,60000;0,2099;0,669;0,13996;193,89
12,80000;0,2134;0,678;0,14205;196,58
13,00000;0,2167;0,687;0,14408;199,27
13,20000;0,2199;0,694;0,14593;201,14
13,40000;0,2234;0,704;0,14803;204,04
13,60000;0,2268;0,714;0,15019;206,85
13,80000;0,2300;0,733;0,15211;212,43
14,00000;0,2333;0,747;0,15403;216,64
14,20000;0,2368;0,762;0,15621;220,83
14,40000;0,2401;0,777;0,15819;225,15
14,60000;0,2432;0,785;0,16000;227,63
14,80000;0,2468;0,790;0,16216;228,85
15,00000;0,2500;0,792;0,16409;229,65
15,20000;0,2532;0,796;0,16594;230,64
15,40000;0,2568;0,797;0,16809;231,13
15,60000;0,2601;0,801;0,17008;232,25
15,80000;0,2632;0,806;0,17189;233,70
16,00000;0,2667;0,811;0,17396;234,97
16,20000;0,2700;0,814;0,17596;236,06
16,40000;0,2732;0,821;0,17797;238,04
16,60000;0,2767;0,826;0,17987;239,35
16,80000;0,2801;0,831;0,18186;240,75
17,00000;0,2833;0,836;0,18386;242,39
17,20000;0,2866;0,839;0,18577;243,26
17,40000;0,2901;0,849;0,18788;246,22
17,60000;0,2933;0,862;0,18985;249,85
17,80000;0,2965;0,873;0,19164;253,04
18,00000;0,3001;0,887;0,19378;257,12
18,20000;0,3034;0,899;0,19562;260,61
18,40000;0,3065;0,910;0,19752;263,67
18,60000;0,3102;0,920;0,19956;266,73
18,80000;0,3134;0,932;0,20152;270,23
19,00000;0,3165;0,942;0,20340;273,16
19,20000;0,3200;0,957;0,20534;277,37
19,40000;0,3234;0,970;0,20736;281,27
19,60000;0,3267;0,986;0,20922;285,80
19,80000;0,3300;0,998;0,21111;289,42
20,00000;0,3335;1,013;0,21314;293,58
20,20000;0,3367;1,029;0,21496;298,18
20,40000;0,3398;1,044;0,21671;302,75
20,60000;0,3435;1,061;0,21890;307,62
20,80000;0,3466;1,082;0,22073;313,51
21,00000;0,3498;1,094;0,22254;317,07
21,20000;0,3535;1,104;0,22471;320,07
21,40000;0,3566;1,110;0,22658;321,78
21,60000;0,3599;1,115;0,22840;323,16
21,80000;0,3634;1,120;0,23031;324,63
22,00000;0,3667;1,123;0,23221;325,64
22,20000;0,3699;1,126;0,23410;326,41
22,40000;0,3733;1,129;0,23610;327,12
22,60000;0,3767;1,131;0,23806;327,91
22,80000;0,3800;1,136;0,23995;329,40
23,00000;0,3833;1,139;0,24173;330,26
23,20000;0,3868;1,146;0,24379;332,12
23,40000;0,3900;1,152;0,24564;333,80
23,60000;0,3932;1,156;0,24747;335,07
23,80000;0,3969;1,165;0,24952;337,75
24,00000;0,4001;1,173;0,25130;339,94
24,20000;0,4032;1,180;0,25308;342,04
24,40000;0,4068;1,193;0,25506;345,94
24,60000;0,4100;1,206;0,25689;349,43
24,80000;0,4132;1,218;0,25869;352,95
25,00000;0,4167;1,229;0,26064;356,33
25,20000;0,4200;1,240;0,26254;359,55
25,40000;0,4233;1,251;0,26433;362,51
25,60000;0,4267;1,260;0,26615;365,23
25,80000;0,4301;1,270;0,26814;368,19
26,00000;0,4333;1,280;0,26993;371,05
26,20000;0,4365;1,288;0,27165;373,21
26,40000;0,4401;1,299;0,27374;376,40
26,60000;0,4433;1,305;0,27549;378,37
26,80000;0,4466;1,316;0,27718;381,34
27,00000;0,4501;1,331;0,27927;385,83
27,20000;0,4534;1,342;0,28101;388,88
27,40000;0,4566;1,356;0,28282;392,93
27,60000;0,4601;1,368;0,28475;396,39
27,80000;0,4634;1,377;0,28661;399,07
28,00000;0,4666;1,385;0,28841;401,53
28,20000;0,4700;1,391;0,29029;403,19
28,40000;0,4734;1,399;0,29218;405,52
28,60000;0,4767;1,407;0,29395;407,91
28,80000;0,4800;1,415;0,29575;410,26
29,00000;0,4834;1,424;0,29760;412,85
29,20000;0,4867;1,433;0,29943;415,30
29,40000;0,4898;1,443;0,30111;418,24
29,60000;0,4934;1,452;0,30309;420,92
29,80000;0,4967;1,460;0,30483;423,28
30,00000;0,4999;1,467;0,30661;425,34
30,20000;0,5035;1,476;0,30848;427,69
30,40000;0,5067;1,482;0,31022;429,56
30,60000;0,5099;1,489;0,31193;431,70
30,80000;0,5134;1,499;0,31381;434,46
31,00000;0,5167;1,513;0,31565;438,68
31,20000;0,5199;1,527;0,31735;442,68
31,40000;0,5234;1,540;0,31918;446,32
31,60000;0,5267;1,550;0,32093;449,40
31,80000;0,5300;1,559;0,32273;451,84
32,00000;0,5332;1,567;0,32441;454,08
32,20000;0,5368;1,580;0,32630;457,92
32,40000;0,5400;1,592;0,32807;461,44
32,60000;0,5432;1,600;0,32976;463,63
32,80000;0,5468;1,615;0,33159;468,00
33,00000;0,5501;1,622;0,33326;470,27
33,20000;0,5531;1,633;0,33496;473,27
33,40000;0,5568;1,639;0,33685;475,17
33,60000;0,5600;1,647;0,33856;477,27
33,80000;0,5632;1,658;0,34016;480,57
34,00000;0,5667;1,672;0,34196;484,50
34,20000;0,5701;1,682;0,34388;487,66
34,40000;0,5733;1,692;0,34558;490,55
34,60000;0,5766;1,700;0,34721;492,89
34,80000;0,5800;1,705;0,34906;494,25
35,00000;0,5833;1,710;0,35080;495,72
35,20000;0,5865;1,716;0,35243;497,50
35,40000;0,5902;1,723;0,35431;499,52
35,60000;0,5933;1,727;0,35590;500,72
35,80000;0,5965;1,732;0,35754;501,96
36,00000;0,6001;1,735;0,35945;502,84
36,20000;0,6034;1,738;0,36110;503,66
36,40000;0,6065;1,740;0,36279;504,38
36,60000;0,6101;1,744;0,36460;505,38
36,80000;0,6134;1,747;0,36630;506,45
37,00000;0,6167;1,753;0,36801;508,10
37,20000;0,6200;1,760;0,36970;510,19
37,40000;0,6234;1,772;0,37138;513,60
37,60000;0,6266;1,785;0,37301;517,47
37,80000;0,6299;1,804;0,37475;522,93
38,00000;0,6335;1,824;0,37669;528,71
38,20000;0,6367;1,839;0,37827;532,99
38,40000;0,6398;1,856;0,37980;538,02
38,60000;0,6436;1,869;0,38170;541,69
38,80000;0,6466;1,882;0,38328;545,47
39,00000;0,6498;1,892;0,38494;548,48
39,20000;0,6534;1,904;0,38673;551,84
39,40000;0,6567;1,915;0,38843;555,21
39,60000;0,6599;1,929;0,39003;559,08
39,80000;0,6634;1,939;0,39184;562,15
40,00000;0,6667;1,952;0,39350;565,79
40,20000;0,6700;1,965;0,39520;569,54
40,40000;0,6733;1,979;0,39677;573,65
40,60000;0,6767;1,997;0,39861;578,75
40,80000;0,6800;2,008;0,40017;582,02
41,00000;0,6832;2,018;0,40176;584,95
41,20000;0,6868;2,025;0,40365;586,92
41,40000;0,6900;2,031;0,40527;588,77
41,60000;0,6932;2,036;0,40680;590,26
41,80000;0,6968;2,041;0,40866;591,66
42,00000;0,7000;2,048;0,41015;593,51
42,20000;0,7032;2,051;0,41182;594,55
42,40000;0,7068;2,057;0,41356;596,25
42,60000;0,7100;2,060;0,41523;596,97
42,80000;0,7133;2,063;0,41687;597,94
43,00000;0,7167;2,064;0,41841;598,40
43,20000;0,7201;2,065;0,42026;598,59
43,40000;0,7233;2,066;0,42179;598,89
43,60000;0,7265;2,068;0,42342;599,52
43,80000;0,7301;2,072;0,42528;600,57
44,00000;0,7334;2,078;0,42690;602,35
44,20000;0,7365;2,089;0,42849;605,53
44,40000;0,7401;2,102;0,43024;609,40
44,60000;0,7433;2,116;0,43186;613,47
44,80000;0,7465;2,127;0,43340;616,44
45,00000;0,7501;2,142;0,43527;620,90
45,20000;0,7533;2,152;0,43696;623,90
45,40000;0,7566;2,162;0,43850;626,62
45,60000;0,7601;2,174;0,44020;630,14
45,80000;0,7634;2,183;0,44187;632,64
46,00000;0,7667;2,194;0,44347;635,90
46,20000;0,7699;2,205;0,44497;639,11
46,40000;0,7734;2,215;0,44671;641,88
46,60000;0,7767;2,223;0,44825;644,43
46,80000;0,7799;2,231;0,44989;646,62
47,00000;0,7835;2,245;0,45165;650,62
47,20000;0,7867;2,257;0,45312;654,16
47,40000;0,7899;2,273;0,45465;658,94
47,60000;0,7935;2,292;0,45646;664,21
47,80000;0,7967;2,308;0,45801;669,08
48,00000;0,7998;2,321;0,45962;672,79
48,20000;0,8034;2,335;0,46128;676,87
48,40000;0,8067;2,343;0,46287;679,09
48,60000;0,8099;2,352;0,46462;681,84
48,80000;0,8134;2,360;0,46611;683,94
49,00000;0,8167;2,368;0,46781;686,39
49,20000;0,8200;2,373;0,46941;687,90
49,40000;0,8232;2,379;0,47093;689,59
49,60000;0,8268;2,384;0,47270;690,90
49,80000;0,8300;2,387;0,47431;692,02
50,00000;0,8332;2,393;0,47584;693,73
50,20000;0,8368;2,399;0,47750;695,32
50,40000;0,8400;2,405;0,47912;696,98
50,60000;0,8431;2,413;0,48062;699,35
50,80000;0,8468;2,421;0,48223;701,82
51,00000;0,8501;2,432;0,48387;705,00
51,20000;0,8533;2,448;0,48536;709,57
51,40000;0,8567;2,463;0,48704;713,88
51,60000;0,8601;2,478;0,48874;718,32
51,80000;0,8633;2,492;0,49023;722,41
52,00000;0,8666;2,503;0,49177;725,44
52,20000;0,8701;2,511;0,49348;727,97
52,40000;0,8734;2,518;0,49494;729,83
52,60000;0,8765;2,521;0,49648;730,86
52,80000;0,8802;2,527;0,49820;732,38
53,00000;0,8834;2,530;0,49967;733,27
53,20000;0,8865;2,536;0,50114;734,93
53,40000;0,8901;2,543;0,50285;736,98
53,60000;0,8933;2,551;0,50444;739,47
53,74200;0,8956;2,559;0,50550;741,80
53,94200;0,8989;2,576;0,50705;746,62
54,14200;0,9024;2,589;0,50878;750,51
54,34200;0,9057;2,602;0,51030;754,25
54,54200;0,9089;2,614;0,51174;757,79
54,74200;0,9125;2,624;0,51350;760,71
54,94200;0,9157;2,631;0,51505;762,62
55,14200;0,9189;2,636;0,51647;764,15
55,34200;0,9226;2,641;0,51821;765,37
55,54200;0,9257;2,644;0,51975;766,42
55,74200;0,9289;2,647;0,52126;767,30
55,94200;0,9325;2,653;0,52283;768,92
56,14200;0,9357;2,655;0,52434;769,68
56,34200;0,9389;2,665;0,52596;772,50
56,54200;0,9424;2,674;0,52751;775,07
56,74200;0,9458;2,681;0,52916;777,15
56,94200;0,9491;2,690;0,53075;779,65
57,14200;0,9523;2,695;0,53214;781,23
57,34200;0,9558;2,705;0,53386;784,07
57,54200;0,9591;2,715;0,53539;786,82
57,74200;0,9622;2,722;0,53685;789,11
57,94200;0,9658;2,740;0,53849;794,13
58,14200;0,9691;2,752;0,54002;797,79
58,34200;0,9723;2,769;0,54153;802,64
58,54200;0,9758;2,784;0,54308;807,07
58,74200;0,9791;2,796;0,54462;810,30
58,94200;0,9823;2,809;0,54612;814,14
59,14200;0,9857;2,823;0,54764;818,25
59,34200;0,9891;2,834;0,54937;821,32
59,54200;0,9923;2,848;0,55091;825,54
59,74200;0,9956;2,859;0,55240;828,83
59,94200;0,9991;2,869;0,55408;831,59
60,14200;1,0024;2,878;0,55562;834,14
60,34200;1,0056;2,884;0,52013;835,97
60,54200;1,0092;2,894;0,43279;838,82
60,74200;1,0124;2,906;-3,46643;842,34
60,94200;1,0155;2,919;-4,18129;846,13
61,14200;1,0192;2,939;-4,08637;851,78
61,34200;1,0224;2,949;-4,68340;854,93
61,54200;1,0256;2,957;-5,26278;857,24
61,74200;1,0291;2,965;-4,49364;859,48
61,94200;1,0324;2,970;-4,87673;860,87
62,14200;1,0356;2,972;-4,88580;861,46
62,34200;1,0390;2,974;-3,85886;861,97
62,54200;1,0425;2,974;-4,41466;862,12
62,74200;1,0457;2,975;-4,67042;862,26
62,94200;1,0489;2,975;-4,20219;862,42
63,14200;1,0525;2,976;-4,31268;862,75
63,34200;1,0557;2,978;-4,07715;863,08
63,54200;1,0589;2,979;-3,69518;863,56
63,74200;1,0625;2,982;-4,21938;864,23
63,94200;1,0657;2,984;-4,27115;864,93
64,14200;1,0690;2,989;-4,51925;866,42
64,34200;1,0724;2,997;-4,26739;868,70
64,54200;1,0758;3,004;-4,24796;870,77
64,74200;1,0790;3,016;-4,19929;874,33
64,94200;1,0823;3,031;-4,27045;878,42
65,14200;1,0858;3,048;-4,22185;883,38
65,34200;1,0890;3,062;-4,26633;887,58
65,54200;1,0923;3,080;-4,22350;892,67
65,74200;1,0959;3,092;-4,23961;896,12
65,94200;1,0991;3,104;-4,23670;899,81
66,14200;1,1022;3,112;-4,24757;902,04
66,34200;1,1058;3,122;-4,23438;904,97
66,54200;1,1091;3,129;-4,24835;907,03
66,74200;1,1122;3,139;-4,23516;909,94
66,94200;1,1158;3,152;-4,24686;913,74
67,14200;1,1190;3,167;-4,23627;918,12
67,34200;1,1223;3,183;-4,24663;922,73
67,54200;1,1258;3,205;-4,23680;928,99
67,74200;1,1291;3,218;-4,24597;932,86
67,94200;1,1323;3,237;-4,23732;938,35
68,14200;1,1356;3,250;-4,24556;942,02
68,34200;1,1391;3,258;-4,23814;944,46
68,54200;1,1424;3,270;-4,24505;947,72
68,74200;1,1456;3,277;-4,23904;949,75
68,94200;1,1492;3,284;-4,24478;951,74
69,14200;1,1524;3,291;-4,23968;953,89
69,34200;1,1555;3,296;-4,24455;955,41
69,54200;1,1592;3,304;-4,24019;957,76
69,74200;1,1624;3,311;-4,24414;959,69
69,94200;1,1656;3,317;-4,24053;961,53
70,14200;1,1691;3,323;-4,24385;963,24
70,34200;1,1724;3,329;-4,24099;965,05
70,54200;1,1755;3,332;-4,24341;965,75
70,74200;1,1790;3,337;-4,24126;967,27
70,94200;1,1824;3,342;-4,24320;968,59
71,14200;1,1857;3,348;-4,24184;970,33
71,34200;1,1890;3,354;-4,24289;972,22
71,54200;1,1924;3,364;-4,24223;974,97
71,74200;1,1958;3,373;-4,24240;977,60
71,94200;1,1989;3,381;-4,24281;980,00
72,14200;1,2025;3,389;-4,24194;982,29
72,34200;1,2057;3,396;-4,24334;984,28
72,54200;1,2089;3,399;-4,24189;985,34
72,74200;1,2125;3,404;-4,24354;986,68
72,94200;1,2157;3,410;-4,24157;988,48
73,14200;1,2189;3,417;-4,24360;990,42
73,34200;1,2225;3,428;-4,24179;993,72
73,54200;1,2257;3,437;-4,24359;996,28
73,74200;1,2290;3,450;-4,24203;999,90
73,94200;1,2323;3,455;-4,24348;1001,56
74,14200;1,2358;3,466;-4,24230;1004,62
74,34200;1,2391;3,473;-4,24342;1006,68
74,54200;1,2423;3,484;-4,24247;1009,97
74,74200;1,2458;3,497;-4,24311;1013,71
74,94200;1,2491;3,511;-4,24255;1017,56
75,14200;1,2521;3,523;-4,24327;1021,08
75,34200;1,2559;3,540;-4,24263;1026,08
75,54200;1,2590;3,550;-4,24337;1028,97
75,74200;1,2622;3,559;-4,24248;1031,55
75,94200;1,2658;3,570;-4,24343;1034,69
76,14200;1,2691;3,576;-4,24234;1036,56
76,34200;1,2722;3,583;-4,24394;1038,47
76,54200;1,2757;3,590;-4,24229;1040,58
76,74200;1,2790;3,596;-4,24388;1042,30
76,94200;1,2823;3,602;-4,24229;1044,09
77,14200;1,2856;3,606;-4,24394;1045,16
77,34200;1,2891;3,611;-4,24239;1046,63
77,54200;1,2924;3,617;-4,24377;1048,36
77,74200;1,2956;3,620;-4,24256;1049,24
77,94200;1,2992;3,629;-4,24360;1051,94
78,14200;1,3024;3,638;-4,24299;1054,51
78,34200;1,3056;3,649;-4,24337;1057,57
78,54200;1,3092;3,661;-4,24323;1061,22
78,74200;1,3124;3,672;-4,24332;1064,49
78,94200;1,3157;3,688;-4,24344;1069,02
79,14200;1,3190;3,701;-4,24314;1072,69
79,34200;1,3224;3,720;-4,24353;1078,40
79,54200;1,3257;3,733;-4,24312;1082,14
79,74200;1,3290;3,746;-4,24360;1085,92
79,94200;1,3325;3,763;-4,24319;1090,63
80,14200;1,3357;3,769;-4,24362;1092,60
80,34200;1,3389;3,775;-4,24326;1094,10
80,54200;1,3425;3,781;-4,24360;1095,97
80,74200;1,3456;3,790;-4,24330;1098,49
80,94200;1,3489;3,798;-4,24356;1100,74
81,14200;1,3525;3,812;-4,24341;1104,87
81,34200;1,3557;3,822;-4,24354;1107,84
81,54200;1,3589;3,836;-4,24355;1111,91
81,74200;1,3624;3,849;-4,24359;1115,56
81,94200;1,3657;3,856;-4,24367;1117,78
82,14200;1,3690;3,861;-4,24343;1119,10
82,34200;1,3723;3,866;-4,24383;1120,66
82,54200;1,3758;3,870;-4,24341;1121,71
82,74200;1,3790;3,872;-4,24377;1122,44
82,94200;1,3823;3,874;-4,24347;1122,92
83,14200;1,3858;3,875;-4,24383;1123,28
83,34200;1,3891;3,877;-4,24350;1123,65
83,54200;1,3922;3,878;-4,24383;1124,06
83,74200;1,3959;3,880;-4,24379;1124,58
83,94200;1,3991;3,882;-4,24356;1125,17
84,14200;1,4023;3,885;-4,24396;1126,05
84,34200;1,4058;3,888;-4,24346;1127,03
84,54200;1,4091;3,894;-4,24420;1128,76
84,74200;1,4123;3,898;-4,24323;1129,75
84,94200;1,4157;3,906;-4,24433;1132,27
85,14200;1,4191;3,916;-4,24336;1134,99
85,34200;1,4224;3,930;-4,24425;1139,11
85,54200;1,4256;3,945;-4,24342;1143,46
85,74200;1,4292;3,963;-4,24411;1148,70
85,94200;1,4324;3,977;-4,24362;1152,83
86,14200;1,4355;3,989;-4,24385;1156,33
86,34200;1,4392;4,001;-4,24391;1159,82
86,54200;1,4423;4,016;-4,24361;1164,19
86,74200;1,4456;4,022;-4,24425;1165,90
86,94200;1,4491;4,036;-4,24351;1169,91
87,14200;1,4524;4,045;-4,24428;1172,46
87,34200;1,4557;4,059;-4,24349;1176,50
87,54200;1,4591;4,073;-4,24431;1180,56
87,74200;1,4624;4,084;-4,24373;1183,74
87,94200;1,4656;4,095;-4,24416;1186,94
88,14200;1,4690;4,106;-4,24373;1190,06
88,34200;1,4725;4,117;-4,24394;1193,22
88,54200;1,4757;4,129;-4,24403;1196,81
88,74200;1,4789;4,139;-4,24388;1199,73
88,94200;1,4825;4,154;-4,24412;1204,18
89,14200;1,4858;4,170;-4,24373;1208,56
89,34200;1,4888;4,185;-4,24428;1212,90
89,54200;1,4925;4,204;-4,24375;1218,47
89,74200;1,4957;4,214;-4,24430;1221,50
89,94200;1,4989;4,223;-4,24387;1224,19
90,14200;1,5025;4,231;-4,24429;1226,32
90,34200;1,5057;4,237;-4,24393;1227,97
90,54200;1,5089;4,239;-4,24434;1228,65
90,74200;1,5124;4,241;-4,24407;1229,39
90,94200;1,5157;4,244;-4,24424;1230,18
91,14200;1,5190;4,245;-4,24406;1230,47
91,34200;1,5223;4,246;-4,24416;1230,69
91,54200;1,5258;4,247;-4,24427;1230,94
91,74200;1,5291;4,248;-4,24416;1231,32
91,94200;1,5323;4,249;-4,24430;1231,65
92,14200;1,5358;4,250;-4,24410;1232,03
92,34200;1,5391;4,253;-4,24430;1232,84
92,54200;1,5422;4,256;-4,24411;1233,50
92,74200;1,5459;4,259;-4,24432;1234,59
92,94200;1,5491;4,264;-4,24416;1236,02
93,14200;1,5523;4,271;-4,24432;1238,05
93,34200;1,5557;4,281;-4,24422;1240,83
93,54200;1,5591;4,295;-4,24434;1244,90
93,74200;1,5623;4,304;-4,24440;1247,48
93,94200;1,5657;4,318;-4,24415;1251,51
94,14200;1,5691;4,332;-4,24457;1255,66
94,34200;1,5724;4,341;-4,24398;1258,34
94,54200;1,5756;4,348;-4,24492;1260,23
94,74200;1,5792;4,356;-4,24376;1262,47
94,94200;1,5824;4,363;-4,24498;1264,55
95,14200;1,5855;4,373;-4,24371;1267,65
95,34200;1,5891;4,387;-4,24493;1271,70
95,54200;1,5924;4,401;-4,24388;1275,78
95,74200;1,5956;4,418;-4,24465;1280,66
95,94200;1,5991;4,435;-4,24408;1285,51
96,14200;1,6024;4,449;-4,24451;1289,58
96,34200;1,6056;4,460;-4,24446;1292,71
96,54200;1,6089;4,470;-4,24430;1295,58
96,74200;1,6124;4,478;-4,24465;1297,95
96,94200;1,6157;4,487;-4,24408;1300,63
97,14200;1,6190;4,495;-4,24475;1302,89
97,34200;1,6225;4,503;-4,24412;1305,17
97,54200;1,6258;4,511;-4,24481;1307,41
97,74200;1,6288;4,518;-4,24416;1309,54
97,94200;1,6326;4,525;-4,24467;1311,54
98,14200;1,6357;4,530;-4,24447;1313,17
98,34200;1,6389;4,536;-4,24453;1314,84
98,54200;1,6425;4,541;-4,24454;1316,27
98,74200;1,6457;4,547;-4,24438;1317,85
98,94200;1,6490;4,551;-4,24467;1319,24
99,14200;1,6524;4,558;-4,24429;1321,06
99,34200;1,6557;4,564;-4,24464;1323,03
99,54200;1,6590;4,575;-4,24433;1326,09
99,74200;1,6623;4,584;-4,24472;1328,74
99,94200;1,6658;4,595;-4,24449;1331,75
100,14200;1,6690;4,611;-4,24456;1336,44
100,34200;1,6722;4,624;-4,24453;1340,25
100,54200;1,6759;4,634;-4,24440;1343,30
100,74200;1,6790;4,646;-4,24469;1346,63
100,94200;1,6822;4,655;-4,24440;1349,14
101,14200;1,6858;4,663;-4,24481;1351,58
101,34200;1,6891;4,671;-4,24432;1353,85
101,54200;1,6923;4,678;-4,24486;1356,05
101,74200;1,6958;4,685;-4,24430;1357,83
101,94200;1,6991;4,693;-4,24488;1360,31
102,14200;1,7023;4,703;-4,24429;1363,14
102,34200;1,7056;4,711;-4,24506;1365,49
102,54200;1,7092;4,716;-4,24441;1366,90
102,74200;1,7124;4,722;-4,24499;1368,63
102,94200;1,7156;4,725;-4,24439;1369,50
103,14200;1,7192;4,728;-4,24505;1370,49
103,34200;1,7224;4,733;-4,24451;1371,77
103,54200;1,7255;4,738;-4,24492;1373,39
103,74200;1,7292;4,747;-4,24469;1375,80
103,94200;1,7324;4,754;-4,24469;1377,95
104,14200;1,7356;4,763;-4,24494;1380,53
104,34200;1,7391;4,771;-4,24449;1382,81
104,54200;1,7424;4,775;-4,24521;1384,20
104,74200;1,7457;4,782;-4,24422;1386,14
104,94200;1,7490;4,786;-4,24530;1387,13
105,14200;1,7524;4,790;-4,24428;1388,54
105,34201;1,7556;4,793;-4,24515;1389,15
105,54201;1,7589;4,801;-4,24449;1391,49
105,74201;1,7625;4,804;-4,24504;1392,39
105,94201;1,7657;4,810;-4,24471;1394,16
106,14201;1,7689;4,817;-4,24486;1396,17
106,34201;1,7725;4,825;-4,24481;1398,68
106,54201;1,7757;4,836;-4,24455;1401,79
106,74201;1,7789;4,847;-4,24501;1404,91
106,94201;1,7825;4,858;-4,24453;1408,07
107,14201;1,7858;4,869;-4,24511;1411,37
107,34201;1,7889;4,875;-4,24451;1412,93
107,54201;1,7924;4,887;-4,24508;1416,44
107,74201;1,7957;4,895;-4,24471;1418,89
107,94201;1,7989;4,901;-4,24496;1420,44
108,14201;1,8023;4,911;-4,24474;1423,39
108,34201;1,8058;4,920;-4,24483;1426,18
108,54201;1,8091;4,937;-4,24505;1430,92
108,74201;1,8123;4,948;-4,24463;1434,18
108,94201;1,8158;4,966;-4,24512;1439,34
109,14201;1,8191;4,977;-4,24469;1442,66
109,34201;1,8222;4,988;-4,24530;1445,89
109,54201;1,8258;4,999;-4,24461;1448,97
109,74201;1,8290;5,010;-4,24518;1452,19
109,94201;1,8322;5,019;-4,24461;1454,92
110,14201;1,8358;5,033;-4,24511;1458,76
110,34201;1,8391;5,048;-4,24482;1463,09
110,54201;1,8423;5,063;-4,24509;1467,41
110,74201;1,8457;5,076;-4,24480;1471,34
110,94201;1,8491;5,093;-4,24508;1476,17
111,14201;1,8524;5,104;-4,24476;1479,41
111,34201;1,8556;5,112;-4,24510;1481,59
111,54201;1,8592;5,122;-4,24485;1484,75
111,74201;1,8624;5,129;-4,24502;1486,63
111,94201;1,8656;5,135;-4,24495;1488,30
112,14201;1,8692;5,139;-4,24499;1489,62
112,34201;1,8724;5,143;-4,24503;1490,60
112,54201;1,8755;5,145;-4,24485;1491,37
112,74201;1,8792;5,147;-4,24515;1491,90
112,94201;1,8824;5,149;-4,24486;1492,38
113,14201;1,8856;5,150;-4,24512;1492,65
113,34201;1,8891;5,150;-4,24479;1492,76
113,54201;1,8924;5,150;-4,24515;1492,81
113,74201;1,8956;5,150;-4,24490;1492,84
113,94201;1,8989;5,150;-4,24499;1492,88
114,14201;1,9025;5,151;-4,24501;1492,97
114,34201;1,9057;5,151;-4,24492;1493,14
114,54201;1,9089;5,153;-4,24519;1493,62
114,74201;1,9125;5,155;-4,24481;1494,24
114,94201;1,9157;5,159;-4,24531;1495,28
115,14201;1,9189;5,165;-4,24480;1497,14
115,34201;1,9225;5,173;-4,24530;1499,56
115,54201;1,9257;5,184;-4,24485;1502,56
115,74201;1,9290;5,200;-4,24513;1507,12
115,94201;1,9324;5,208;-4,24504;1509,52
116,14201;1,9358;5,218;-4,24494;1512,46
116,34201;1,9390;5,228;-4,24536;1515,22
116,54201;1,9423;5,237;-4,24477;1518,11
116,74201;1,9458;5,248;-4,24550;1521,06
116,94201;1,9491;5,258;-4,24472;1524,02
117,14201;1,9523;5,265;-4,24560;1525,97
117,34201;1,9559;5,278;-4,24462;1529,76
117,54201;1,9591;5,288;-4,24553;1532,86
117,74201;1,9622;5,298;-4,24474;1535,79
117,94201;1,9659;5,308;-4,24535;1538,69
118,14201;1,9690;5,317;-4,24500;1541,25
118,34201;1,9722;5,325;-4,24512;1543,34
118,54201;1,9758;5,334;-4,24528;1546,12
118,74201;1,9791;5,342;-4,24494;1548,35
118,94201;1,9823;5,350;-4,24549;1550,76
119,14201;1,9857;5,359;-4,24488;1553,30
119,34201;1,9890;5,374;-4,24552;1557,64
119,54201;1,9923;5,385;-4,24491;1561,00
119,74201;1,9956;5,401;-4,24553;1565,52
119,94201;1,9991;5,413;-4,24495;1568,92
120,14201;2,0024;5,425;-4,24541;1572,44
120,34201;2,0056;5,432;-4,24511;1574,55
120,54201;2,0092;5,443;-4,24531;1577,75
120,74201;2,0124;5,447;-4,24537;1578,83
120,94201;2,0155;5,454;-4,24514;1580,82
121,14201;2,0192;5,456;-4,24537;1581,35
121,34201;2,0225;5,460;-4,24505;1582,72
121,54201;2,0257;5,464;-4,24547;1583,88
121,74201;2,0291;5,467;-4,24498;1584,70
121,94201;2,0324;5,472;-4,24543;1586,06
122,14201;2,0357;5,478;-4,24513;1587,72
122,34201;2,0390;5,482;-4,24557;1589,04
122,54201;2,0425;5,489;-4,24508;1591,04
122,74201;2,0457;5,495;-4,24551;1592,89
122,94201;2,0489;5,503;-4,24503;1595,09
123,14201;2,0526;5,509;-4,24543;1596,67
123,34201;2,0557;5,516;-4,24521;1598,98
123,54201;2,0589;5,521;-4,24538;1600,22
123,74201;2,0624;5,528;-4,24534;1602,43
123,94201;2,0657;5,534;-4,24513;1604,01
124,14201;2,0689;5,540;-4,24533;1605,87
124,34201;2,0725;5,546;-4,24497;1607,48
124,54201;2,0757;5,555;-4,24549;1610,26
124,74201;2,0790;5,562;-4,24498;1612,04
124,94201;2,0823;5,576;-4,24565;1616,30
125,14201;2,0858;5,582;-4,24493;1617,88
125,34201;2,0890;5,590;-4,24566;1620,35
125,54201;2,0923;5,594;-4,24503;1621,50
125,74201;2,0958;5,596;-4,24552;1622,11
125,94201;2,0991;5,597;-4,24518;1622,38
126,14201;2,1023;5,599;-4,24520;1622,94
126,34201;2,1059;5,602;-4,24546;1623,71
126,54201;2,1091;5,606;-4,24517;1624,91
126,74201;2,1122;5,613;-4,24567;1627,06
126,94201;2,1158;5,625;-4,24504;1630,36
127,14201;2,1191;5,636;-4,24577;1633,50
127,34201;2,1223;5,650;-4,24500;1637,60
127,54201;2,1257;5,658;-4,24577;1639,89
127,74201;2,1291;5,667;-4,24514;1642,62
127,94201;2,1323;5,674;-4,24568;1644,59
128,14201;2,1356;5,680;-4,24541;1646,33
128,34201;2,1392;5,686;-4,24526;1648,25
128,54201;2,1424;5,692;-4,24554;1649,82
128,74201;2,1455;5,699;-4,24504;1651,78
128,94201;2,1492;5,708;-4,24561;1654,56
129,14201;2,1524;5,718;-4,24510;1657,34
129,34201;2,1556;5,722;-4,24572;1658,45
129,54201;2,1591;5,737;-4,24482;1662,76
129,74201;2,1624;5,744;-4,24577;1665,03
129,94201;2,1656;5,755;-4,24494;1668,01
130,14201;2,1691;5,763;-4,24566;1670,30
130,34201;2,1725;5,770;-4,24514;1672,40
130,54201;2,1757;5,776;-4,24559;1674,30
130,74201;2,1790;5,779;-4,24537;1675,19
130,94201;2,1825;5,783;-4,24536;1676,30
131,14201;2,1857;5,787;-4,24549;1677,52
131,34201;2,1889;5,789;-4,24525;1678,10
131,54201;2,1925;5,796;-4,24535;1679,91
131,74201;2,1957;5,801;-4,24533;1681,46
131,94201;2,1989;5,808;-4,24555;1683,45
132,14201;2,2025;5,815;-4,24518;1685,54
132,34201;2,2057;5,827;-4,24558;1688,87
132,54201;2,2088;5,842;-4,24535;1693,28
132,74201;2,2125;5,855;-4,24565;1697,24
132,94201;2,2157;5,868;-4,24521;1700,85
133,14201;2,2190;5,876;-4,24567;1703,28
133,34201;2,2224;5,890;-4,24533;1707,29
133,54201;2,2257;5,904;-4,24579;1711,31
133,74201;2,2290;5,911;-4,24539;1713,29
133,94201;2,2322;5,922;-4,24543;1716,64
134,14201;2,2358;5,932;-4,24548;1719,45
134,34201;2,2391;5,943;-4,24536;1722,70
134,54201;2,2423;5,952;-4,24577;1725,16
134,74201;2,2458;5,962;-4,24502;1728,26
134,94201;2,2491;5,972;-4,24602;1731,08
135,14201;2,2522;5,979;-4,24514;1733,06
135,34201;2,2559;5,988;-4,24609;1735,55
135,54201;2,2591;5,993;-4,24516;1737,19
135,74201;2,2623;5,997;-4,24609;1738,29
135,94201;2,2658;6,003;-4,24515;1739,95
136,14201;2,2691;6,007;-4,24577;1741,21
136,34201;2,2724;6,012;-4,24530;1742,55
136,54201;2,2757;6,017;-4,24574;1744,07
136,74201;2,2791;6,022;-4,24550;1745,46
136,94201;2,2824;6,029;-4,24554;1747,59
137,14201;2,2856;6,037;-4,24568;1749,84
137,34201;2,2892;6,045;-4,24539;1752,06
137,54201;2,2924;6,048;-4,24575;1753,04
137,74201;2,2955;6,052;-4,24539;1754,18
137,94201;2,2992;6,054;-4,24599;1754,66
138,14201;2,3023;6,055;-4,24536;1754,98
138,34201;2,3055;6,055;-4,24569;1755,07
138,54201;2,3092;6,056;-4,24561;1755,36
138,74201;2,3124;6,057;-4,24550;1755,76
138,94201;2,3156;6,060;-4,24580;1756,38
139,14201;2,3191;6,062;-4,24545;1757,10
139,34201;2,3224;6,066;-4,24600;1758,35
139,54201;2,3257;6,069;-4,24545;1759,20
139,74201;2,3290;6,078;-4,24615;1761,80
139,94201;2,3325;6,087;-4,24541;1764,27
140,14201;2,3357;6,093;-4,24607;1766,12
140,34201;2,3389;6,100;-4,24539;1768,13
140,54201;2,3426;6,111;-4,24577;1771,17
140,74201;2,3458;6,120;-4,24540;1774,04
140,94201;2,3488;6,127;-4,24570;1775,90
141,14201;2,3525;6,137;-4,24541;1778,72
141,34201;2,3558;6,150;-4,24562;1782,50
141,54201;2,3590;6,163;-4,24550;1786,24
141,74201;2,3624;6,177;-4,24555;1790,54
141,94201;2,3657;6,189;-4,24560;1793,97
142,14201;2,3690;6,202;-4,24576;1797,70
142,34201;2,3723;6,210;-4,24591;1800,14
142,54201;2,3758;6,219;-4,24584;1802,60
142,74201;2,3790;6,226;-4,24594;1804,71
142,94201;2,3822;6,233;-4,24588;1806,68
143,14201;2,3859;6,245;-4,24582;1810,01
143,34201;2,3890;6,257;-4,24556;1813,64
143,54201;2,3923;6,274;-4,24603;1818,55
143,74201;2,3958;6,289;-4,24570;1822,94
143,94201;2,3991;6,304;-4,24579;1827,25
144,14201;2,4023;6,319;-4,24555;1831,50
144,34201;2,4058;6,330;-4,24563;1834,70
144,54201;2,4091;6,340;-4,24569;1837,62
144,74201;2,4123;6,344;-4,24549;1838,92
144,94201;2,4157;6,351;-4,24590;1840,76
145,14201;2,4191;6,358;-4,24530;1842,91
145,34201;2,4223;6,364;-4,24609;1844,50
145,54201;2,4256;6,370;-4,24506;1846,37
145,74201;2,4292;6,373;-4,24601;1847,39
145,94201;2,4324;6,383;-4,24530;1850,18
146,14201;2,4355;6,387;-4,24592;1851,33
146,34201;2,4392;6,394;-4,24562;1853,43
146,54201;2,4424;6,403;-4,24563;1856,02
146,74201;2,4455;6,407;-4,24608;1857,04
146,94201;2,4491;6,413;-4,24532;1858,94
147,14201;2,4524;6,417;-4,24621;1860,09
147,34201;2,4556;6,420;-4,24518;1860,94
147,54201;2,4591;6,424;-4,24630;1861,93
147,74201;2,4624;6,428;-4,24498;1863,12
147,94201;2,4656;6,432;-4,24642;1864,41
148,14201;2,4689;6,438;-4,24523;1866,11
148,34201;2,4725;6,445;-4,24649;1868,06
148,54201;2,4757;6,454;-4,24538;1870,86
148,74201;2,4789;6,459;-4,24593;1872,22
148,94201;2,4825;6,466;-4,24559;1874,21
149,14201;2,4857;6,469;-4,24594;1875,01
149,34201;2,4890;6,472;-4,24556;1876,04
149,54201;2,4925;6,476;-4,24570;1877,22
149,74201;2,4958;6,482;-4,24578;1878,85
149,94201;2,4988;6,485;-4,24574;1879,82
150,14201;2,5025;6,494;-4,24578;1882,36
150,34201;2,5057;6,502;-4,24560;1884,53
150,54201;2,5090;6,509;-4,24598;1886,71
150,74201;2,5124;6,517;-4,24559;1889,05
150,94201;2,5157;6,528;-4,24605;1892,12
151,14201;2,5190;6,537;-4,24547;1894,72
151,34201;2,5222;6,543;-4,24604;1896,59
151,54201;2,5258;6,552;-4,24557;1899,17
151,74201;2,5291;6,559;-4,24621;1901,23
151,94201;2,5322;6,567;-4,24607;1903,52
152,14201;2,5359;6,573;-4,24627;1905,30
152,34201;2,5390;6,583;-4,24612;1908,10
152,54201;2,5422;6,594;-4,24609;1911,25
152,74201;2,5458;6,607;-4,24592;1915,11
152,94201;2,5491;6,620;-4,24569;1918,88
153,14201;2,5523;6,636;-4,24615;1923,59
153,34201;2,5557;6,646;-4,24545;1926,46
153,54201;2,5591;6,662;-4,24626;1931,00
153,74201;2,5624;6,670;-4,24542;1933,30
153,94201;2,5656;6,678;-4,24602;1935,69
154,14201;2,5692;6,683;-4,24541;1937,06
154,34201;2,5724;6,687;-4,24599;1938,33
154,54201;2,5756;6,691;-4,24564;1939,33
154,74201;2,5792;6,696;-4,24597;1940,82
154,94201;2,5825;6,698;-4,24591;1941,33
155,14201;2,5855;6,704;-4,24563;1943,17
155,34201;2,5891;6,712;-4,24630;1945,43
155,54201;2,5924;6,720;-4,24563;1947,77
155,74201;2,5955;6,729;-4,24634;1950,37
155,94201;2,5991;6,739;-4,24568;1953,31
156,14201;2,6024;6,749;-4,24651;1956,22
156,34201;2,6057;6,757;-4,24554;1958,62
156,54201;2,6090;6,768;-4,24628;1961,79
156,74201;2,6124;6,777;-4,24576;1964,21
156,94201;2,6157;6,785;-4,24606;1966,63
157,14201;2,6189;6,792;-4,24591;1968,63
157,34201;2,6225;6,804;-4,24587;1972,18
157,54201;2,6257;6,814;-4,24615;1974,96
157,74201;2,6289;6,824;-4,24603;1978,11
157,94201;2,6325;6,840;-4,24635;1982,47
158,14201;2,6357;6,848;-4,24597;1984,99
158,34201;2,6389;6,857;-4,24625;1987,65
158,54201;2,6424;6,864;-4,24597;1989,60
158,74201;2,6458;6,867;-4,24612;1990,32
158,94201;2,6490;6,871;-4,24608;1991,50
159,14201;2,6523;6,874;-4,24600;1992,42
159,34201;2,6558;6,880;-4,24602;1994,24
159,54201;2,6590;6,887;-4,24600;1996,28
159,74201;2,6622;6,896;-4,24599;1998,87
159,94201;2,6659;6,906;-4,24600;2001,85
160,14201;2,6690;6,918;-4,24600;2005,21
160,34201;2,6722;6,925;-4,24612;2007,10
160,54201;2,6759;6,931;-4,24600;2009,04
160,74201;2,6790;6,935;-4,24602;2010,22
160,94201;2,6822;6,940;-4,24584;2011,47
161,14201;2,6857;6,945;-4,24595;2012,91
161,34201;2,6891;6,949;-4,24606;2014,34
161,54201;2,6922;6,954;-4,24589;2015,54
161,74201;2,6957;6,960;-4,24620;2017,30
161,94201;2,6990;6,965;-4,24609;2018,81
162,14201;2,7023;6,969;-4,24644;2019,99
162,34201;2,7056;6,975;-4,24613;2021,70
162,54201;2,7091;6,981;-4,24631;2023,35
162,74201;2,7124;6,983;-4,24613;2024,17
162,94201;2,7156;6,989;-4,24620;2025,73
163,14201;2,7192;6,995;-4,24621;2027,48
163,34201;2,7224;6,996;-4,24581;2027,97
163,54201;2,7256;7,003;-4,24612;2029,81
163,74201;2,7292;7,009;-4,24588;2031,55
163,94201;2,7324;7,014;-4,24627;2032,96
164,14201;2,7355;7,020;-4,24592;2034,86
164,34201;2,7391;7,028;-4,24585;2037,15
164,54201;2,7424;7,039;-4,24594;2040,21
164,74201;2,7457;7,050;-4,24587;2043,35
164,94201;2,7490;7,057;-4,24615;2045,37
165,14201;2,7525;7,069;-4,24567;2048,93
165,34201;2,7557;7,078;-4,24652;2051,48
165,54201;2,7589;7,084;-4,24550;2053,40
165,74201;2,7626;7,094;-4,24621;2056,24
165,94201;2,7657;7,100;-4,24513;2057,84
166,14201;2,7689;7,111;-4,24630;2061,28
166,34201;2,7725;7,120;-4,24548;2063,63
166,54201;2,7757;7,131;-4,24639;2066,85
166,74201;2,7789;7,142;-4,24584;2070,13
166,94201;2,7824;7,155;-4,24649;2073,78
167,14201;2,7857;7,166;-4,24586;2077,06
167,34201;2,7890;7,178;-4,24599;2080,51
167,54201;2,7924;7,187;-4,24587;2083,11
167,74201;2,7958;7,195;-4,24571;2085,63
167,94201;2,7990;7,204;-4,24598;2088,11
168,14201;2,8023;7,211;-4,24573;2090,04
168,34201;2,8058;7,217;-4,24592;2091,88
168,54201;2,8091;7,224;-4,24572;2093,89
168,74201;2,8122;7,229;-4,24579;2095,31
168,94201;2,8159;7,237;-4,24585;2097,67
169,14201;2,8191;7,245;-4,24585;2099,88
169,34201;2,8223;7,250;-4,24586;2101,57
169,54201;2,8258;7,261;-4,24586;2104,71
169,74201;2,8290;7,274;-4,24603;2108,34
169,94201;2,8322;7,286;-4,24584;2111,99
170,14201;2,8358;7,297;-4,24592;2115,01
170,34201;2,8391;7,304;-4,24597;2117,14
170,54201;2,8423;7,310;-4,24594;2118,90
170,74201;2,8457;7,314;-4,24587;2120,06
170,94201;2,8491;7,317;-4,24592;2120,95
171,14201;2,8523;7,318;-4,24590;2121,25
171,34201;2,8555;7,321;-4,24597;2121,89
171,54201;2,8592;7,322;-4,24583;2122,33
171,74201;2,8624;7,323;-4,24611;2122,55
171,94201;2,8656;7,324;-4,24581;2122,77
172,14201;2,8691;7,325;-4,24615;2123,07
172,34201;2,8724;7,327;-4,24587;2123,68
172,54201;2,8756;7,328;-4,24623;2124,19
172,74201;2,8791;7,332;-4,24581;2125,31
172,94201;2,8825;7,334;-4,24607;2125,85
173,14201;2,8856;7,338;-4,24614;2126,98
173,34201;2,8890;7,342;-4,24595;2127,97
173,54201;2,8925;7,344;-4,24627;2128,78
173,74201;2,8957;7,349;-4,24581;2130,13
173,94201;2,8989;7,354;-4,24637;2131,56
174,14201;2,9025;7,362;-4,24581;2133,86
174,34201;2,9058;7,371;-4,24641;2136,66
174,54201;2,9089;7,381;-4,24580;2139,28
174,74201;2,9126;7,395;-4,24631;2143,38
174,94201;2,9157;7,402;-4,24590;2145,48
175,14201;2,9189;7,413;-4,24597;2148,58
175,34201;2,9224;7,422;-4,24588;2151,17
175,54201;2,9257;7,430;-4,24601;2153,59
175,74201;2,9289;7,438;-4,24616;2155,81
175,94201;2,9325;7,446;-4,24590;2158,27
176,14201;2,9357;7,455;-4,24627;2160,76
176,34201;2,9390;7,462;-4,24581;2162,85
176,54201;2,9422;7,474;-4,24623;2166,42
176,74201;2,9458;7,487;-4,24600;2170,21
176,94201;2,9490;7,506;-4,24606;2175,54
177,14201;2,9522;7,517;-4,24603;2178,81
177,34201;2,9558;7,536;-4,24597;2184,31
177,54201;2,9591;7,547;-4,24612;2187,41
177,74201;2,9622;7,555;-4,24596;2189,75
177,94201;2,9659;7,567;-4,24614;2193,39
178,14201;2,9690;7,574;-4,24591;2195,35
178,34201;2,9722;7,583;-4,24610;2197,93
178,54201;2,9757;7,593;-4,24593;2200,76
178,74201;2,9791;7,599;-4,24597;2202,71
178,94201;2,9824;7,607;-4,24617;2204,84
179,14201;2,9857;7,612;-4,24579;2206,49
179,34201;2,9891;7,617;-4,24624;2207,96
179,54201;2,9924;7,624;-4,24598;2209,98
179,74201;2,9956;7,628;-4,24609;2211,01
179,94201;2,9992;7,635;-4,24598;2213,11
180,14201;3,0024;7,640;-4,24587;2214,58
180,34201;3,0055;7,645;-4,24613;2215,97
180,54201;3,0092;7,651;-4,24586;2217,54
180,74201;3,0124;7,657;-4,24618;2219,53
180,94201;3,0156;7,664;-4,24592;2221,44
181,14201;3,0191;7,668;-4,24617;2222,71
181,34201;3,0224;7,678;-4,24602;2225,45
181,54201;3,0256;7,686;-4,24600;2227,70
181,74201;3,0291;7,694;-4,24610;2230,16
181,94201;3,0324;7,701;-4,24584;2232,11
182,14201;3,0357;7,710;-4,24635;2234,70
182,34201;3,0390;7,715;-4,24585;2236,20
182,54201;3,0425;7,723;-4,24635;2238,43
182,74201;3,0458;7,727;-4,24571;2239,72
182,94201;3,0489;7,732;-4,24634;2241,23
183,14201;3,0526;7,736;-4,24586;2242,30
183,34201;3,0558;7,739;-4,24601;2243,19
183,54201;3,0589;7,743;-4,24616;2244,27
183,74201;3,0625;7,747;-4,24586;2245,52
183,94201;3,0657;7,751;-4,24637;2246,77
184,14201;3,0689;7,755;-4,24566;2247,92
184,34201;3,0724;7,762;-4,24656;2249,83
184,54201;3,0758;7,770;-4,24582;2252,21
184,74201;3,0790;7,776;-4,24634;2253,98
184,94201;3,0824;7,781;-4,24591;2255,43
185,14201;3,0858;7,791;-4,24608;2258,21
185,34201;3,0890;7,794;-4,24607;2259,06
185,54201;3,0922;7,802;-4,24584;2261,55
185,74201;3,0958;7,809;-4,24640;2263,53
185,94201;3,0991;7,817;-4,24576;2265,86
186,14201;3,1023;7,821;-4,24651;2266,88
186,34201;3,1058;7,824;-4,24574;2267,88
186,54201;3,1091;7,829;-4,24644;2269,21
186,74201;3,1123;7,830;-4,24593;2269,54
186,94201;3,1158;7,834;-4,24628;2270,71
187,14201;3,1191;7,838;-4,24622;2271,76
187,34201;3,1223;7,841;-4,24611;2272,73
187,54201;3,1257;7,844;-4,24634;2273,68
187,74201;3,1291;7,849;-4,24593;2275,09
187,94201;3,1324;7,842;-4,24647;2272,94
188,00001;3,1333;6,942;-4,24333;2012,19
188,00801;3,1336;6,178;-4,24415;1790,85